package alienMod.structures;

import java.util.Random;

import net.minecraft.block.Block;
import net.minecraft.world.World;
import net.minecraft.world.gen.feature.WorldGenerator;
import alienMod.blocks.Blocks;
import alienMod.mobs.entities.EntityAlien;

public class WorldGenUFO2 extends WorldGenerator
{
	protected int[] GetValidSpawnBlocks() {
		return new int[] { 0, Block.grass.blockID, Block.dirt.blockID,
				Block.gravel.blockID, Block.sand.blockID,
				Block.blockClay.blockID };
	}
	
	public boolean LocationIsValidSpawn(World world, int i, int j, int k) {
		int distanceToAir = 0;
		int checkID = world.getBlockId(i, j, k);
		
		while (checkID != 0) {
			distanceToAir++;
			checkID = world.getBlockId(i, j + distanceToAir, k);
		}
		
		if (distanceToAir > 3) {
			return false;
		}
		j += distanceToAir - 1;
		
		int blockID = world.getBlockId(i, j, k);
		int blockIDAbove = world.getBlockId(i, j + 1, k);
		int blockIDBelow = world.getBlockId(i, j - 1, k);
		return true;
	}
	
	public WorldGenUFO2() {
	}
	
	@Override
	public boolean generate(World world, Random rand, int i, int j, int k) {
		// check that each corner is one of the valid spawn blocks
		if (!LocationIsValidSpawn(world, i, j, k))
		{
			return false;
		}
		
		world.setBlock(i + 0, j + 20, k + 24, Blocks.viriBlock.blockID);
		world.setBlock(i + 0, j + 20, k + 25, Blocks.viriBlock.blockID);
		world.setBlock(i + 0, j + 20, k + 26, Blocks.viriBlock.blockID);
		world.setBlock(i + 0, j + 20, k + 27, Blocks.viriBlock.blockID);
		world.setBlock(i + 0, j + 20, k + 28, Blocks.viriBlock.blockID);
		world.setBlock(i + 0, j + 20, k + 29, Blocks.viriBlock.blockID);
		world.setBlock(i + 0, j + 20, k + 30, Blocks.viriBlock.blockID);
		world.setBlock(i + 0, j + 21, k + 22, Blocks.viriBlock.blockID);
		world.setBlock(i + 0, j + 21, k + 23, Blocks.viriBlock.blockID);
		world.setBlock(i + 0, j + 21, k + 24, Blocks.viriBlock.blockID);
		world.setBlock(i + 0, j + 21, k + 25, Blocks.viriBlock.blockID);
		world.setBlock(i + 0, j + 21, k + 26, Blocks.viriBlock.blockID);
		world.setBlock(i + 0, j + 21, k + 27, Blocks.viriBlock.blockID);
		world.setBlock(i + 0, j + 21, k + 28, Blocks.viriBlock.blockID);
		world.setBlock(i + 0, j + 21, k + 29, Blocks.viriBlock.blockID);
		world.setBlock(i + 0, j + 21, k + 30, Blocks.viriBlock.blockID);
		world.setBlock(i + 0, j + 21, k + 31, Blocks.viriBlock.blockID);
		world.setBlock(i + 0, j + 21, k + 32, Blocks.viriBlock.blockID);
		world.setBlock(i + 0, j + 22, k + 21, Blocks.viriBlock.blockID);
		world.setBlock(i + 0, j + 22, k + 22, Blocks.viriBlock.blockID);
		world.setBlock(i + 0, j + 22, k + 23, Blocks.viriBlock.blockID);
		world.setBlock(i + 0, j + 22, k + 31, Blocks.viriBlock.blockID);
		world.setBlock(i + 0, j + 22, k + 32, Blocks.viriBlock.blockID);
		world.setBlock(i + 0, j + 22, k + 33, Blocks.viriBlock.blockID);
		world.setBlock(i + 0, j + 23, k + 20, Blocks.viriBlock.blockID);
		world.setBlock(i + 0, j + 23, k + 21, Blocks.viriBlock.blockID);
		world.setBlock(i + 0, j + 23, k + 22, Blocks.viriBlock.blockID);
		world.setBlock(i + 0, j + 23, k + 32, Blocks.viriBlock.blockID);
		world.setBlock(i + 0, j + 23, k + 33, Blocks.viriBlock.blockID);
		world.setBlock(i + 0, j + 23, k + 34, Blocks.viriBlock.blockID);
		world.setBlock(i + 0, j + 24, k + 19, Blocks.viriBlock.blockID);
		world.setBlock(i + 0, j + 24, k + 20, Blocks.viriBlock.blockID);
		world.setBlock(i + 0, j + 24, k + 21, Blocks.viriBlock.blockID);
		world.setBlock(i + 0, j + 24, k + 33, Blocks.viriBlock.blockID);
		world.setBlock(i + 0, j + 24, k + 34, Blocks.viriBlock.blockID);
		world.setBlock(i + 0, j + 24, k + 35, Blocks.viriBlock.blockID);
		world.setBlock(i + 0, j + 25, k + 19, Blocks.viriBlock.blockID);
		world.setBlock(i + 0, j + 25, k + 20, Blocks.viriBlock.blockID);
		world.setBlock(i + 0, j + 25, k + 34, Blocks.viriBlock.blockID);
		world.setBlock(i + 0, j + 25, k + 35, Blocks.viriBlock.blockID);
		world.setBlock(i + 0, j + 26, k + 18, Blocks.viriBlock.blockID);
		world.setBlock(i + 0, j + 26, k + 19, Blocks.viriBlock.blockID);
		world.setBlock(i + 0, j + 26, k + 35, Blocks.viriBlock.blockID);
		world.setBlock(i + 0, j + 26, k + 36, Blocks.viriBlock.blockID);
		world.setBlock(i + 0, j + 27, k + 18, Blocks.viriBlock.blockID);
		world.setBlock(i + 0, j + 27, k + 19, Blocks.viriBlock.blockID);
		world.setBlock(i + 0, j + 27, k + 35, Blocks.viriBlock.blockID);
		world.setBlock(i + 0, j + 27, k + 36, Blocks.viriBlock.blockID);
		world.setBlock(i + 0, j + 28, k + 18, Blocks.viriBlock.blockID);
		world.setBlock(i + 0, j + 28, k + 19, Blocks.viriBlock.blockID);
		world.setBlock(i + 0, j + 28, k + 35, Blocks.viriBlock.blockID);
		world.setBlock(i + 0, j + 28, k + 36, Blocks.viriBlock.blockID);
		world.setBlock(i + 0, j + 29, k + 18, Blocks.viriBlock.blockID);
		world.setBlock(i + 0, j + 29, k + 19, Blocks.viriBlock.blockID);
		world.setBlock(i + 0, j + 29, k + 35, Blocks.viriBlock.blockID);
		world.setBlock(i + 0, j + 29, k + 36, Blocks.viriBlock.blockID);
		world.setBlock(i + 0, j + 30, k + 18, Blocks.viriBlock.blockID);
		world.setBlock(i + 0, j + 30, k + 19, Blocks.viriBlock.blockID);
		world.setBlock(i + 0, j + 30, k + 35, Blocks.viriBlock.blockID);
		world.setBlock(i + 0, j + 30, k + 36, Blocks.viriBlock.blockID);
		world.setBlock(i + 0, j + 31, k + 18, Block.glass.blockID);
		world.setBlock(i + 0, j + 31, k + 19, Block.glass.blockID);
		world.setBlock(i + 0, j + 31, k + 20, Block.glass.blockID);
		world.setBlock(i + 0, j + 31, k + 21, Block.glass.blockID);
		world.setBlock(i + 0, j + 31, k + 22, Block.glass.blockID);
		world.setBlock(i + 0, j + 31, k + 23, Block.glass.blockID);
		world.setBlock(i + 0, j + 31, k + 24, Block.glass.blockID);
		world.setBlock(i + 0, j + 31, k + 25, Block.glass.blockID);
		world.setBlock(i + 0, j + 31, k + 26, Block.glass.blockID);
		world.setBlock(i + 0, j + 31, k + 27, Block.glass.blockID);
		world.setBlock(i + 0, j + 31, k + 28, Block.glass.blockID);
		world.setBlock(i + 0, j + 31, k + 29, Block.glass.blockID);
		world.setBlock(i + 0, j + 31, k + 30, Block.glass.blockID);
		world.setBlock(i + 0, j + 31, k + 31, Block.glass.blockID);
		world.setBlock(i + 0, j + 31, k + 32, Block.glass.blockID);
		world.setBlock(i + 0, j + 31, k + 33, Block.glass.blockID);
		world.setBlock(i + 0, j + 31, k + 34, Block.glass.blockID);
		world.setBlock(i + 0, j + 31, k + 35, Block.glass.blockID);
		world.setBlock(i + 0, j + 31, k + 36, Block.glass.blockID);
		world.setBlock(i + 0, j + 32, k + 18, Blocks.viriBlock.blockID);
		world.setBlock(i + 0, j + 32, k + 19, Blocks.viriBlock.blockID);
		world.setBlock(i + 0, j + 32, k + 35, Blocks.viriBlock.blockID);
		world.setBlock(i + 0, j + 32, k + 36, Blocks.viriBlock.blockID);
		world.setBlock(i + 1, j + 18, k + 24, Blocks.viriBlock.blockID);
		world.setBlock(i + 1, j + 18, k + 25, Blocks.viriBlock.blockID);
		world.setBlock(i + 1, j + 18, k + 26, Blocks.viriBlock.blockID);
		world.setBlock(i + 1, j + 18, k + 27, Blocks.viriBlock.blockID);
		world.setBlock(i + 1, j + 18, k + 28, Blocks.viriBlock.blockID);
		world.setBlock(i + 1, j + 18, k + 29, Blocks.viriBlock.blockID);
		world.setBlock(i + 1, j + 18, k + 30, Blocks.viriBlock.blockID);
		world.setBlock(i + 1, j + 19, k + 22, Blocks.viriBlock.blockID);
		world.setBlock(i + 1, j + 19, k + 23, Blocks.viriBlock.blockID);
		world.setBlock(i + 1, j + 19, k + 24, Blocks.viriBlock.blockID);
		world.setBlock(i + 1, j + 19, k + 25, Blocks.viriBlock.blockID);
		world.setBlock(i + 1, j + 19, k + 26, Blocks.viriBlock.blockID);
		world.setBlock(i + 1, j + 19, k + 27, Blocks.viriBlock.blockID);
		world.setBlock(i + 1, j + 19, k + 28, Blocks.viriBlock.blockID);
		world.setBlock(i + 1, j + 19, k + 29, Blocks.viriBlock.blockID);
		world.setBlock(i + 1, j + 19, k + 30, Blocks.viriBlock.blockID);
		world.setBlock(i + 1, j + 19, k + 31, Blocks.viriBlock.blockID);
		world.setBlock(i + 1, j + 19, k + 32, Blocks.viriBlock.blockID);
		world.setBlock(i + 1, j + 20, k + 20, Blocks.viriBlock.blockID);
		world.setBlock(i + 1, j + 20, k + 21, Blocks.viriBlock.blockID);
		world.setBlock(i + 1, j + 20, k + 22, Blocks.viriBlock.blockID);
		world.setBlock(i + 1, j + 20, k + 23, Blocks.viriBlock.blockID);
		world.setBlock(i + 1, j + 20, k + 31, Blocks.viriBlock.blockID);
		world.setBlock(i + 1, j + 20, k + 32, Blocks.viriBlock.blockID);
		world.setBlock(i + 1, j + 20, k + 33, Blocks.viriBlock.blockID);
		world.setBlock(i + 1, j + 20, k + 34, Blocks.viriBlock.blockID);
		world.setBlock(i + 1, j + 21, k + 19, Blocks.viriBlock.blockID);
		world.setBlock(i + 1, j + 21, k + 20, Blocks.viriBlock.blockID);
		world.setBlock(i + 1, j + 21, k + 21, Blocks.viriBlock.blockID);
		world.setBlock(i + 1, j + 21, k + 33, Blocks.viriBlock.blockID);
		world.setBlock(i + 1, j + 21, k + 34, Blocks.viriBlock.blockID);
		world.setBlock(i + 1, j + 21, k + 35, Blocks.viriBlock.blockID);
		world.setBlock(i + 1, j + 22, k + 18, Blocks.viriBlock.blockID);
		world.setBlock(i + 1, j + 22, k + 19, Blocks.viriBlock.blockID);
		world.setBlock(i + 1, j + 22, k + 20, Blocks.viriBlock.blockID);
		world.setBlock(i + 1, j + 22, k + 34, Blocks.viriBlock.blockID);
		world.setBlock(i + 1, j + 22, k + 35, Blocks.viriBlock.blockID);
		world.setBlock(i + 1, j + 22, k + 36, Blocks.viriBlock.blockID);
		world.setBlock(i + 1, j + 23, k + 18, Blocks.viriBlock.blockID);
		world.setBlock(i + 1, j + 23, k + 19, Blocks.viriBlock.blockID);
		world.setBlock(i + 1, j + 23, k + 35, Blocks.viriBlock.blockID);
		world.setBlock(i + 1, j + 23, k + 36, Blocks.viriBlock.blockID);
		world.setBlock(i + 1, j + 24, k + 17, Blocks.viriBlock.blockID);
		world.setBlock(i + 1, j + 24, k + 18, Blocks.viriBlock.blockID);
		world.setBlock(i + 1, j + 24, k + 36, Blocks.viriBlock.blockID);
		world.setBlock(i + 1, j + 24, k + 37, Blocks.viriBlock.blockID);
		world.setBlock(i + 1, j + 25, k + 17, Blocks.viriBlock.blockID);
		world.setBlock(i + 1, j + 25, k + 18, Blocks.viriBlock.blockID);
		world.setBlock(i + 1, j + 25, k + 36, Blocks.viriBlock.blockID);
		world.setBlock(i + 1, j + 25, k + 37, Blocks.viriBlock.blockID);
		world.setBlock(i + 1, j + 26, k + 16, Blocks.viriBlock.blockID);
		world.setBlock(i + 1, j + 26, k + 17, Blocks.viriBlock.blockID);
		world.setBlock(i + 1, j + 26, k + 37, Blocks.viriBlock.blockID);
		world.setBlock(i + 1, j + 26, k + 38, Blocks.viriBlock.blockID);
		world.setBlock(i + 1, j + 27, k + 16, Blocks.viriBlock.blockID);
		world.setBlock(i + 1, j + 27, k + 17, Blocks.viriBlock.blockID);
		world.setBlock(i + 1, j + 27, k + 37, Blocks.viriBlock.blockID);
		world.setBlock(i + 1, j + 27, k + 38, Blocks.viriBlock.blockID);
		world.setBlock(i + 1, j + 28, k + 16, Blocks.viriBlock.blockID);
		world.setBlock(i + 1, j + 28, k + 17, Blocks.viriBlock.blockID);
		world.setBlock(i + 1, j + 28, k + 37, Blocks.viriBlock.blockID);
		world.setBlock(i + 1, j + 28, k + 38, Blocks.viriBlock.blockID);
		world.setBlock(i + 1, j + 29, k + 16, Blocks.viriBlock.blockID);
		world.setBlock(i + 1, j + 29, k + 17, Blocks.viriBlock.blockID);
		world.setBlock(i + 1, j + 29, k + 37, Blocks.viriBlock.blockID);
		world.setBlock(i + 1, j + 29, k + 38, Blocks.viriBlock.blockID);
		world.setBlock(i + 1, j + 30, k + 16, Blocks.viriBlock.blockID);
		world.setBlock(i + 1, j + 30, k + 17, Blocks.viriBlock.blockID);
		world.setBlock(i + 1, j + 30, k + 37, Blocks.viriBlock.blockID);
		world.setBlock(i + 1, j + 30, k + 38, Blocks.viriBlock.blockID);
		world.setBlock(i + 1, j + 31, k + 16, Block.glass.blockID);
		world.setBlock(i + 1, j + 31, k + 17, Block.glass.blockID);
		world.setBlock(i + 1, j + 31, k + 18, Block.glass.blockID);
		world.setBlock(i + 1, j + 31, k + 19, Block.glass.blockID);
		world.setBlock(i + 1, j + 31, k + 20, Block.glass.blockID);
		world.setBlock(i + 1, j + 31, k + 21, Block.glass.blockID);
		world.setBlock(i + 1, j + 31, k + 22, Block.glass.blockID);
		world.setBlock(i + 1, j + 31, k + 23, Block.glass.blockID);
		world.setBlock(i + 1, j + 31, k + 24, Block.glass.blockID);
		world.setBlock(i + 1, j + 31, k + 25, Block.glass.blockID);
		world.setBlock(i + 1, j + 31, k + 26, Block.glass.blockID);
		world.setBlock(i + 1, j + 31, k + 27, Block.glass.blockID);
		world.setBlock(i + 1, j + 31, k + 28, Block.glass.blockID);
		world.setBlock(i + 1, j + 31, k + 29, Block.glass.blockID);
		world.setBlock(i + 1, j + 31, k + 30, Block.glass.blockID);
		world.setBlock(i + 1, j + 31, k + 31, Block.glass.blockID);
		world.setBlock(i + 1, j + 31, k + 32, Block.glass.blockID);
		world.setBlock(i + 1, j + 31, k + 33, Block.glass.blockID);
		world.setBlock(i + 1, j + 31, k + 34, Block.glass.blockID);
		world.setBlock(i + 1, j + 31, k + 35, Block.glass.blockID);
		world.setBlock(i + 1, j + 31, k + 36, Block.glass.blockID);
		world.setBlock(i + 1, j + 31, k + 37, Block.glass.blockID);
		world.setBlock(i + 1, j + 31, k + 38, Block.glass.blockID);
		world.setBlock(i + 1, j + 32, k + 16, Blocks.viriBlock.blockID);
		world.setBlock(i + 1, j + 32, k + 17, Blocks.viriBlock.blockID);
		world.setBlock(i + 1, j + 32, k + 37, Blocks.viriBlock.blockID);
		world.setBlock(i + 1, j + 32, k + 38, Blocks.viriBlock.blockID);
		world.setBlock(i + 2, j + 17, k + 23, Blocks.viriBlock.blockID);
		world.setBlock(i + 2, j + 17, k + 24, Blocks.viriBlock.blockID);
		world.setBlock(i + 2, j + 17, k + 25, Blocks.viriBlock.blockID);
		world.setBlock(i + 2, j + 17, k + 26, Blocks.viriBlock.blockID);
		world.setBlock(i + 2, j + 17, k + 27, Blocks.viriBlock.blockID);
		world.setBlock(i + 2, j + 17, k + 28, Blocks.viriBlock.blockID);
		world.setBlock(i + 2, j + 17, k + 29, Blocks.viriBlock.blockID);
		world.setBlock(i + 2, j + 17, k + 30, Blocks.viriBlock.blockID);
		world.setBlock(i + 2, j + 17, k + 31, Blocks.viriBlock.blockID);
		world.setBlock(i + 2, j + 18, k + 21, Blocks.viriBlock.blockID);
		world.setBlock(i + 2, j + 18, k + 22, Blocks.viriBlock.blockID);
		world.setBlock(i + 2, j + 18, k + 23, Blocks.viriBlock.blockID);
		world.setBlock(i + 2, j + 18, k + 31, Blocks.viriBlock.blockID);
		world.setBlock(i + 2, j + 18, k + 32, Blocks.viriBlock.blockID);
		world.setBlock(i + 2, j + 18, k + 33, Blocks.viriBlock.blockID);
		world.setBlock(i + 2, j + 19, k + 19, Blocks.viriBlock.blockID);
		world.setBlock(i + 2, j + 19, k + 20, Blocks.viriBlock.blockID);
		world.setBlock(i + 2, j + 19, k + 21, Blocks.viriBlock.blockID);
		world.setBlock(i + 2, j + 19, k + 33, Blocks.viriBlock.blockID);
		world.setBlock(i + 2, j + 19, k + 34, Blocks.viriBlock.blockID);
		world.setBlock(i + 2, j + 19, k + 35, Blocks.viriBlock.blockID);
		world.setBlock(i + 2, j + 20, k + 18, Blocks.viriBlock.blockID);
		world.setBlock(i + 2, j + 20, k + 19, Blocks.viriBlock.blockID);
		world.setBlock(i + 2, j + 20, k + 35, Blocks.viriBlock.blockID);
		world.setBlock(i + 2, j + 20, k + 36, Blocks.viriBlock.blockID);
		world.setBlock(i + 2, j + 21, k + 17, Blocks.viriBlock.blockID);
		world.setBlock(i + 2, j + 21, k + 18, Blocks.viriBlock.blockID);
		world.setBlock(i + 2, j + 21, k + 36, Blocks.viriBlock.blockID);
		world.setBlock(i + 2, j + 21, k + 37, Blocks.viriBlock.blockID);
		world.setBlock(i + 2, j + 22, k + 17, Blocks.viriBlock.blockID);
		world.setBlock(i + 2, j + 22, k + 37, Blocks.viriBlock.blockID);
		world.setBlock(i + 2, j + 23, k + 16, Blocks.viriBlock.blockID);
		world.setBlock(i + 2, j + 23, k + 17, Blocks.viriBlock.blockID);
		world.setBlock(i + 2, j + 23, k + 37, Blocks.viriBlock.blockID);
		world.setBlock(i + 2, j + 23, k + 38, Blocks.viriBlock.blockID);
		world.setBlock(i + 2, j + 24, k + 16, Blocks.viriBlock.blockID);
		world.setBlock(i + 2, j + 24, k + 38, Blocks.viriBlock.blockID);
		world.setBlock(i + 2, j + 25, k + 15, Blocks.viriBlock.blockID);
		world.setBlock(i + 2, j + 25, k + 16, Blocks.viriBlock.blockID);
		world.setBlock(i + 2, j + 25, k + 38, Blocks.viriBlock.blockID);
		world.setBlock(i + 2, j + 25, k + 39, Blocks.viriBlock.blockID);
		world.setBlock(i + 2, j + 26, k + 15, Blocks.viriBlock.blockID);
		world.setBlock(i + 2, j + 26, k + 39, Blocks.viriBlock.blockID);
		world.setBlock(i + 2, j + 27, k + 15, Blocks.viriBlock.blockID);
		world.setBlock(i + 2, j + 27, k + 39, Blocks.viriBlock.blockID);
		world.setBlock(i + 2, j + 28, k + 15, Blocks.viriBlock.blockID);
		world.setBlock(i + 2, j + 28, k + 39, Blocks.viriBlock.blockID);
		world.setBlock(i + 2, j + 29, k + 15, Blocks.viriBlock.blockID);
		world.setBlock(i + 2, j + 29, k + 39, Blocks.viriBlock.blockID);
		world.setBlock(i + 2, j + 30, k + 15, Blocks.viriBlock.blockID);
		world.setBlock(i + 2, j + 30, k + 39, Blocks.viriBlock.blockID);
		world.setBlock(i + 2, j + 31, k + 15, Block.glass.blockID);
		world.setBlock(i + 2, j + 31, k + 16, Block.glass.blockID);
		world.setBlock(i + 2, j + 31, k + 17, Block.glass.blockID);
		world.setBlock(i + 2, j + 31, k + 18, Block.glass.blockID);
		world.setBlock(i + 2, j + 31, k + 19, Block.glass.blockID);
		world.setBlock(i + 2, j + 31, k + 20, Block.glass.blockID);
		world.setBlock(i + 2, j + 31, k + 21, Block.glass.blockID);
		world.setBlock(i + 2, j + 31, k + 22, Block.glass.blockID);
		world.setBlock(i + 2, j + 31, k + 23, Block.glass.blockID);
		world.setBlock(i + 2, j + 31, k + 24, Block.glass.blockID);
		world.setBlock(i + 2, j + 31, k + 25, Block.glass.blockID);
		world.setBlock(i + 2, j + 31, k + 26, Block.glass.blockID);
		world.setBlock(i + 2, j + 31, k + 27, Block.glass.blockID);
		world.setBlock(i + 2, j + 31, k + 28, Block.glass.blockID);
		world.setBlock(i + 2, j + 31, k + 29, Block.glass.blockID);
		world.setBlock(i + 2, j + 31, k + 30, Block.glass.blockID);
		world.setBlock(i + 2, j + 31, k + 31, Block.glass.blockID);
		world.setBlock(i + 2, j + 31, k + 32, Block.glass.blockID);
		world.setBlock(i + 2, j + 31, k + 33, Block.glass.blockID);
		world.setBlock(i + 2, j + 31, k + 34, Block.glass.blockID);
		world.setBlock(i + 2, j + 31, k + 35, Block.glass.blockID);
		world.setBlock(i + 2, j + 31, k + 36, Block.glass.blockID);
		world.setBlock(i + 2, j + 31, k + 37, Block.glass.blockID);
		world.setBlock(i + 2, j + 31, k + 38, Block.glass.blockID);
		world.setBlock(i + 2, j + 31, k + 39, Block.glass.blockID);
		world.setBlock(i + 2, j + 32, k + 15, Blocks.viriBlock.blockID);
		world.setBlock(i + 2, j + 32, k + 39, Blocks.viriBlock.blockID);
		world.setBlock(i + 3, j + 16, k + 22, Blocks.viriBlock.blockID);
		world.setBlock(i + 3, j + 16, k + 23, Blocks.viriBlock.blockID);
		world.setBlock(i + 3, j + 16, k + 24, Blocks.viriBlock.blockID);
		world.setBlock(i + 3, j + 16, k + 25, Blocks.viriBlock.blockID);
		world.setBlock(i + 3, j + 16, k + 26, Blocks.viriBlock.blockID);
		world.setBlock(i + 3, j + 16, k + 27, Blocks.viriBlock.blockID);
		world.setBlock(i + 3, j + 16, k + 28, Blocks.viriBlock.blockID);
		world.setBlock(i + 3, j + 16, k + 29, Blocks.viriBlock.blockID);
		world.setBlock(i + 3, j + 16, k + 30, Blocks.viriBlock.blockID);
		world.setBlock(i + 3, j + 16, k + 31, Blocks.viriBlock.blockID);
		world.setBlock(i + 3, j + 16, k + 32, Blocks.viriBlock.blockID);
		world.setBlock(i + 3, j + 17, k + 20, Blocks.viriBlock.blockID);
		world.setBlock(i + 3, j + 17, k + 21, Blocks.viriBlock.blockID);
		world.setBlock(i + 3, j + 17, k + 22, Blocks.viriBlock.blockID);
		world.setBlock(i + 3, j + 17, k + 32, Blocks.viriBlock.blockID);
		world.setBlock(i + 3, j + 17, k + 33, Blocks.viriBlock.blockID);
		world.setBlock(i + 3, j + 17, k + 34, Blocks.viriBlock.blockID);
		world.setBlock(i + 3, j + 18, k + 19, Blocks.viriBlock.blockID);
		world.setBlock(i + 3, j + 18, k + 20, Blocks.viriBlock.blockID);
		world.setBlock(i + 3, j + 18, k + 34, Blocks.viriBlock.blockID);
		world.setBlock(i + 3, j + 18, k + 35, Blocks.viriBlock.blockID);
		world.setBlock(i + 3, j + 19, k + 18, Blocks.viriBlock.blockID);
		world.setBlock(i + 3, j + 19, k + 36, Blocks.viriBlock.blockID);
		world.setBlock(i + 3, j + 20, k + 17, Blocks.viriBlock.blockID);
		world.setBlock(i + 3, j + 20, k + 37, Blocks.viriBlock.blockID);
		world.setBlock(i + 3, j + 21, k + 16, Blocks.viriBlock.blockID);
		world.setBlock(i + 3, j + 21, k + 38, Blocks.viriBlock.blockID);
		world.setBlock(i + 3, j + 22, k + 15, Blocks.viriBlock.blockID);
		world.setBlock(i + 3, j + 22, k + 16, Blocks.viriBlock.blockID);
		world.setBlock(i + 3, j + 22, k + 38, Blocks.viriBlock.blockID);
		world.setBlock(i + 3, j + 22, k + 39, Blocks.viriBlock.blockID);
		world.setBlock(i + 3, j + 23, k + 15, Blocks.viriBlock.blockID);
		world.setBlock(i + 3, j + 23, k + 39, Blocks.viriBlock.blockID);
		world.setBlock(i + 3, j + 24, k + 14, Blocks.viriBlock.blockID);
		world.setBlock(i + 3, j + 24, k + 15, Blocks.viriBlock.blockID);
		world.setBlock(i + 3, j + 24, k + 39, Blocks.viriBlock.blockID);
		world.setBlock(i + 3, j + 24, k + 40, Blocks.viriBlock.blockID);
		world.setBlock(i + 3, j + 25, k + 14, Blocks.viriBlock.blockID);
		world.setBlock(i + 3, j + 25, k + 40, Blocks.viriBlock.blockID);
		world.setBlock(i + 3, j + 26, k + 14, Blocks.viriBlock.blockID);
		world.setBlock(i + 3, j + 26, k + 40, Blocks.viriBlock.blockID);
		world.setBlock(i + 3, j + 27, k + 14, Blocks.viriBlock.blockID);
		world.setBlock(i + 3, j + 27, k + 40, Blocks.viriBlock.blockID);
		world.setBlock(i + 3, j + 28, k + 14, Blocks.viriBlock.blockID);
		world.setBlock(i + 3, j + 28, k + 40, Blocks.viriBlock.blockID);
		world.setBlock(i + 3, j + 29, k + 14, Blocks.viriBlock.blockID);
		world.setBlock(i + 3, j + 29, k + 40, Blocks.viriBlock.blockID);
		world.setBlock(i + 3, j + 30, k + 14, Blocks.viriBlock.blockID);
		world.setBlock(i + 3, j + 30, k + 40, Blocks.viriBlock.blockID);
		world.setBlock(i + 3, j + 31, k + 14, Block.glass.blockID);
		world.setBlock(i + 3, j + 31, k + 15, Block.glass.blockID);
		world.setBlock(i + 3, j + 31, k + 16, Block.glass.blockID);
		world.setBlock(i + 3, j + 31, k + 17, Block.glass.blockID);
		world.setBlock(i + 3, j + 31, k + 18, Block.glass.blockID);
		world.setBlock(i + 3, j + 31, k + 19, Block.glass.blockID);
		world.setBlock(i + 3, j + 31, k + 20, Block.glass.blockID);
		world.setBlock(i + 3, j + 31, k + 21, Block.glass.blockID);
		world.setBlock(i + 3, j + 31, k + 22, Block.glass.blockID);
		world.setBlock(i + 3, j + 31, k + 23, Block.glass.blockID);
		world.setBlock(i + 3, j + 31, k + 24, Block.glass.blockID);
		world.setBlock(i + 3, j + 31, k + 25, Block.glass.blockID);
		world.setBlock(i + 3, j + 31, k + 26, Block.glass.blockID);
		world.setBlock(i + 3, j + 31, k + 27, Block.glass.blockID);
		world.setBlock(i + 3, j + 31, k + 28, Block.glass.blockID);
		world.setBlock(i + 3, j + 31, k + 29, Block.glass.blockID);
		world.setBlock(i + 3, j + 31, k + 30, Block.glass.blockID);
		world.setBlock(i + 3, j + 31, k + 31, Block.glass.blockID);
		world.setBlock(i + 3, j + 31, k + 32, Block.glass.blockID);
		world.setBlock(i + 3, j + 31, k + 33, Block.glass.blockID);
		world.setBlock(i + 3, j + 31, k + 34, Block.glass.blockID);
		world.setBlock(i + 3, j + 31, k + 35, Block.glass.blockID);
		world.setBlock(i + 3, j + 31, k + 36, Block.glass.blockID);
		world.setBlock(i + 3, j + 31, k + 37, Block.glass.blockID);
		world.setBlock(i + 3, j + 31, k + 38, Block.glass.blockID);
		world.setBlock(i + 3, j + 31, k + 39, Block.glass.blockID);
		world.setBlock(i + 3, j + 31, k + 40, Block.glass.blockID);
		world.setBlock(i + 3, j + 32, k + 14, Blocks.viriBlock.blockID);
		world.setBlock(i + 3, j + 32, k + 40, Blocks.viriBlock.blockID);
		world.setBlock(i + 4, j + 15, k + 22, Blocks.viriBlock.blockID);
		world.setBlock(i + 4, j + 15, k + 23, Blocks.viriBlock.blockID);
		world.setBlock(i + 4, j + 15, k + 24, Blocks.viriBlock.blockID);
		world.setBlock(i + 4, j + 15, k + 25, Blocks.viriBlock.blockID);
		world.setBlock(i + 4, j + 15, k + 26, Blocks.viriBlock.blockID);
		world.setBlock(i + 4, j + 15, k + 27, Blocks.viriBlock.blockID);
		world.setBlock(i + 4, j + 15, k + 28, Blocks.viriBlock.blockID);
		world.setBlock(i + 4, j + 15, k + 29, Blocks.viriBlock.blockID);
		world.setBlock(i + 4, j + 15, k + 30, Blocks.viriBlock.blockID);
		world.setBlock(i + 4, j + 15, k + 31, Blocks.viriBlock.blockID);
		world.setBlock(i + 4, j + 15, k + 32, Blocks.viriBlock.blockID);
		world.setBlock(i + 4, j + 16, k + 20, Blocks.viriBlock.blockID);
		world.setBlock(i + 4, j + 16, k + 21, Blocks.viriBlock.blockID);
		world.setBlock(i + 4, j + 16, k + 33, Blocks.viriBlock.blockID);
		world.setBlock(i + 4, j + 16, k + 34, Blocks.viriBlock.blockID);
		world.setBlock(i + 4, j + 17, k + 19, Blocks.viriBlock.blockID);
		world.setBlock(i + 4, j + 17, k + 35, Blocks.viriBlock.blockID);
		world.setBlock(i + 4, j + 18, k + 17, Blocks.viriBlock.blockID);
		world.setBlock(i + 4, j + 18, k + 18, Blocks.viriBlock.blockID);
		world.setBlock(i + 4, j + 18, k + 36, Blocks.viriBlock.blockID);
		world.setBlock(i + 4, j + 18, k + 37, Blocks.viriBlock.blockID);
		world.setBlock(i + 4, j + 19, k + 16, Blocks.viriBlock.blockID);
		world.setBlock(i + 4, j + 19, k + 17, Blocks.viriBlock.blockID);
		world.setBlock(i + 4, j + 19, k + 37, Blocks.viriBlock.blockID);
		world.setBlock(i + 4, j + 19, k + 38, Blocks.viriBlock.blockID);
		world.setBlock(i + 4, j + 20, k + 16, Blocks.viriBlock.blockID);
		world.setBlock(i + 4, j + 20, k + 38, Blocks.viriBlock.blockID);
		world.setBlock(i + 4, j + 21, k + 15, Blocks.viriBlock.blockID);
		world.setBlock(i + 4, j + 21, k + 39, Blocks.viriBlock.blockID);
		world.setBlock(i + 4, j + 22, k + 14, Blocks.viriBlock.blockID);
		world.setBlock(i + 4, j + 22, k + 40, Blocks.viriBlock.blockID);
		world.setBlock(i + 4, j + 23, k + 14, Blocks.viriBlock.blockID);
		world.setBlock(i + 4, j + 23, k + 40, Blocks.viriBlock.blockID);
		world.setBlock(i + 4, j + 24, k + 13, Blocks.viriBlock.blockID);
		world.setBlock(i + 4, j + 24, k + 41, Blocks.viriBlock.blockID);
		world.setBlock(i + 4, j + 25, k + 13, Blocks.viriBlock.blockID);
		world.setBlock(i + 4, j + 25, k + 41, Blocks.viriBlock.blockID);
		world.setBlock(i + 4, j + 26, k + 13, Blocks.viriBlock.blockID);
		world.setBlock(i + 4, j + 26, k + 41, Blocks.viriBlock.blockID);
		world.setBlock(i + 4, j + 27, k + 13, Blocks.viriBlock.blockID);
		world.setBlock(i + 4, j + 27, k + 41, Blocks.viriBlock.blockID);
		world.setBlock(i + 4, j + 28, k + 13, Blocks.viriBlock.blockID);
		world.setBlock(i + 4, j + 28, k + 41, Blocks.viriBlock.blockID);
		world.setBlock(i + 4, j + 29, k + 13, Blocks.viriBlock.blockID);
		world.setBlock(i + 4, j + 29, k + 41, Blocks.viriBlock.blockID);
		world.setBlock(i + 4, j + 30, k + 13, Blocks.viriBlock.blockID);
		world.setBlock(i + 4, j + 30, k + 41, Blocks.viriBlock.blockID);
		world.setBlock(i + 4, j + 31, k + 13, Block.glass.blockID);
		world.setBlock(i + 4, j + 31, k + 14, Block.glass.blockID);
		world.setBlock(i + 4, j + 31, k + 15, Block.glass.blockID);
		world.setBlock(i + 4, j + 31, k + 16, Block.glass.blockID);
		world.setBlock(i + 4, j + 31, k + 17, Block.glass.blockID);
		world.setBlock(i + 4, j + 31, k + 18, Block.glass.blockID);
		world.setBlock(i + 4, j + 31, k + 19, Block.glass.blockID);
		world.setBlock(i + 4, j + 31, k + 20, Block.glass.blockID);
		world.setBlock(i + 4, j + 31, k + 21, Block.glass.blockID);
		world.setBlock(i + 4, j + 31, k + 22, Block.glass.blockID);
		world.setBlock(i + 4, j + 31, k + 23, Block.glass.blockID);
		world.setBlock(i + 4, j + 31, k + 24, Block.glass.blockID);
		world.setBlock(i + 4, j + 31, k + 25, Block.glass.blockID);
		world.setBlock(i + 4, j + 31, k + 26, Block.glass.blockID);
		world.setBlock(i + 4, j + 31, k + 27, Block.glass.blockID);
		world.setBlock(i + 4, j + 31, k + 28, Block.glass.blockID);
		world.setBlock(i + 4, j + 31, k + 29, Block.glass.blockID);
		world.setBlock(i + 4, j + 31, k + 30, Block.glass.blockID);
		world.setBlock(i + 4, j + 31, k + 31, Block.glass.blockID);
		world.setBlock(i + 4, j + 31, k + 32, Block.glass.blockID);
		world.setBlock(i + 4, j + 31, k + 33, Block.glass.blockID);
		world.setBlock(i + 4, j + 31, k + 34, Block.glass.blockID);
		world.setBlock(i + 4, j + 31, k + 35, Block.glass.blockID);
		world.setBlock(i + 4, j + 31, k + 36, Block.glass.blockID);
		world.setBlock(i + 4, j + 31, k + 37, Block.glass.blockID);
		world.setBlock(i + 4, j + 31, k + 38, Block.glass.blockID);
		world.setBlock(i + 4, j + 31, k + 39, Block.glass.blockID);
		world.setBlock(i + 4, j + 31, k + 40, Block.glass.blockID);
		world.setBlock(i + 4, j + 31, k + 41, Block.glass.blockID);
		world.setBlock(i + 4, j + 32, k + 13, Blocks.viriBlock.blockID);
		world.setBlock(i + 4, j + 32, k + 41, Blocks.viriBlock.blockID);
		world.setBlock(i + 5, j + 14, k + 22, Blocks.viriBlock.blockID);
		world.setBlock(i + 5, j + 14, k + 23, Blocks.viriBlock.blockID);
		world.setBlock(i + 5, j + 14, k + 24, Blocks.viriBlock.blockID);
		world.setBlock(i + 5, j + 14, k + 25, Blocks.viriBlock.blockID);
		world.setBlock(i + 5, j + 14, k + 26, Blocks.viriBlock.blockID);
		world.setBlock(i + 5, j + 14, k + 27, Blocks.viriBlock.blockID);
		world.setBlock(i + 5, j + 14, k + 28, Blocks.viriBlock.blockID);
		world.setBlock(i + 5, j + 14, k + 29, Blocks.viriBlock.blockID);
		world.setBlock(i + 5, j + 14, k + 30, Blocks.viriBlock.blockID);
		world.setBlock(i + 5, j + 14, k + 31, Blocks.viriBlock.blockID);
		world.setBlock(i + 5, j + 14, k + 32, Blocks.viriBlock.blockID);
		world.setBlock(i + 5, j + 15, k + 20, Blocks.viriBlock.blockID);
		world.setBlock(i + 5, j + 15, k + 21, Blocks.viriBlock.blockID);
		world.setBlock(i + 5, j + 15, k + 33, Blocks.viriBlock.blockID);
		world.setBlock(i + 5, j + 15, k + 34, Blocks.viriBlock.blockID);
		world.setBlock(i + 5, j + 16, k + 18, Blocks.viriBlock.blockID);
		world.setBlock(i + 5, j + 16, k + 19, Blocks.viriBlock.blockID);
		world.setBlock(i + 5, j + 16, k + 35, Blocks.viriBlock.blockID);
		world.setBlock(i + 5, j + 16, k + 36, Blocks.viriBlock.blockID);
		world.setBlock(i + 5, j + 17, k + 17, Blocks.viriBlock.blockID);
		world.setBlock(i + 5, j + 17, k + 18, Blocks.viriBlock.blockID);
		world.setBlock(i + 5, j + 17, k + 36, Blocks.viriBlock.blockID);
		world.setBlock(i + 5, j + 17, k + 37, Blocks.viriBlock.blockID);
		world.setBlock(i + 5, j + 18, k + 16, Blocks.viriBlock.blockID);
		world.setBlock(i + 5, j + 18, k + 38, Blocks.viriBlock.blockID);
		world.setBlock(i + 5, j + 19, k + 15, Blocks.viriBlock.blockID);
		world.setBlock(i + 5, j + 19, k + 39, Blocks.viriBlock.blockID);
		world.setBlock(i + 5, j + 20, k + 14, Blocks.viriBlock.blockID);
		world.setBlock(i + 5, j + 20, k + 15, Blocks.viriBlock.blockID);
		world.setBlock(i + 5, j + 20, k + 39, Blocks.viriBlock.blockID);
		world.setBlock(i + 5, j + 20, k + 40, Blocks.viriBlock.blockID);
		world.setBlock(i + 5, j + 21, k + 14, Blocks.viriBlock.blockID);
		world.setBlock(i + 5, j + 21, k + 40, Blocks.viriBlock.blockID);
		world.setBlock(i + 5, j + 22, k + 13, Blocks.viriBlock.blockID);
		world.setBlock(i + 5, j + 22, k + 41, Blocks.viriBlock.blockID);
		world.setBlock(i + 5, j + 23, k + 13, Blocks.viriBlock.blockID);
		world.setBlock(i + 5, j + 23, k + 41, Blocks.viriBlock.blockID);
		world.setBlock(i + 5, j + 24, k + 12, Blocks.viriBlock.blockID);
		world.setBlock(i + 5, j + 24, k + 42, Blocks.viriBlock.blockID);
		world.setBlock(i + 5, j + 25, k + 12, Blocks.viriBlock.blockID);
		world.setBlock(i + 5, j + 25, k + 42, Blocks.viriBlock.blockID);
		world.setBlock(i + 5, j + 26, k + 12, Blocks.viriBlock.blockID);
		world.setBlock(i + 5, j + 26, k + 42, Blocks.viriBlock.blockID);
		world.setBlock(i + 5, j + 27, k + 12, Blocks.viriBlock.blockID);
		world.setBlock(i + 5, j + 27, k + 42, Blocks.viriBlock.blockID);
		world.setBlock(i + 5, j + 28, k + 12, Blocks.viriBlock.blockID);
		world.setBlock(i + 5, j + 28, k + 42, Blocks.viriBlock.blockID);
		world.setBlock(i + 5, j + 29, k + 12, Blocks.viriBlock.blockID);
		world.setBlock(i + 5, j + 29, k + 42, Blocks.viriBlock.blockID);
		world.setBlock(i + 5, j + 30, k + 12, Blocks.viriBlock.blockID);
		world.setBlock(i + 5, j + 30, k + 42, Blocks.viriBlock.blockID);
		world.setBlock(i + 5, j + 31, k + 12, Block.glass.blockID);
		world.setBlock(i + 5, j + 31, k + 13, Block.glass.blockID);
		world.setBlock(i + 5, j + 31, k + 14, Block.glass.blockID);
		world.setBlock(i + 5, j + 31, k + 15, Block.glass.blockID);
		world.setBlock(i + 5, j + 31, k + 16, Block.glass.blockID);
		world.setBlock(i + 5, j + 31, k + 17, Block.glass.blockID);
		world.setBlock(i + 5, j + 31, k + 18, Block.glass.blockID);
		world.setBlock(i + 5, j + 31, k + 19, Block.glass.blockID);
		world.setBlock(i + 5, j + 31, k + 20, Block.glass.blockID);
		world.setBlock(i + 5, j + 31, k + 21, Block.glass.blockID);
		world.setBlock(i + 5, j + 31, k + 22, Block.glass.blockID);
		world.setBlock(i + 5, j + 31, k + 23, Block.glass.blockID);
		world.setBlock(i + 5, j + 31, k + 24, Block.glass.blockID);
		world.setBlock(i + 5, j + 31, k + 25, Block.glass.blockID);
		world.setBlock(i + 5, j + 31, k + 26, Block.glass.blockID);
		world.setBlock(i + 5, j + 31, k + 27, Block.glass.blockID);
		world.setBlock(i + 5, j + 31, k + 28, Block.glass.blockID);
		world.setBlock(i + 5, j + 31, k + 29, Block.glass.blockID);
		world.setBlock(i + 5, j + 31, k + 30, Block.glass.blockID);
		world.setBlock(i + 5, j + 31, k + 31, Block.glass.blockID);
		world.setBlock(i + 5, j + 31, k + 32, Block.glass.blockID);
		world.setBlock(i + 5, j + 31, k + 33, Block.glass.blockID);
		world.setBlock(i + 5, j + 31, k + 34, Block.glass.blockID);
		world.setBlock(i + 5, j + 31, k + 35, Block.glass.blockID);
		world.setBlock(i + 5, j + 31, k + 36, Block.glass.blockID);
		world.setBlock(i + 5, j + 31, k + 37, Block.glass.blockID);
		world.setBlock(i + 5, j + 31, k + 38, Block.glass.blockID);
		world.setBlock(i + 5, j + 31, k + 39, Block.glass.blockID);
		world.setBlock(i + 5, j + 31, k + 40, Block.glass.blockID);
		world.setBlock(i + 5, j + 31, k + 41, Block.glass.blockID);
		world.setBlock(i + 5, j + 31, k + 42, Block.glass.blockID);
		world.setBlock(i + 5, j + 32, k + 12, Blocks.viriBlock.blockID);
		world.setBlock(i + 5, j + 32, k + 42, Blocks.viriBlock.blockID);
		world.setBlock(i + 6, j + 13, k + 23, Blocks.viriBlock.blockID);
		world.setBlock(i + 6, j + 13, k + 24, Blocks.viriBlock.blockID);
		world.setBlock(i + 6, j + 13, k + 25, Blocks.viriBlock.blockID);
		world.setBlock(i + 6, j + 13, k + 26, Blocks.viriBlock.blockID);
		world.setBlock(i + 6, j + 13, k + 27, Blocks.viriBlock.blockID);
		world.setBlock(i + 6, j + 13, k + 28, Blocks.viriBlock.blockID);
		world.setBlock(i + 6, j + 13, k + 29, Blocks.viriBlock.blockID);
		world.setBlock(i + 6, j + 13, k + 30, Blocks.viriBlock.blockID);
		world.setBlock(i + 6, j + 13, k + 31, Blocks.viriBlock.blockID);
		world.setBlock(i + 6, j + 14, k + 20, Blocks.viriBlock.blockID);
		world.setBlock(i + 6, j + 14, k + 21, Blocks.viriBlock.blockID);
		world.setBlock(i + 6, j + 14, k + 22, Blocks.viriBlock.blockID);
		world.setBlock(i + 6, j + 14, k + 32, Blocks.viriBlock.blockID);
		world.setBlock(i + 6, j + 14, k + 33, Blocks.viriBlock.blockID);
		world.setBlock(i + 6, j + 14, k + 34, Blocks.viriBlock.blockID);
		world.setBlock(i + 6, j + 15, k + 19, Blocks.viriBlock.blockID);
		world.setBlock(i + 6, j + 15, k + 35, Blocks.viriBlock.blockID);
		world.setBlock(i + 6, j + 16, k + 17, Blocks.viriBlock.blockID);
		world.setBlock(i + 6, j + 16, k + 18, Blocks.viriBlock.blockID);
		world.setBlock(i + 6, j + 16, k + 36, Blocks.viriBlock.blockID);
		world.setBlock(i + 6, j + 16, k + 37, Blocks.viriBlock.blockID);
		world.setBlock(i + 6, j + 17, k + 16, Blocks.viriBlock.blockID);
		world.setBlock(i + 6, j + 17, k + 38, Blocks.viriBlock.blockID);
		world.setBlock(i + 6, j + 18, k + 15, Blocks.viriBlock.blockID);
		world.setBlock(i + 6, j + 18, k + 39, Blocks.viriBlock.blockID);
		world.setBlock(i + 6, j + 19, k + 14, Blocks.viriBlock.blockID);
		world.setBlock(i + 6, j + 19, k + 40, Blocks.viriBlock.blockID);
		world.setBlock(i + 6, j + 20, k + 14, Blocks.viriBlock.blockID);
		world.setBlock(i + 6, j + 20, k + 40, Blocks.viriBlock.blockID);
		world.setBlock(i + 6, j + 21, k + 13, Blocks.viriBlock.blockID);
		world.setBlock(i + 6, j + 21, k + 41, Blocks.viriBlock.blockID);
		world.setBlock(i + 6, j + 22, k + 12, Blocks.viriBlock.blockID);
		world.setBlock(i + 6, j + 22, k + 42, Blocks.viriBlock.blockID);
		world.setBlock(i + 6, j + 23, k + 12, Blocks.viriBlock.blockID);
		world.setBlock(i + 6, j + 23, k + 42, Blocks.viriBlock.blockID);
		world.setBlock(i + 6, j + 24, k + 12, Blocks.viriBlock.blockID);
		world.setBlock(i + 6, j + 24, k + 42, Blocks.viriBlock.blockID);
		world.setBlock(i + 6, j + 25, k + 11, Blocks.viriBlock.blockID);
		world.setBlock(i + 6, j + 25, k + 43, Blocks.viriBlock.blockID);
		world.setBlock(i + 6, j + 26, k + 11, Blocks.viriBlock.blockID);
		world.setBlock(i + 6, j + 26, k + 43, Blocks.viriBlock.blockID);
		world.setBlock(i + 6, j + 27, k + 11, Blocks.viriBlock.blockID);
		world.setBlock(i + 6, j + 27, k + 43, Blocks.viriBlock.blockID);
		world.setBlock(i + 6, j + 28, k + 11, Blocks.viriBlock.blockID);
		world.setBlock(i + 6, j + 28, k + 43, Blocks.viriBlock.blockID);
		world.setBlock(i + 6, j + 29, k + 11, Blocks.viriBlock.blockID);
		world.setBlock(i + 6, j + 29, k + 43, Blocks.viriBlock.blockID);
		world.setBlock(i + 6, j + 30, k + 11, Blocks.viriBlock.blockID);
		world.setBlock(i + 6, j + 30, k + 43, Blocks.viriBlock.blockID);
		world.setBlock(i + 6, j + 31, k + 11, Block.glass.blockID);
		world.setBlock(i + 6, j + 31, k + 12, Block.glass.blockID);
		world.setBlock(i + 6, j + 31, k + 13, Block.glass.blockID);
		world.setBlock(i + 6, j + 31, k + 14, Block.glass.blockID);
		world.setBlock(i + 6, j + 31, k + 15, Block.glass.blockID);
		world.setBlock(i + 6, j + 31, k + 16, Block.glass.blockID);
		world.setBlock(i + 6, j + 31, k + 17, Block.glass.blockID);
		world.setBlock(i + 6, j + 31, k + 18, Block.glass.blockID);
		world.setBlock(i + 6, j + 31, k + 19, Block.glass.blockID);
		world.setBlock(i + 6, j + 31, k + 20, Block.glass.blockID);
		world.setBlock(i + 6, j + 31, k + 21, Block.glass.blockID);
		world.setBlock(i + 6, j + 31, k + 22, Block.glass.blockID);
		world.setBlock(i + 6, j + 31, k + 23, Block.glass.blockID);
		world.setBlock(i + 6, j + 31, k + 24, Block.glass.blockID);
		world.setBlock(i + 6, j + 31, k + 25, Block.glass.blockID);
		world.setBlock(i + 6, j + 31, k + 26, Block.glass.blockID);
		world.setBlock(i + 6, j + 31, k + 27, Block.glass.blockID);
		world.setBlock(i + 6, j + 31, k + 28, Block.glass.blockID);
		world.setBlock(i + 6, j + 31, k + 29, Block.glass.blockID);
		world.setBlock(i + 6, j + 31, k + 30, Block.glass.blockID);
		world.setBlock(i + 6, j + 31, k + 31, Block.glass.blockID);
		world.setBlock(i + 6, j + 31, k + 32, Block.glass.blockID);
		world.setBlock(i + 6, j + 31, k + 33, Block.glass.blockID);
		world.setBlock(i + 6, j + 31, k + 34, Block.glass.blockID);
		world.setBlock(i + 6, j + 31, k + 35, Block.glass.blockID);
		world.setBlock(i + 6, j + 31, k + 36, Block.glass.blockID);
		world.setBlock(i + 6, j + 31, k + 37, Block.glass.blockID);
		world.setBlock(i + 6, j + 31, k + 38, Block.glass.blockID);
		world.setBlock(i + 6, j + 31, k + 39, Block.glass.blockID);
		world.setBlock(i + 6, j + 31, k + 40, Block.glass.blockID);
		world.setBlock(i + 6, j + 31, k + 41, Block.glass.blockID);
		world.setBlock(i + 6, j + 31, k + 42, Block.glass.blockID);
		world.setBlock(i + 6, j + 31, k + 43, Block.glass.blockID);
		world.setBlock(i + 6, j + 32, k + 11, Blocks.viriBlock.blockID);
		world.setBlock(i + 6, j + 32, k + 43, Blocks.viriBlock.blockID);
		world.setBlock(i + 7, j + 12, k + 24, Blocks.viriBlock.blockID);
		world.setBlock(i + 7, j + 12, k + 25, Blocks.viriBlock.blockID);
		world.setBlock(i + 7, j + 12, k + 26, Blocks.viriBlock.blockID);
		world.setBlock(i + 7, j + 12, k + 27, Blocks.viriBlock.blockID);
		world.setBlock(i + 7, j + 12, k + 28, Blocks.viriBlock.blockID);
		world.setBlock(i + 7, j + 12, k + 29, Blocks.viriBlock.blockID);
		world.setBlock(i + 7, j + 12, k + 30, Blocks.viriBlock.blockID);
		world.setBlock(i + 7, j + 13, k + 21, Blocks.viriBlock.blockID);
		world.setBlock(i + 7, j + 13, k + 22, Blocks.viriBlock.blockID);
		world.setBlock(i + 7, j + 13, k + 23, Blocks.viriBlock.blockID);
		world.setBlock(i + 7, j + 13, k + 31, Blocks.viriBlock.blockID);
		world.setBlock(i + 7, j + 13, k + 32, Blocks.viriBlock.blockID);
		world.setBlock(i + 7, j + 13, k + 33, Blocks.viriBlock.blockID);
		world.setBlock(i + 7, j + 14, k + 19, Blocks.viriBlock.blockID);
		world.setBlock(i + 7, j + 14, k + 20, Blocks.viriBlock.blockID);
		world.setBlock(i + 7, j + 14, k + 34, Blocks.viriBlock.blockID);
		world.setBlock(i + 7, j + 14, k + 35, Blocks.viriBlock.blockID);
		world.setBlock(i + 7, j + 15, k + 17, Blocks.viriBlock.blockID);
		world.setBlock(i + 7, j + 15, k + 18, Blocks.viriBlock.blockID);
		world.setBlock(i + 7, j + 15, k + 36, Blocks.viriBlock.blockID);
		world.setBlock(i + 7, j + 15, k + 37, Blocks.viriBlock.blockID);
		world.setBlock(i + 7, j + 16, k + 16, Blocks.viriBlock.blockID);
		world.setBlock(i + 7, j + 16, k + 38, Blocks.viriBlock.blockID);
		world.setBlock(i + 7, j + 17, k + 15, Blocks.viriBlock.blockID);
		world.setBlock(i + 7, j + 17, k + 39, Blocks.viriBlock.blockID);
		world.setBlock(i + 7, j + 18, k + 14, Blocks.viriBlock.blockID);
		world.setBlock(i + 7, j + 18, k + 40, Blocks.viriBlock.blockID);
		world.setBlock(i + 7, j + 19, k + 13, Blocks.viriBlock.blockID);
		world.setBlock(i + 7, j + 19, k + 41, Blocks.viriBlock.blockID);
		world.setBlock(i + 7, j + 20, k + 13, Blocks.viriBlock.blockID);
		world.setBlock(i + 7, j + 20, k + 41, Blocks.viriBlock.blockID);
		world.setBlock(i + 7, j + 21, k + 12, Blocks.viriBlock.blockID);
		world.setBlock(i + 7, j + 21, k + 42, Blocks.viriBlock.blockID);
		world.setBlock(i + 7, j + 22, k + 12, Blocks.viriBlock.blockID);
		world.setBlock(i + 7, j + 22, k + 42, Blocks.viriBlock.blockID);
		world.setBlock(i + 7, j + 23, k + 11, Blocks.viriBlock.blockID);
		world.setBlock(i + 7, j + 23, k + 43, Blocks.viriBlock.blockID);
		world.setBlock(i + 7, j + 24, k + 11, Blocks.viriBlock.blockID);
		world.setBlock(i + 7, j + 24, k + 43, Blocks.viriBlock.blockID);
		world.setBlock(i + 7, j + 25, k + 11, Blocks.viriBlock.blockID);
		world.setBlock(i + 7, j + 25, k + 43, Blocks.viriBlock.blockID);
		world.setBlock(i + 7, j + 26, k + 10, Blocks.viriBlock.blockID);
		world.setBlock(i + 7, j + 26, k + 44, Blocks.viriBlock.blockID);
		world.setBlock(i + 7, j + 27, k + 10, Blocks.viriBlock.blockID);
		world.setBlock(i + 7, j + 27, k + 44, Blocks.viriBlock.blockID);
		world.setBlock(i + 7, j + 28, k + 10, Blocks.viriBlock.blockID);
		world.setBlock(i + 7, j + 28, k + 44, Blocks.viriBlock.blockID);
		world.setBlock(i + 7, j + 29, k + 10, Blocks.viriBlock.blockID);
		world.setBlock(i + 7, j + 29, k + 44, Blocks.viriBlock.blockID);
		world.setBlock(i + 7, j + 30, k + 10, Blocks.viriBlock.blockID);
		world.setBlock(i + 7, j + 30, k + 44, Blocks.viriBlock.blockID);
		world.setBlock(i + 7, j + 31, k + 10, Block.glass.blockID);
		world.setBlock(i + 7, j + 31, k + 11, Block.glass.blockID);
		world.setBlock(i + 7, j + 31, k + 12, Block.glass.blockID);
		world.setBlock(i + 7, j + 31, k + 13, Block.glass.blockID);
		world.setBlock(i + 7, j + 31, k + 14, Block.glass.blockID);
		world.setBlock(i + 7, j + 31, k + 15, Block.glass.blockID);
		world.setBlock(i + 7, j + 31, k + 16, Block.glass.blockID);
		world.setBlock(i + 7, j + 31, k + 17, Block.glass.blockID);
		world.setBlock(i + 7, j + 31, k + 18, Block.glass.blockID);
		world.setBlock(i + 7, j + 31, k + 19, Block.glass.blockID);
		world.setBlock(i + 7, j + 31, k + 20, Block.glass.blockID);
		world.setBlock(i + 7, j + 31, k + 21, Block.glass.blockID);
		world.setBlock(i + 7, j + 31, k + 22, Block.glass.blockID);
		world.setBlock(i + 7, j + 31, k + 23, Block.glass.blockID);
		world.setBlock(i + 7, j + 31, k + 24, Block.glass.blockID);
		world.setBlock(i + 7, j + 31, k + 25, Block.glass.blockID);
		world.setBlock(i + 7, j + 31, k + 26, Block.glass.blockID);
		world.setBlock(i + 7, j + 31, k + 27, Block.glass.blockID);
		world.setBlock(i + 7, j + 31, k + 28, Block.glass.blockID);
		world.setBlock(i + 7, j + 31, k + 29, Block.glass.blockID);
		world.setBlock(i + 7, j + 31, k + 30, Block.glass.blockID);
		world.setBlock(i + 7, j + 31, k + 31, Block.glass.blockID);
		world.setBlock(i + 7, j + 31, k + 32, Block.glass.blockID);
		world.setBlock(i + 7, j + 31, k + 33, Block.glass.blockID);
		world.setBlock(i + 7, j + 31, k + 34, Block.glass.blockID);
		world.setBlock(i + 7, j + 31, k + 35, Block.glass.blockID);
		world.setBlock(i + 7, j + 31, k + 36, Block.glass.blockID);
		world.setBlock(i + 7, j + 31, k + 37, Block.glass.blockID);
		world.setBlock(i + 7, j + 31, k + 38, Block.glass.blockID);
		world.setBlock(i + 7, j + 31, k + 39, Block.glass.blockID);
		world.setBlock(i + 7, j + 31, k + 40, Block.glass.blockID);
		world.setBlock(i + 7, j + 31, k + 41, Block.glass.blockID);
		world.setBlock(i + 7, j + 31, k + 42, Block.glass.blockID);
		world.setBlock(i + 7, j + 31, k + 43, Block.glass.blockID);
		world.setBlock(i + 7, j + 31, k + 44, Block.glass.blockID);
		world.setBlock(i + 7, j + 32, k + 10, Blocks.viriBlock.blockID);
		world.setBlock(i + 7, j + 32, k + 44, Blocks.viriBlock.blockID);
		world.setBlock(i + 8, j + 12, k + 22, Blocks.viriBlock.blockID);
		world.setBlock(i + 8, j + 12, k + 23, Blocks.viriBlock.blockID);
		world.setBlock(i + 8, j + 12, k + 24, Blocks.viriBlock.blockID);
		world.setBlock(i + 8, j + 12, k + 25, Blocks.viriBlock.blockID);
		world.setBlock(i + 8, j + 12, k + 26, Blocks.viriBlock.blockID);
		world.setBlock(i + 8, j + 12, k + 27, Blocks.viriBlock.blockID);
		world.setBlock(i + 8, j + 12, k + 28, Blocks.viriBlock.blockID);
		world.setBlock(i + 8, j + 12, k + 29, Blocks.viriBlock.blockID);
		world.setBlock(i + 8, j + 12, k + 30, Blocks.viriBlock.blockID);
		world.setBlock(i + 8, j + 12, k + 31, Blocks.viriBlock.blockID);
		world.setBlock(i + 8, j + 12, k + 32, Blocks.viriBlock.blockID);
		world.setBlock(i + 8, j + 13, k + 19, Blocks.viriBlock.blockID);
		world.setBlock(i + 8, j + 13, k + 20, Blocks.viriBlock.blockID);
		world.setBlock(i + 8, j + 13, k + 21, Blocks.viriBlock.blockID);
		world.setBlock(i + 8, j + 13, k + 33, Blocks.viriBlock.blockID);
		world.setBlock(i + 8, j + 13, k + 34, Blocks.viriBlock.blockID);
		world.setBlock(i + 8, j + 13, k + 35, Blocks.viriBlock.blockID);
		world.setBlock(i + 8, j + 14, k + 18, Blocks.viriBlock.blockID);
		world.setBlock(i + 8, j + 14, k + 36, Blocks.viriBlock.blockID);
		world.setBlock(i + 8, j + 15, k + 16, Blocks.viriBlock.blockID);
		world.setBlock(i + 8, j + 15, k + 17, Blocks.viriBlock.blockID);
		world.setBlock(i + 8, j + 15, k + 37, Blocks.viriBlock.blockID);
		world.setBlock(i + 8, j + 15, k + 38, Blocks.viriBlock.blockID);
		world.setBlock(i + 8, j + 16, k + 15, Blocks.viriBlock.blockID);
		world.setBlock(i + 8, j + 16, k + 39, Blocks.viriBlock.blockID);
		world.setBlock(i + 8, j + 17, k + 14, Blocks.viriBlock.blockID);
		world.setBlock(i + 8, j + 17, k + 40, Blocks.viriBlock.blockID);
		world.setBlock(i + 8, j + 18, k + 13, Blocks.viriBlock.blockID);
		world.setBlock(i + 8, j + 18, k + 41, Blocks.viriBlock.blockID);
		world.setBlock(i + 8, j + 19, k + 13, Blocks.viriBlock.blockID);
		world.setBlock(i + 8, j + 19, k + 41, Blocks.viriBlock.blockID);
		world.setBlock(i + 8, j + 20, k + 12, Blocks.viriBlock.blockID);
		world.setBlock(i + 8, j + 20, k + 42, Blocks.viriBlock.blockID);
		world.setBlock(i + 8, j + 21, k + 11, Blocks.viriBlock.blockID);
		world.setBlock(i + 8, j + 21, k + 43, Blocks.viriBlock.blockID);
		world.setBlock(i + 8, j + 22, k + 11, Blocks.viriBlock.blockID);
		world.setBlock(i + 8, j + 22, k + 43, Blocks.viriBlock.blockID);
		world.setBlock(i + 8, j + 23, k + 11, Blocks.viriBlock.blockID);
		world.setBlock(i + 8, j + 23, k + 43, Blocks.viriBlock.blockID);
		world.setBlock(i + 8, j + 24, k + 10, Blocks.viriBlock.blockID);
		world.setBlock(i + 8, j + 24, k + 44, Blocks.viriBlock.blockID);
		world.setBlock(i + 8, j + 25, k + 10, Blocks.viriBlock.blockID);
		world.setBlock(i + 8, j + 25, k + 44, Blocks.viriBlock.blockID);
		world.setBlock(i + 8, j + 26, k + 10, Blocks.viriBlock.blockID);
		world.setBlock(i + 8, j + 26, k + 44, Blocks.viriBlock.blockID);
		world.setBlock(i + 8, j + 27, k + 10, Blocks.viriBlock.blockID);
		world.setBlock(i + 8, j + 27, k + 44, Blocks.viriBlock.blockID);
		world.setBlock(i + 8, j + 28, k + 10, Blocks.viriBlock.blockID);
		world.setBlock(i + 8, j + 28, k + 44, Blocks.viriBlock.blockID);
		world.setBlock(i + 8, j + 29, k + 10, Blocks.viriBlock.blockID);
		world.setBlock(i + 8, j + 29, k + 44, Blocks.viriBlock.blockID);
		world.setBlock(i + 8, j + 30, k + 10, Blocks.viriBlock.blockID);
		world.setBlock(i + 8, j + 30, k + 44, Blocks.viriBlock.blockID);
		world.setBlock(i + 8, j + 31, k + 10, Block.glass.blockID);
		world.setBlock(i + 8, j + 31, k + 11, Block.glass.blockID);
		world.setBlock(i + 8, j + 31, k + 12, Block.glass.blockID);
		world.setBlock(i + 8, j + 31, k + 13, Block.glass.blockID);
		world.setBlock(i + 8, j + 31, k + 14, Block.glass.blockID);
		world.setBlock(i + 8, j + 31, k + 15, Block.glass.blockID);
		world.setBlock(i + 8, j + 31, k + 16, Block.glass.blockID);
		world.setBlock(i + 8, j + 31, k + 17, Block.glass.blockID);
		world.setBlock(i + 8, j + 31, k + 18, Block.glass.blockID);
		world.setBlock(i + 8, j + 31, k + 19, Block.glass.blockID);
		world.setBlock(i + 8, j + 31, k + 20, Block.glass.blockID);
		world.setBlock(i + 8, j + 31, k + 21, Block.glass.blockID);
		world.setBlock(i + 8, j + 31, k + 22, Block.glass.blockID);
		world.setBlock(i + 8, j + 31, k + 23, Block.glass.blockID);
		world.setBlock(i + 8, j + 31, k + 24, Block.glass.blockID);
		world.setBlock(i + 8, j + 31, k + 25, Block.glass.blockID);
		world.setBlock(i + 8, j + 31, k + 26, Block.glass.blockID);
		world.setBlock(i + 8, j + 31, k + 27, Block.glass.blockID);
		world.setBlock(i + 8, j + 31, k + 28, Block.glass.blockID);
		world.setBlock(i + 8, j + 31, k + 29, Block.glass.blockID);
		world.setBlock(i + 8, j + 31, k + 30, Block.glass.blockID);
		world.setBlock(i + 8, j + 31, k + 31, Block.glass.blockID);
		world.setBlock(i + 8, j + 31, k + 32, Block.glass.blockID);
		world.setBlock(i + 8, j + 31, k + 33, Block.glass.blockID);
		world.setBlock(i + 8, j + 31, k + 34, Block.glass.blockID);
		world.setBlock(i + 8, j + 31, k + 35, Block.glass.blockID);
		world.setBlock(i + 8, j + 31, k + 36, Block.glass.blockID);
		world.setBlock(i + 8, j + 31, k + 37, Block.glass.blockID);
		world.setBlock(i + 8, j + 31, k + 38, Block.glass.blockID);
		world.setBlock(i + 8, j + 31, k + 39, Block.glass.blockID);
		world.setBlock(i + 8, j + 31, k + 40, Block.glass.blockID);
		world.setBlock(i + 8, j + 31, k + 41, Block.glass.blockID);
		world.setBlock(i + 8, j + 31, k + 42, Block.glass.blockID);
		world.setBlock(i + 8, j + 31, k + 43, Block.glass.blockID);
		world.setBlock(i + 8, j + 31, k + 44, Block.glass.blockID);
		world.setBlock(i + 8, j + 32, k + 10, Blocks.viriBlock.blockID);
		world.setBlock(i + 8, j + 32, k + 44, Blocks.viriBlock.blockID);
		world.setBlock(i + 9, j + 11, k + 24, Blocks.viriBlock.blockID);
		world.setBlock(i + 9, j + 11, k + 25, Blocks.viriBlock.blockID);
		world.setBlock(i + 9, j + 11, k + 26, Blocks.viriBlock.blockID);
		world.setBlock(i + 9, j + 11, k + 27, Blocks.viriBlock.blockID);
		world.setBlock(i + 9, j + 11, k + 28, Blocks.viriBlock.blockID);
		world.setBlock(i + 9, j + 11, k + 29, Blocks.viriBlock.blockID);
		world.setBlock(i + 9, j + 11, k + 30, Blocks.viriBlock.blockID);
		world.setBlock(i + 9, j + 12, k + 20, Blocks.viriBlock.blockID);
		world.setBlock(i + 9, j + 12, k + 21, Blocks.viriBlock.blockID);
		world.setBlock(i + 9, j + 12, k + 22, Blocks.viriBlock.blockID);
		world.setBlock(i + 9, j + 12, k + 23, Blocks.viriBlock.blockID);
		world.setBlock(i + 9, j + 12, k + 31, Blocks.viriBlock.blockID);
		world.setBlock(i + 9, j + 12, k + 32, Blocks.viriBlock.blockID);
		world.setBlock(i + 9, j + 12, k + 33, Blocks.viriBlock.blockID);
		world.setBlock(i + 9, j + 12, k + 34, Blocks.viriBlock.blockID);
		world.setBlock(i + 9, j + 13, k + 18, Blocks.viriBlock.blockID);
		world.setBlock(i + 9, j + 13, k + 19, Blocks.viriBlock.blockID);
		world.setBlock(i + 9, j + 13, k + 35, Blocks.viriBlock.blockID);
		world.setBlock(i + 9, j + 13, k + 36, Blocks.viriBlock.blockID);
		world.setBlock(i + 9, j + 14, k + 17, Blocks.viriBlock.blockID);
		world.setBlock(i + 9, j + 14, k + 37, Blocks.viriBlock.blockID);
		world.setBlock(i + 9, j + 15, k + 16, Blocks.viriBlock.blockID);
		world.setBlock(i + 9, j + 15, k + 38, Blocks.viriBlock.blockID);
		world.setBlock(i + 9, j + 16, k + 14, Blocks.viriBlock.blockID);
		world.setBlock(i + 9, j + 16, k + 15, Blocks.viriBlock.blockID);
		world.setBlock(i + 9, j + 16, k + 39, Blocks.viriBlock.blockID);
		world.setBlock(i + 9, j + 16, k + 40, Blocks.viriBlock.blockID);
		world.setBlock(i + 9, j + 17, k + 14, Blocks.viriBlock.blockID);
		world.setBlock(i + 9, j + 17, k + 40, Blocks.viriBlock.blockID);
		world.setBlock(i + 9, j + 18, k + 13, Blocks.viriBlock.blockID);
		world.setBlock(i + 9, j + 18, k + 41, Blocks.viriBlock.blockID);
		world.setBlock(i + 9, j + 19, k + 12, Blocks.viriBlock.blockID);
		world.setBlock(i + 9, j + 19, k + 42, Blocks.viriBlock.blockID);
		world.setBlock(i + 9, j + 20, k + 11, Blocks.viriBlock.blockID);
		world.setBlock(i + 9, j + 20, k + 43, Blocks.viriBlock.blockID);
		world.setBlock(i + 9, j + 21, k + 11, Blocks.viriBlock.blockID);
		world.setBlock(i + 9, j + 21, k + 43, Blocks.viriBlock.blockID);
		world.setBlock(i + 9, j + 22, k + 10, Blocks.viriBlock.blockID);
		world.setBlock(i + 9, j + 22, k + 44, Blocks.viriBlock.blockID);
		world.setBlock(i + 9, j + 23, k + 10, Blocks.viriBlock.blockID);
		world.setBlock(i + 9, j + 23, k + 44, Blocks.viriBlock.blockID);
		world.setBlock(i + 9, j + 24, k + 10, Blocks.viriBlock.blockID);
		world.setBlock(i + 9, j + 24, k + 44, Blocks.viriBlock.blockID);
		world.setBlock(i + 9, j + 25, k + 10, Blocks.viriBlock.blockID);
		world.setBlock(i + 9, j + 25, k + 44, Blocks.viriBlock.blockID);
		world.setBlock(i + 9, j + 26, k + 9, Blocks.viriBlock.blockID);
		world.setBlock(i + 9, j + 26, k + 45, Blocks.viriBlock.blockID);
		world.setBlock(i + 9, j + 27, k + 9, Blocks.viriBlock.blockID);
		world.setBlock(i + 9, j + 27, k + 45, Blocks.viriBlock.blockID);
		world.setBlock(i + 9, j + 28, k + 9, Blocks.viriBlock.blockID);
		world.setBlock(i + 9, j + 28, k + 45, Blocks.viriBlock.blockID);
		world.setBlock(i + 9, j + 29, k + 9, Blocks.viriBlock.blockID);
		world.setBlock(i + 9, j + 29, k + 45, Blocks.viriBlock.blockID);
		world.setBlock(i + 9, j + 30, k + 9, Blocks.viriBlock.blockID);
		world.setBlock(i + 9, j + 30, k + 45, Blocks.viriBlock.blockID);
		world.setBlock(i + 9, j + 31, k + 9, Block.glass.blockID);
		world.setBlock(i + 9, j + 31, k + 10, Block.glass.blockID);
		world.setBlock(i + 9, j + 31, k + 11, Block.glass.blockID);
		world.setBlock(i + 9, j + 31, k + 12, Block.glass.blockID);
		world.setBlock(i + 9, j + 31, k + 13, Block.glass.blockID);
		world.setBlock(i + 9, j + 31, k + 14, Block.glass.blockID);
		world.setBlock(i + 9, j + 31, k + 15, Block.glass.blockID);
		world.setBlock(i + 9, j + 31, k + 16, Block.glass.blockID);
		world.setBlock(i + 9, j + 31, k + 17, Block.glass.blockID);
		world.setBlock(i + 9, j + 31, k + 18, Block.glass.blockID);
		world.setBlock(i + 9, j + 31, k + 19, Block.glass.blockID);
		world.setBlock(i + 9, j + 31, k + 20, Block.glass.blockID);
		world.setBlock(i + 9, j + 31, k + 21, Block.glass.blockID);
		world.setBlock(i + 9, j + 31, k + 22, Block.glass.blockID);
		world.setBlock(i + 9, j + 31, k + 23, Block.glass.blockID);
		world.setBlock(i + 9, j + 31, k + 24, Block.glass.blockID);
		world.setBlock(i + 9, j + 31, k + 25, Block.glass.blockID);
		world.setBlock(i + 9, j + 31, k + 26, Block.glass.blockID);
		world.setBlock(i + 9, j + 31, k + 27, Block.glass.blockID);
		world.setBlock(i + 9, j + 31, k + 28, Block.glass.blockID);
		world.setBlock(i + 9, j + 31, k + 29, Block.glass.blockID);
		world.setBlock(i + 9, j + 31, k + 30, Block.glass.blockID);
		world.setBlock(i + 9, j + 31, k + 31, Block.glass.blockID);
		world.setBlock(i + 9, j + 31, k + 32, Block.glass.blockID);
		world.setBlock(i + 9, j + 31, k + 33, Block.glass.blockID);
		world.setBlock(i + 9, j + 31, k + 34, Block.glass.blockID);
		world.setBlock(i + 9, j + 31, k + 35, Block.glass.blockID);
		world.setBlock(i + 9, j + 31, k + 36, Block.glass.blockID);
		world.setBlock(i + 9, j + 31, k + 37, Block.glass.blockID);
		world.setBlock(i + 9, j + 31, k + 38, Block.glass.blockID);
		world.setBlock(i + 9, j + 31, k + 39, Block.glass.blockID);
		world.setBlock(i + 9, j + 31, k + 40, Block.glass.blockID);
		world.setBlock(i + 9, j + 31, k + 41, Block.glass.blockID);
		world.setBlock(i + 9, j + 31, k + 42, Block.glass.blockID);
		world.setBlock(i + 9, j + 31, k + 43, Block.glass.blockID);
		world.setBlock(i + 9, j + 31, k + 44, Block.glass.blockID);
		world.setBlock(i + 9, j + 31, k + 45, Block.glass.blockID);
		world.setBlock(i + 9, j + 32, k + 9, Blocks.viriBlock.blockID);
		world.setBlock(i + 9, j + 32, k + 45, Blocks.viriBlock.blockID);
		world.setBlock(i + 10, j + 11, k + 22, Blocks.viriBlock.blockID);
		world.setBlock(i + 10, j + 11, k + 23, Blocks.viriBlock.blockID);
		world.setBlock(i + 10, j + 11, k + 24, Blocks.viriBlock.blockID);
		world.setBlock(i + 10, j + 11, k + 25, Blocks.viriBlock.blockID);
		world.setBlock(i + 10, j + 11, k + 26, Blocks.viriBlock.blockID);
		world.setBlock(i + 10, j + 11, k + 27, Blocks.viriBlock.blockID);
		world.setBlock(i + 10, j + 11, k + 28, Blocks.viriBlock.blockID);
		world.setBlock(i + 10, j + 11, k + 29, Blocks.viriBlock.blockID);
		world.setBlock(i + 10, j + 11, k + 30, Blocks.viriBlock.blockID);
		world.setBlock(i + 10, j + 11, k + 31, Blocks.viriBlock.blockID);
		world.setBlock(i + 10, j + 11, k + 32, Blocks.viriBlock.blockID);
		world.setBlock(i + 10, j + 12, k + 19, Blocks.viriBlock.blockID);
		world.setBlock(i + 10, j + 12, k + 20, Blocks.viriBlock.blockID);
		world.setBlock(i + 10, j + 12, k + 21, Blocks.viriBlock.blockID);
		// world.setBlock(i + 10, j + 12, k + 27, Block.cobblestone.blockID);
		if (rand.nextInt(10) <= 5) {
			EntityAlien alien = new EntityAlien(world);
			alien.setLocationAndAngles(i + 10, j + 12, k + 27, 0, 0);
			world.spawnEntityInWorld(alien);
			System.out.println("Alien spawned.");
		}
		world.setBlock(i + 10, j + 12, k + 33, Blocks.viriBlock.blockID);
		world.setBlock(i + 10, j + 12, k + 34, Blocks.viriBlock.blockID);
		world.setBlock(i + 10, j + 12, k + 35, Blocks.viriBlock.blockID);
		world.setBlock(i + 10, j + 13, k + 17, Blocks.viriBlock.blockID);
		world.setBlock(i + 10, j + 13, k + 18, Blocks.viriBlock.blockID);
		world.setBlock(i + 10, j + 13, k + 36, Blocks.viriBlock.blockID);
		world.setBlock(i + 10, j + 13, k + 37, Blocks.viriBlock.blockID);
		world.setBlock(i + 10, j + 14, k + 16, Blocks.viriBlock.blockID);
		world.setBlock(i + 10, j + 14, k + 38, Blocks.viriBlock.blockID);
		world.setBlock(i + 10, j + 15, k + 15, Blocks.viriBlock.blockID);
		world.setBlock(i + 10, j + 15, k + 39, Blocks.viriBlock.blockID);
		world.setBlock(i + 10, j + 16, k + 14, Blocks.viriBlock.blockID);
		world.setBlock(i + 10, j + 16, k + 40, Blocks.viriBlock.blockID);
		world.setBlock(i + 10, j + 17, k + 13, Blocks.viriBlock.blockID);
		world.setBlock(i + 10, j + 17, k + 41, Blocks.viriBlock.blockID);
		world.setBlock(i + 10, j + 18, k + 12, Blocks.viriBlock.blockID);
		world.setBlock(i + 10, j + 18, k + 42, Blocks.viriBlock.blockID);
		world.setBlock(i + 10, j + 19, k + 11, Blocks.viriBlock.blockID);
		world.setBlock(i + 10, j + 19, k + 43, Blocks.viriBlock.blockID);
		world.setBlock(i + 10, j + 20, k + 11, Blocks.viriBlock.blockID);
		world.setBlock(i + 10, j + 20, k + 43, Blocks.viriBlock.blockID);
		world.setBlock(i + 10, j + 21, k + 10, Blocks.viriBlock.blockID);
		world.setBlock(i + 10, j + 21, k + 44, Blocks.viriBlock.blockID);
		world.setBlock(i + 10, j + 22, k + 10, Blocks.viriBlock.blockID);
		world.setBlock(i + 10, j + 22, k + 44, Blocks.viriBlock.blockID);
		world.setBlock(i + 10, j + 23, k + 10, Blocks.viriBlock.blockID);
		world.setBlock(i + 10, j + 23, k + 44, Blocks.viriBlock.blockID);
		world.setBlock(i + 10, j + 24, k + 9, Blocks.viriBlock.blockID);
		world.setBlock(i + 10, j + 24, k + 45, Blocks.viriBlock.blockID);
		world.setBlock(i + 10, j + 25, k + 9, Blocks.viriBlock.blockID);
		world.setBlock(i + 10, j + 25, k + 45, Blocks.viriBlock.blockID);
		world.setBlock(i + 10, j + 26, k + 9, Blocks.viriBlock.blockID);
		world.setBlock(i + 10, j + 26, k + 45, Blocks.viriBlock.blockID);
		world.setBlock(i + 10, j + 27, k + 9, Blocks.viriBlock.blockID);
		world.setBlock(i + 10, j + 27, k + 45, Blocks.viriBlock.blockID);
		world.setBlock(i + 10, j + 28, k + 9, Blocks.viriBlock.blockID);
		world.setBlock(i + 10, j + 28, k + 45, Blocks.viriBlock.blockID);
		world.setBlock(i + 10, j + 29, k + 9, Blocks.viriBlock.blockID);
		world.setBlock(i + 10, j + 29, k + 45, Blocks.viriBlock.blockID);
		world.setBlock(i + 10, j + 30, k + 9, Blocks.viriBlock.blockID);
		world.setBlock(i + 10, j + 30, k + 45, Blocks.viriBlock.blockID);
		world.setBlock(i + 10, j + 31, k + 9, Block.glass.blockID);
		world.setBlock(i + 10, j + 31, k + 10, Block.glass.blockID);
		world.setBlock(i + 10, j + 31, k + 11, Block.glass.blockID);
		world.setBlock(i + 10, j + 31, k + 12, Block.glass.blockID);
		world.setBlock(i + 10, j + 31, k + 13, Block.glass.blockID);
		world.setBlock(i + 10, j + 31, k + 14, Block.glass.blockID);
		world.setBlock(i + 10, j + 31, k + 15, Block.glass.blockID);
		world.setBlock(i + 10, j + 31, k + 16, Block.glass.blockID);
		world.setBlock(i + 10, j + 31, k + 17, Block.glass.blockID);
		world.setBlock(i + 10, j + 31, k + 18, Block.glass.blockID);
		world.setBlock(i + 10, j + 31, k + 19, Block.glass.blockID);
		world.setBlock(i + 10, j + 31, k + 20, Block.glass.blockID);
		world.setBlock(i + 10, j + 31, k + 21, Block.glass.blockID);
		world.setBlock(i + 10, j + 31, k + 22, Block.glass.blockID);
		world.setBlock(i + 10, j + 31, k + 23, Block.glass.blockID);
		world.setBlock(i + 10, j + 31, k + 24, Block.glass.blockID);
		world.setBlock(i + 10, j + 31, k + 25, Block.glass.blockID);
		world.setBlock(i + 10, j + 31, k + 26, Block.glass.blockID);
		world.setBlock(i + 10, j + 31, k + 27, Block.glass.blockID);
		world.setBlock(i + 10, j + 31, k + 28, Block.glass.blockID);
		world.setBlock(i + 10, j + 31, k + 29, Block.glass.blockID);
		world.setBlock(i + 10, j + 31, k + 30, Block.glass.blockID);
		world.setBlock(i + 10, j + 31, k + 31, Block.glass.blockID);
		world.setBlock(i + 10, j + 31, k + 32, Block.glass.blockID);
		world.setBlock(i + 10, j + 31, k + 33, Block.glass.blockID);
		world.setBlock(i + 10, j + 31, k + 34, Block.glass.blockID);
		world.setBlock(i + 10, j + 31, k + 35, Block.glass.blockID);
		world.setBlock(i + 10, j + 31, k + 36, Block.glass.blockID);
		world.setBlock(i + 10, j + 31, k + 37, Block.glass.blockID);
		world.setBlock(i + 10, j + 31, k + 38, Block.glass.blockID);
		world.setBlock(i + 10, j + 31, k + 39, Block.glass.blockID);
		world.setBlock(i + 10, j + 31, k + 40, Block.glass.blockID);
		world.setBlock(i + 10, j + 31, k + 41, Block.glass.blockID);
		world.setBlock(i + 10, j + 31, k + 42, Block.glass.blockID);
		world.setBlock(i + 10, j + 31, k + 43, Block.glass.blockID);
		world.setBlock(i + 10, j + 31, k + 44, Block.glass.blockID);
		world.setBlock(i + 10, j + 31, k + 45, Block.glass.blockID);
		world.setBlock(i + 10, j + 32, k + 9, Blocks.viriBlock.blockID);
		world.setBlock(i + 10, j + 32, k + 45, Blocks.viriBlock.blockID);
		world.setBlock(i + 11, j + 10, k + 24, Blocks.viriBlock.blockID);
		world.setBlock(i + 11, j + 10, k + 25, Blocks.viriBlock.blockID);
		world.setBlock(i + 11, j + 10, k + 26, Blocks.viriBlock.blockID);
		world.setBlock(i + 11, j + 10, k + 27, Blocks.viriBlock.blockID);
		world.setBlock(i + 11, j + 10, k + 28, Blocks.viriBlock.blockID);
		world.setBlock(i + 11, j + 10, k + 29, Blocks.viriBlock.blockID);
		world.setBlock(i + 11, j + 10, k + 30, Blocks.viriBlock.blockID);
		world.setBlock(i + 11, j + 11, k + 21, Blocks.viriBlock.blockID);
		world.setBlock(i + 11, j + 11, k + 22, Blocks.viriBlock.blockID);
		world.setBlock(i + 11, j + 11, k + 23, Blocks.viriBlock.blockID);
		world.setBlock(i + 11, j + 11, k + 31, Blocks.viriBlock.blockID);
		world.setBlock(i + 11, j + 11, k + 32, Blocks.viriBlock.blockID);
		world.setBlock(i + 11, j + 11, k + 33, Blocks.viriBlock.blockID);
		world.setBlock(i + 11, j + 12, k + 18, Blocks.viriBlock.blockID);
		world.setBlock(i + 11, j + 12, k + 19, Blocks.viriBlock.blockID);
		world.setBlock(i + 11, j + 12, k + 20, Blocks.viriBlock.blockID);
		world.setBlock(i + 11, j + 12, k + 34, Blocks.viriBlock.blockID);
		world.setBlock(i + 11, j + 12, k + 35, Blocks.viriBlock.blockID);
		world.setBlock(i + 11, j + 12, k + 36, Blocks.viriBlock.blockID);
		world.setBlock(i + 11, j + 13, k + 17, Blocks.viriBlock.blockID);
		world.setBlock(i + 11, j + 13, k + 37, Blocks.viriBlock.blockID);
		world.setBlock(i + 11, j + 14, k + 15, Blocks.viriBlock.blockID);
		world.setBlock(i + 11, j + 14, k + 16, Blocks.viriBlock.blockID);
		world.setBlock(i + 11, j + 14, k + 38, Blocks.viriBlock.blockID);
		world.setBlock(i + 11, j + 14, k + 39, Blocks.viriBlock.blockID);
		world.setBlock(i + 11, j + 15, k + 14, Blocks.viriBlock.blockID);
		world.setBlock(i + 11, j + 15, k + 40, Blocks.viriBlock.blockID);
		world.setBlock(i + 11, j + 16, k + 13, Blocks.viriBlock.blockID);
		world.setBlock(i + 11, j + 16, k + 41, Blocks.viriBlock.blockID);
		world.setBlock(i + 11, j + 17, k + 12, Blocks.viriBlock.blockID);
		world.setBlock(i + 11, j + 17, k + 42, Blocks.viriBlock.blockID);
		world.setBlock(i + 11, j + 18, k + 12, Blocks.viriBlock.blockID);
		world.setBlock(i + 11, j + 18, k + 42, Blocks.viriBlock.blockID);
		world.setBlock(i + 11, j + 19, k + 11, Blocks.viriBlock.blockID);
		world.setBlock(i + 11, j + 19, k + 43, Blocks.viriBlock.blockID);
		world.setBlock(i + 11, j + 20, k + 10, Blocks.viriBlock.blockID);
		world.setBlock(i + 11, j + 20, k + 44, Blocks.viriBlock.blockID);
		world.setBlock(i + 11, j + 21, k + 10, Blocks.viriBlock.blockID);
		world.setBlock(i + 11, j + 21, k + 44, Blocks.viriBlock.blockID);
		world.setBlock(i + 11, j + 22, k + 10, Blocks.viriBlock.blockID);
		world.setBlock(i + 11, j + 22, k + 44, Blocks.viriBlock.blockID);
		world.setBlock(i + 11, j + 23, k + 9, Blocks.viriBlock.blockID);
		world.setBlock(i + 11, j + 23, k + 45, Blocks.viriBlock.blockID);
		world.setBlock(i + 11, j + 24, k + 9, Blocks.viriBlock.blockID);
		world.setBlock(i + 11, j + 24, k + 45, Blocks.viriBlock.blockID);
		world.setBlock(i + 11, j + 25, k + 9, Blocks.viriBlock.blockID);
		world.setBlock(i + 11, j + 25, k + 45, Blocks.viriBlock.blockID);
		world.setBlock(i + 11, j + 26, k + 8, Blocks.viriBlock.blockID);
		world.setBlock(i + 11, j + 26, k + 46, Blocks.viriBlock.blockID);
		world.setBlock(i + 11, j + 27, k + 8, Blocks.viriBlock.blockID);
		world.setBlock(i + 11, j + 27, k + 46, Blocks.viriBlock.blockID);
		world.setBlock(i + 11, j + 28, k + 8, Blocks.viriBlock.blockID);
		world.setBlock(i + 11, j + 28, k + 46, Blocks.viriBlock.blockID);
		world.setBlock(i + 11, j + 29, k + 8, Blocks.viriBlock.blockID);
		world.setBlock(i + 11, j + 29, k + 46, Blocks.viriBlock.blockID);
		world.setBlock(i + 11, j + 30, k + 8, Blocks.viriBlock.blockID);
		world.setBlock(i + 11, j + 30, k + 46, Blocks.viriBlock.blockID);
		world.setBlock(i + 11, j + 31, k + 8, Block.glass.blockID);
		world.setBlock(i + 11, j + 31, k + 9, Block.glass.blockID);
		world.setBlock(i + 11, j + 31, k + 10, Block.glass.blockID);
		world.setBlock(i + 11, j + 31, k + 11, Block.glass.blockID);
		world.setBlock(i + 11, j + 31, k + 12, Block.glass.blockID);
		world.setBlock(i + 11, j + 31, k + 13, Block.glass.blockID);
		world.setBlock(i + 11, j + 31, k + 14, Block.glass.blockID);
		world.setBlock(i + 11, j + 31, k + 15, Block.glass.blockID);
		world.setBlock(i + 11, j + 31, k + 16, Block.glass.blockID);
		world.setBlock(i + 11, j + 31, k + 17, Block.glass.blockID);
		world.setBlock(i + 11, j + 31, k + 18, Block.glass.blockID);
		world.setBlock(i + 11, j + 31, k + 19, Block.glass.blockID);
		world.setBlock(i + 11, j + 31, k + 20, Block.glass.blockID);
		world.setBlock(i + 11, j + 31, k + 21, Block.glass.blockID);
		world.setBlock(i + 11, j + 31, k + 22, Block.glass.blockID);
		world.setBlock(i + 11, j + 31, k + 23, Block.glass.blockID);
		world.setBlock(i + 11, j + 31, k + 24, Block.glass.blockID);
		world.setBlock(i + 11, j + 31, k + 25, Block.glass.blockID);
		world.setBlock(i + 11, j + 31, k + 26, Block.glass.blockID);
		world.setBlock(i + 11, j + 31, k + 27, Block.glass.blockID);
		world.setBlock(i + 11, j + 31, k + 28, Block.glass.blockID);
		world.setBlock(i + 11, j + 31, k + 29, Block.glass.blockID);
		world.setBlock(i + 11, j + 31, k + 30, Block.glass.blockID);
		world.setBlock(i + 11, j + 31, k + 31, Block.glass.blockID);
		world.setBlock(i + 11, j + 31, k + 32, Block.glass.blockID);
		world.setBlock(i + 11, j + 31, k + 33, Block.glass.blockID);
		world.setBlock(i + 11, j + 31, k + 34, Block.glass.blockID);
		world.setBlock(i + 11, j + 31, k + 35, Block.glass.blockID);
		world.setBlock(i + 11, j + 31, k + 36, Block.glass.blockID);
		world.setBlock(i + 11, j + 31, k + 37, Block.glass.blockID);
		world.setBlock(i + 11, j + 31, k + 38, Block.glass.blockID);
		world.setBlock(i + 11, j + 31, k + 39, Block.glass.blockID);
		world.setBlock(i + 11, j + 31, k + 40, Block.glass.blockID);
		world.setBlock(i + 11, j + 31, k + 41, Block.glass.blockID);
		world.setBlock(i + 11, j + 31, k + 42, Block.glass.blockID);
		world.setBlock(i + 11, j + 31, k + 43, Block.glass.blockID);
		world.setBlock(i + 11, j + 31, k + 44, Block.glass.blockID);
		world.setBlock(i + 11, j + 31, k + 45, Block.glass.blockID);
		world.setBlock(i + 11, j + 31, k + 46, Block.glass.blockID);
		world.setBlock(i + 11, j + 32, k + 8, Blocks.viriBlock.blockID);
		world.setBlock(i + 11, j + 32, k + 46, Blocks.viriBlock.blockID);
		world.setBlock(i + 12, j + 10, k + 23, Blocks.viriBlock.blockID);
		world.setBlock(i + 12, j + 10, k + 24, Blocks.viriBlock.blockID);
		world.setBlock(i + 12, j + 10, k + 25, Blocks.viriBlock.blockID);
		world.setBlock(i + 12, j + 10, k + 26, Blocks.viriBlock.blockID);
		world.setBlock(i + 12, j + 10, k + 27, Blocks.viriBlock.blockID);
		world.setBlock(i + 12, j + 10, k + 28, Blocks.viriBlock.blockID);
		world.setBlock(i + 12, j + 10, k + 29, Blocks.viriBlock.blockID);
		world.setBlock(i + 12, j + 10, k + 30, Blocks.viriBlock.blockID);
		world.setBlock(i + 12, j + 10, k + 31, Blocks.viriBlock.blockID);
		world.setBlock(i + 12, j + 11, k + 20, Blocks.viriBlock.blockID);
		world.setBlock(i + 12, j + 11, k + 21, Blocks.viriBlock.blockID);
		world.setBlock(i + 12, j + 11, k + 22, Blocks.viriBlock.blockID);
		world.setBlock(i + 12, j + 11, k + 32, Blocks.viriBlock.blockID);
		world.setBlock(i + 12, j + 11, k + 33, Blocks.viriBlock.blockID);
		world.setBlock(i + 12, j + 11, k + 34, Blocks.viriBlock.blockID);
		world.setBlock(i + 12, j + 12, k + 18, Blocks.viriBlock.blockID);
		world.setBlock(i + 12, j + 12, k + 19, Blocks.viriBlock.blockID);
		world.setBlock(i + 12, j + 12, k + 35, Blocks.viriBlock.blockID);
		world.setBlock(i + 12, j + 12, k + 36, Blocks.viriBlock.blockID);
		world.setBlock(i + 12, j + 13, k + 16, Blocks.viriBlock.blockID);
		world.setBlock(i + 12, j + 13, k + 17, Blocks.viriBlock.blockID);
		world.setBlock(i + 12, j + 13, k + 37, Blocks.viriBlock.blockID);
		world.setBlock(i + 12, j + 13, k + 38, Blocks.viriBlock.blockID);
		world.setBlock(i + 12, j + 14, k + 15, Blocks.viriBlock.blockID);
		world.setBlock(i + 12, j + 14, k + 39, Blocks.viriBlock.blockID);
		world.setBlock(i + 12, j + 15, k + 14, Blocks.viriBlock.blockID);
		world.setBlock(i + 12, j + 15, k + 40, Blocks.viriBlock.blockID);
		world.setBlock(i + 12, j + 16, k + 13, Blocks.viriBlock.blockID);
		world.setBlock(i + 12, j + 16, k + 41, Blocks.viriBlock.blockID);
		world.setBlock(i + 12, j + 17, k + 12, Blocks.viriBlock.blockID);
		world.setBlock(i + 12, j + 17, k + 42, Blocks.viriBlock.blockID);
		world.setBlock(i + 12, j + 18, k + 11, Blocks.viriBlock.blockID);
		world.setBlock(i + 12, j + 18, k + 43, Blocks.viriBlock.blockID);
		world.setBlock(i + 12, j + 19, k + 11, Blocks.viriBlock.blockID);
		world.setBlock(i + 12, j + 19, k + 43, Blocks.viriBlock.blockID);
		world.setBlock(i + 12, j + 20, k + 10, Blocks.viriBlock.blockID);
		world.setBlock(i + 12, j + 20, k + 44, Blocks.viriBlock.blockID);
		world.setBlock(i + 12, j + 21, k + 10, Blocks.viriBlock.blockID);
		world.setBlock(i + 12, j + 21, k + 44, Blocks.viriBlock.blockID);
		world.setBlock(i + 12, j + 22, k + 9, Blocks.viriBlock.blockID);
		world.setBlock(i + 12, j + 22, k + 45, Blocks.viriBlock.blockID);
		world.setBlock(i + 12, j + 23, k + 9, Blocks.viriBlock.blockID);
		world.setBlock(i + 12, j + 23, k + 45, Blocks.viriBlock.blockID);
		world.setBlock(i + 12, j + 24, k + 9, Blocks.viriBlock.blockID);
		world.setBlock(i + 12, j + 24, k + 45, Blocks.viriBlock.blockID);
		world.setBlock(i + 12, j + 25, k + 8, Blocks.viriBlock.blockID);
		world.setBlock(i + 12, j + 25, k + 46, Blocks.viriBlock.blockID);
		world.setBlock(i + 12, j + 26, k + 8, Blocks.viriBlock.blockID);
		world.setBlock(i + 12, j + 26, k + 46, Blocks.viriBlock.blockID);
		world.setBlock(i + 12, j + 27, k + 8, Blocks.viriBlock.blockID);
		world.setBlock(i + 12, j + 27, k + 46, Blocks.viriBlock.blockID);
		world.setBlock(i + 12, j + 28, k + 8, Blocks.viriBlock.blockID);
		world.setBlock(i + 12, j + 28, k + 46, Blocks.viriBlock.blockID);
		world.setBlock(i + 12, j + 29, k + 8, Blocks.viriBlock.blockID);
		world.setBlock(i + 12, j + 29, k + 46, Blocks.viriBlock.blockID);
		world.setBlock(i + 12, j + 30, k + 8, Blocks.viriBlock.blockID);
		world.setBlock(i + 12, j + 30, k + 46, Blocks.viriBlock.blockID);
		world.setBlock(i + 12, j + 31, k + 8, Block.glass.blockID);
		world.setBlock(i + 12, j + 31, k + 9, Block.glass.blockID);
		world.setBlock(i + 12, j + 31, k + 10, Block.glass.blockID);
		world.setBlock(i + 12, j + 31, k + 11, Block.glass.blockID);
		world.setBlock(i + 12, j + 31, k + 12, Block.glass.blockID);
		world.setBlock(i + 12, j + 31, k + 13, Block.glass.blockID);
		world.setBlock(i + 12, j + 31, k + 14, Block.glass.blockID);
		world.setBlock(i + 12, j + 31, k + 15, Block.glass.blockID);
		world.setBlock(i + 12, j + 31, k + 16, Block.glass.blockID);
		world.setBlock(i + 12, j + 31, k + 17, Block.glass.blockID);
		world.setBlock(i + 12, j + 31, k + 18, Block.glass.blockID);
		world.setBlock(i + 12, j + 31, k + 19, Block.glass.blockID);
		world.setBlock(i + 12, j + 31, k + 20, Block.glass.blockID);
		world.setBlock(i + 12, j + 31, k + 21, Block.glass.blockID);
		world.setBlock(i + 12, j + 31, k + 22, Block.glass.blockID);
		world.setBlock(i + 12, j + 31, k + 23, Block.glass.blockID);
		world.setBlock(i + 12, j + 31, k + 24, Block.glass.blockID);
		world.setBlock(i + 12, j + 31, k + 25, Block.glass.blockID);
		world.setBlock(i + 12, j + 31, k + 26, Block.glass.blockID);
		world.setBlock(i + 12, j + 31, k + 27, Block.glass.blockID);
		world.setBlock(i + 12, j + 31, k + 28, Block.glass.blockID);
		world.setBlock(i + 12, j + 31, k + 29, Block.glass.blockID);
		world.setBlock(i + 12, j + 31, k + 30, Block.glass.blockID);
		world.setBlock(i + 12, j + 31, k + 31, Block.glass.blockID);
		world.setBlock(i + 12, j + 31, k + 32, Block.glass.blockID);
		world.setBlock(i + 12, j + 31, k + 33, Block.glass.blockID);
		world.setBlock(i + 12, j + 31, k + 34, Block.glass.blockID);
		world.setBlock(i + 12, j + 31, k + 35, Block.glass.blockID);
		world.setBlock(i + 12, j + 31, k + 36, Block.glass.blockID);
		world.setBlock(i + 12, j + 31, k + 37, Block.glass.blockID);
		world.setBlock(i + 12, j + 31, k + 38, Block.glass.blockID);
		world.setBlock(i + 12, j + 31, k + 39, Block.glass.blockID);
		world.setBlock(i + 12, j + 31, k + 40, Block.glass.blockID);
		world.setBlock(i + 12, j + 31, k + 41, Block.glass.blockID);
		world.setBlock(i + 12, j + 31, k + 42, Block.glass.blockID);
		world.setBlock(i + 12, j + 31, k + 43, Block.glass.blockID);
		world.setBlock(i + 12, j + 31, k + 44, Block.glass.blockID);
		world.setBlock(i + 12, j + 31, k + 45, Block.glass.blockID);
		world.setBlock(i + 12, j + 31, k + 46, Block.glass.blockID);
		world.setBlock(i + 12, j + 32, k + 8, Blocks.viriBlock.blockID);
		world.setBlock(i + 12, j + 32, k + 46, Blocks.viriBlock.blockID);
		world.setBlock(i + 13, j + 10, k + 22, Blocks.viriBlock.blockID);
		world.setBlock(i + 13, j + 10, k + 23, Blocks.viriBlock.blockID);
		world.setBlock(i + 13, j + 10, k + 24, Blocks.viriBlock.blockID);
		world.setBlock(i + 13, j + 10, k + 25, Blocks.viriBlock.blockID);
		world.setBlock(i + 13, j + 10, k + 26, Blocks.viriBlock.blockID);
		world.setBlock(i + 13, j + 10, k + 27, Blocks.viriBlock.blockID);
		world.setBlock(i + 13, j + 10, k + 28, Blocks.viriBlock.blockID);
		world.setBlock(i + 13, j + 10, k + 29, Blocks.viriBlock.blockID);
		world.setBlock(i + 13, j + 10, k + 30, Blocks.viriBlock.blockID);
		world.setBlock(i + 13, j + 10, k + 31, Blocks.viriBlock.blockID);
		world.setBlock(i + 13, j + 10, k + 32, Blocks.viriBlock.blockID);
		world.setBlock(i + 13, j + 11, k + 19, Blocks.viriBlock.blockID);
		world.setBlock(i + 13, j + 11, k + 20, Blocks.viriBlock.blockID);
		world.setBlock(i + 13, j + 11, k + 21, Blocks.viriBlock.blockID);
		world.setBlock(i + 13, j + 11, k + 33, Blocks.viriBlock.blockID);
		world.setBlock(i + 13, j + 11, k + 34, Blocks.viriBlock.blockID);
		world.setBlock(i + 13, j + 11, k + 35, Blocks.viriBlock.blockID);
		world.setBlock(i + 13, j + 12, k + 17, Blocks.viriBlock.blockID);
		world.setBlock(i + 13, j + 12, k + 18, Blocks.viriBlock.blockID);
		world.setBlock(i + 13, j + 12, k + 36, Blocks.viriBlock.blockID);
		world.setBlock(i + 13, j + 12, k + 37, Blocks.viriBlock.blockID);
		world.setBlock(i + 13, j + 13, k + 16, Blocks.viriBlock.blockID);
		world.setBlock(i + 13, j + 13, k + 38, Blocks.viriBlock.blockID);
		world.setBlock(i + 13, j + 14, k + 14, Blocks.viriBlock.blockID);
		world.setBlock(i + 13, j + 14, k + 15, Blocks.viriBlock.blockID);
		world.setBlock(i + 13, j + 14, k + 39, Blocks.viriBlock.blockID);
		world.setBlock(i + 13, j + 14, k + 40, Blocks.viriBlock.blockID);
		world.setBlock(i + 13, j + 15, k + 13, Blocks.viriBlock.blockID);
		world.setBlock(i + 13, j + 15, k + 41, Blocks.viriBlock.blockID);
		world.setBlock(i + 13, j + 16, k + 12, Blocks.viriBlock.blockID);
		world.setBlock(i + 13, j + 16, k + 42, Blocks.viriBlock.blockID);
		world.setBlock(i + 13, j + 17, k + 12, Blocks.viriBlock.blockID);
		world.setBlock(i + 13, j + 17, k + 42, Blocks.viriBlock.blockID);
		world.setBlock(i + 13, j + 18, k + 11, Blocks.viriBlock.blockID);
		world.setBlock(i + 13, j + 18, k + 43, Blocks.viriBlock.blockID);
		world.setBlock(i + 13, j + 19, k + 10, Blocks.viriBlock.blockID);
		world.setBlock(i + 13, j + 19, k + 44, Blocks.viriBlock.blockID);
		world.setBlock(i + 13, j + 20, k + 10, Blocks.viriBlock.blockID);
		world.setBlock(i + 13, j + 20, k + 44, Blocks.viriBlock.blockID);
		world.setBlock(i + 13, j + 21, k + 9, Blocks.viriBlock.blockID);
		world.setBlock(i + 13, j + 21, k + 45, Blocks.viriBlock.blockID);
		world.setBlock(i + 13, j + 22, k + 9, Blocks.viriBlock.blockID);
		world.setBlock(i + 13, j + 22, k + 45, Blocks.viriBlock.blockID);
		world.setBlock(i + 13, j + 23, k + 9, Blocks.viriBlock.blockID);
		world.setBlock(i + 13, j + 23, k + 45, Blocks.viriBlock.blockID);
		world.setBlock(i + 13, j + 24, k + 8, Blocks.viriBlock.blockID);
		world.setBlock(i + 13, j + 24, k + 46, Blocks.viriBlock.blockID);
		world.setBlock(i + 13, j + 25, k + 8, Blocks.viriBlock.blockID);
		world.setBlock(i + 13, j + 25, k + 46, Blocks.viriBlock.blockID);
		world.setBlock(i + 13, j + 26, k + 8, Blocks.viriBlock.blockID);
		world.setBlock(i + 13, j + 26, k + 46, Blocks.viriBlock.blockID);
		world.setBlock(i + 13, j + 27, k + 8, Blocks.viriBlock.blockID);
		world.setBlock(i + 13, j + 27, k + 46, Blocks.viriBlock.blockID);
		world.setBlock(i + 13, j + 28, k + 8, Blocks.viriBlock.blockID);
		world.setBlock(i + 13, j + 28, k + 46, Blocks.viriBlock.blockID);
		world.setBlock(i + 13, j + 29, k + 8, Blocks.viriBlock.blockID);
		world.setBlock(i + 13, j + 29, k + 46, Blocks.viriBlock.blockID);
		world.setBlock(i + 13, j + 30, k + 8, Blocks.viriBlock.blockID);
		world.setBlock(i + 13, j + 30, k + 46, Blocks.viriBlock.blockID);
		world.setBlock(i + 13, j + 31, k + 8, Block.glass.blockID);
		world.setBlock(i + 13, j + 31, k + 9, Block.glass.blockID);
		world.setBlock(i + 13, j + 31, k + 10, Block.glass.blockID);
		world.setBlock(i + 13, j + 31, k + 11, Block.glass.blockID);
		world.setBlock(i + 13, j + 31, k + 12, Block.glass.blockID);
		world.setBlock(i + 13, j + 31, k + 13, Block.glass.blockID);
		world.setBlock(i + 13, j + 31, k + 14, Block.glass.blockID);
		world.setBlock(i + 13, j + 31, k + 15, Block.glass.blockID);
		world.setBlock(i + 13, j + 31, k + 16, Block.glass.blockID);
		world.setBlock(i + 13, j + 31, k + 17, Block.glass.blockID);
		world.setBlock(i + 13, j + 31, k + 18, Block.glass.blockID);
		world.setBlock(i + 13, j + 31, k + 19, Block.glass.blockID);
		world.setBlock(i + 13, j + 31, k + 20, Block.glass.blockID);
		world.setBlock(i + 13, j + 31, k + 21, Block.glass.blockID);
		world.setBlock(i + 13, j + 31, k + 22, Block.glass.blockID);
		world.setBlock(i + 13, j + 31, k + 23, Block.glass.blockID);
		world.setBlock(i + 13, j + 31, k + 24, Block.glass.blockID);
		world.setBlock(i + 13, j + 31, k + 25, Block.glass.blockID);
		world.setBlock(i + 13, j + 31, k + 26, Block.glass.blockID);
		world.setBlock(i + 13, j + 31, k + 27, Block.glass.blockID);
		world.setBlock(i + 13, j + 31, k + 28, Block.glass.blockID);
		world.setBlock(i + 13, j + 31, k + 29, Block.glass.blockID);
		world.setBlock(i + 13, j + 31, k + 30, Block.glass.blockID);
		world.setBlock(i + 13, j + 31, k + 31, Block.glass.blockID);
		world.setBlock(i + 13, j + 31, k + 32, Block.glass.blockID);
		world.setBlock(i + 13, j + 31, k + 33, Block.glass.blockID);
		world.setBlock(i + 13, j + 31, k + 34, Block.glass.blockID);
		world.setBlock(i + 13, j + 31, k + 35, Block.glass.blockID);
		world.setBlock(i + 13, j + 31, k + 36, Block.glass.blockID);
		world.setBlock(i + 13, j + 31, k + 37, Block.glass.blockID);
		world.setBlock(i + 13, j + 31, k + 38, Block.glass.blockID);
		world.setBlock(i + 13, j + 31, k + 39, Block.glass.blockID);
		world.setBlock(i + 13, j + 31, k + 40, Block.glass.blockID);
		world.setBlock(i + 13, j + 31, k + 41, Block.glass.blockID);
		world.setBlock(i + 13, j + 31, k + 42, Block.glass.blockID);
		world.setBlock(i + 13, j + 31, k + 43, Block.glass.blockID);
		world.setBlock(i + 13, j + 31, k + 44, Block.glass.blockID);
		world.setBlock(i + 13, j + 31, k + 45, Block.glass.blockID);
		world.setBlock(i + 13, j + 31, k + 46, Block.glass.blockID);
		world.setBlock(i + 13, j + 32, k + 8, Blocks.viriBlock.blockID);
		world.setBlock(i + 13, j + 32, k + 46, Blocks.viriBlock.blockID);
		world.setBlock(i + 14, j + 9, k + 25, Blocks.viriBlock.blockID);
		world.setBlock(i + 14, j + 9, k + 26, Blocks.viriBlock.blockID);
		world.setBlock(i + 14, j + 9, k + 27, Blocks.viriBlock.blockID);
		world.setBlock(i + 14, j + 9, k + 28, Blocks.viriBlock.blockID);
		world.setBlock(i + 14, j + 9, k + 29, Blocks.viriBlock.blockID);
		world.setBlock(i + 14, j + 10, k + 21, Blocks.viriBlock.blockID);
		world.setBlock(i + 14, j + 10, k + 22, Blocks.viriBlock.blockID);
		world.setBlock(i + 14, j + 10, k + 23, Blocks.viriBlock.blockID);
		world.setBlock(i + 14, j + 10, k + 24, Blocks.viriBlock.blockID);
		// world.setBlock(i + 14, j + 10, k + 27, Block.cobblestone.blockID);
		if (rand.nextInt(10) <= 5) {
			EntityAlien alien = new EntityAlien(world);
			alien.setLocationAndAngles(i + 14, j + 10, k + 27, 0, 0);
			world.spawnEntityInWorld(alien);
			System.out.println("Alien spawned.");
		}
		world.setBlock(i + 14, j + 10, k + 30, Blocks.viriBlock.blockID);
		world.setBlock(i + 14, j + 10, k + 31, Blocks.viriBlock.blockID);
		world.setBlock(i + 14, j + 10, k + 32, Blocks.viriBlock.blockID);
		world.setBlock(i + 14, j + 10, k + 33, Blocks.viriBlock.blockID);
		world.setBlock(i + 14, j + 11, k + 19, Blocks.viriBlock.blockID);
		world.setBlock(i + 14, j + 11, k + 20, Blocks.viriBlock.blockID);
		world.setBlock(i + 14, j + 11, k + 34, Blocks.viriBlock.blockID);
		world.setBlock(i + 14, j + 11, k + 35, Blocks.viriBlock.blockID);
		world.setBlock(i + 14, j + 12, k + 17, Blocks.viriBlock.blockID);
		world.setBlock(i + 14, j + 12, k + 18, Blocks.viriBlock.blockID);
		world.setBlock(i + 14, j + 12, k + 36, Blocks.viriBlock.blockID);
		world.setBlock(i + 14, j + 12, k + 37, Blocks.viriBlock.blockID);
		world.setBlock(i + 14, j + 13, k + 15, Blocks.viriBlock.blockID);
		world.setBlock(i + 14, j + 13, k + 16, Blocks.viriBlock.blockID);
		world.setBlock(i + 14, j + 13, k + 38, Blocks.viriBlock.blockID);
		world.setBlock(i + 14, j + 13, k + 39, Blocks.viriBlock.blockID);
		world.setBlock(i + 14, j + 14, k + 14, Blocks.viriBlock.blockID);
		world.setBlock(i + 14, j + 14, k + 40, Blocks.viriBlock.blockID);
		world.setBlock(i + 14, j + 15, k + 13, Blocks.viriBlock.blockID);
		world.setBlock(i + 14, j + 15, k + 41, Blocks.viriBlock.blockID);
		world.setBlock(i + 14, j + 16, k + 12, Blocks.viriBlock.blockID);
		world.setBlock(i + 14, j + 16, k + 42, Blocks.viriBlock.blockID);
		world.setBlock(i + 14, j + 17, k + 11, Blocks.viriBlock.blockID);
		world.setBlock(i + 14, j + 17, k + 43, Blocks.viriBlock.blockID);
		world.setBlock(i + 14, j + 18, k + 11, Blocks.viriBlock.blockID);
		world.setBlock(i + 14, j + 18, k + 43, Blocks.viriBlock.blockID);
		world.setBlock(i + 14, j + 19, k + 10, Blocks.viriBlock.blockID);
		world.setBlock(i + 14, j + 19, k + 44, Blocks.viriBlock.blockID);
		world.setBlock(i + 14, j + 20, k + 10, Blocks.viriBlock.blockID);
		world.setBlock(i + 14, j + 20, k + 44, Blocks.viriBlock.blockID);
		world.setBlock(i + 14, j + 21, k + 9, Blocks.viriBlock.blockID);
		world.setBlock(i + 14, j + 21, k + 45, Blocks.viriBlock.blockID);
		world.setBlock(i + 14, j + 22, k + 9, Blocks.viriBlock.blockID);
		world.setBlock(i + 14, j + 22, k + 45, Blocks.viriBlock.blockID);
		world.setBlock(i + 14, j + 23, k + 8, Blocks.viriBlock.blockID);
		world.setBlock(i + 14, j + 23, k + 46, Blocks.viriBlock.blockID);
		world.setBlock(i + 14, j + 24, k + 8, Blocks.viriBlock.blockID);
		world.setBlock(i + 14, j + 24, k + 46, Blocks.viriBlock.blockID);
		world.setBlock(i + 14, j + 25, k + 8, Blocks.viriBlock.blockID);
		world.setBlock(i + 14, j + 25, k + 46, Blocks.viriBlock.blockID);
		world.setBlock(i + 14, j + 26, k + 8, Blocks.viriBlock.blockID);
		world.setBlock(i + 14, j + 26, k + 46, Blocks.viriBlock.blockID);
		world.setBlock(i + 14, j + 27, k + 7, Blocks.viriBlock.blockID);
		world.setBlock(i + 14, j + 27, k + 47, Blocks.viriBlock.blockID);
		world.setBlock(i + 14, j + 28, k + 7, Blocks.viriBlock.blockID);
		world.setBlock(i + 14, j + 28, k + 47, Blocks.viriBlock.blockID);
		world.setBlock(i + 14, j + 29, k + 7, Blocks.viriBlock.blockID);
		world.setBlock(i + 14, j + 29, k + 47, Blocks.viriBlock.blockID);
		world.setBlock(i + 14, j + 30, k + 7, Blocks.viriBlock.blockID);
		world.setBlock(i + 14, j + 30, k + 47, Blocks.viriBlock.blockID);
		world.setBlock(i + 14, j + 31, k + 7, Block.glass.blockID);
		world.setBlock(i + 14, j + 31, k + 8, Block.glass.blockID);
		world.setBlock(i + 14, j + 31, k + 9, Block.glass.blockID);
		world.setBlock(i + 14, j + 31, k + 10, Block.glass.blockID);
		world.setBlock(i + 14, j + 31, k + 11, Block.glass.blockID);
		world.setBlock(i + 14, j + 31, k + 12, Block.glass.blockID);
		world.setBlock(i + 14, j + 31, k + 13, Block.glass.blockID);
		world.setBlock(i + 14, j + 31, k + 14, Block.glass.blockID);
		world.setBlock(i + 14, j + 31, k + 15, Block.glass.blockID);
		world.setBlock(i + 14, j + 31, k + 16, Block.glass.blockID);
		world.setBlock(i + 14, j + 31, k + 17, Block.glass.blockID);
		world.setBlock(i + 14, j + 31, k + 18, Block.glass.blockID);
		world.setBlock(i + 14, j + 31, k + 19, Block.glass.blockID);
		world.setBlock(i + 14, j + 31, k + 20, Block.glass.blockID);
		world.setBlock(i + 14, j + 31, k + 21, Block.glass.blockID);
		world.setBlock(i + 14, j + 31, k + 22, Block.glass.blockID);
		world.setBlock(i + 14, j + 31, k + 23, Block.glass.blockID);
		world.setBlock(i + 14, j + 31, k + 24, Block.glass.blockID);
		world.setBlock(i + 14, j + 31, k + 25, Block.glass.blockID);
		world.setBlock(i + 14, j + 31, k + 26, Block.glass.blockID);
		world.setBlock(i + 14, j + 31, k + 27, Block.glass.blockID);
		world.setBlock(i + 14, j + 31, k + 28, Block.glass.blockID);
		world.setBlock(i + 14, j + 31, k + 29, Block.glass.blockID);
		world.setBlock(i + 14, j + 31, k + 30, Block.glass.blockID);
		world.setBlock(i + 14, j + 31, k + 31, Block.glass.blockID);
		world.setBlock(i + 14, j + 31, k + 32, Block.glass.blockID);
		world.setBlock(i + 14, j + 31, k + 33, Block.glass.blockID);
		world.setBlock(i + 14, j + 31, k + 34, Block.glass.blockID);
		world.setBlock(i + 14, j + 31, k + 35, Block.glass.blockID);
		world.setBlock(i + 14, j + 31, k + 36, Block.glass.blockID);
		world.setBlock(i + 14, j + 31, k + 37, Block.glass.blockID);
		world.setBlock(i + 14, j + 31, k + 38, Block.glass.blockID);
		world.setBlock(i + 14, j + 31, k + 39, Block.glass.blockID);
		world.setBlock(i + 14, j + 31, k + 40, Block.glass.blockID);
		world.setBlock(i + 14, j + 31, k + 41, Block.glass.blockID);
		world.setBlock(i + 14, j + 31, k + 42, Block.glass.blockID);
		world.setBlock(i + 14, j + 31, k + 43, Block.glass.blockID);
		world.setBlock(i + 14, j + 31, k + 44, Block.glass.blockID);
		world.setBlock(i + 14, j + 31, k + 45, Block.glass.blockID);
		world.setBlock(i + 14, j + 31, k + 46, Block.glass.blockID);
		world.setBlock(i + 14, j + 31, k + 47, Block.glass.blockID);
		world.setBlock(i + 14, j + 32, k + 8, Blocks.viriBlock.blockID);
		world.setBlock(i + 14, j + 32, k + 46, Blocks.viriBlock.blockID);
		world.setBlock(i + 15, j + 9, k + 24, Blocks.viriBlock.blockID);
		world.setBlock(i + 15, j + 9, k + 25, Blocks.viriBlock.blockID);
		world.setBlock(i + 15, j + 9, k + 26, Blocks.viriBlock.blockID);
		world.setBlock(i + 15, j + 9, k + 27, Blocks.viriBlock.blockID);
		world.setBlock(i + 15, j + 9, k + 28, Blocks.viriBlock.blockID);
		world.setBlock(i + 15, j + 9, k + 29, Blocks.viriBlock.blockID);
		world.setBlock(i + 15, j + 9, k + 30, Blocks.viriBlock.blockID);
		world.setBlock(i + 15, j + 10, k + 20, Blocks.viriBlock.blockID);
		world.setBlock(i + 15, j + 10, k + 21, Blocks.viriBlock.blockID);
		world.setBlock(i + 15, j + 10, k + 22, Blocks.viriBlock.blockID);
		world.setBlock(i + 15, j + 10, k + 23, Blocks.viriBlock.blockID);
		world.setBlock(i + 15, j + 10, k + 31, Blocks.viriBlock.blockID);
		world.setBlock(i + 15, j + 10, k + 32, Blocks.viriBlock.blockID);
		world.setBlock(i + 15, j + 10, k + 33, Blocks.viriBlock.blockID);
		world.setBlock(i + 15, j + 10, k + 34, Blocks.viriBlock.blockID);
		world.setBlock(i + 15, j + 11, k + 18, Blocks.viriBlock.blockID);
		world.setBlock(i + 15, j + 11, k + 19, Blocks.viriBlock.blockID);
		world.setBlock(i + 15, j + 11, k + 35, Blocks.viriBlock.blockID);
		world.setBlock(i + 15, j + 11, k + 36, Blocks.viriBlock.blockID);
		world.setBlock(i + 15, j + 12, k + 16, Blocks.viriBlock.blockID);
		world.setBlock(i + 15, j + 12, k + 17, Blocks.viriBlock.blockID);
		world.setBlock(i + 15, j + 12, k + 37, Blocks.viriBlock.blockID);
		world.setBlock(i + 15, j + 12, k + 38, Blocks.viriBlock.blockID);
		world.setBlock(i + 15, j + 13, k + 15, Blocks.viriBlock.blockID);
		world.setBlock(i + 15, j + 13, k + 39, Blocks.viriBlock.blockID);
		world.setBlock(i + 15, j + 14, k + 14, Blocks.viriBlock.blockID);
		world.setBlock(i + 15, j + 14, k + 40, Blocks.viriBlock.blockID);
		world.setBlock(i + 15, j + 15, k + 13, Blocks.viriBlock.blockID);
		world.setBlock(i + 15, j + 15, k + 41, Blocks.viriBlock.blockID);
		world.setBlock(i + 15, j + 16, k + 12, Blocks.viriBlock.blockID);
		world.setBlock(i + 15, j + 16, k + 42, Blocks.viriBlock.blockID);
		world.setBlock(i + 15, j + 17, k + 11, Blocks.viriBlock.blockID);
		world.setBlock(i + 15, j + 17, k + 43, Blocks.viriBlock.blockID);
		world.setBlock(i + 15, j + 18, k + 10, Blocks.viriBlock.blockID);
		world.setBlock(i + 15, j + 18, k + 44, Blocks.viriBlock.blockID);
		world.setBlock(i + 15, j + 19, k + 10, Blocks.viriBlock.blockID);
		world.setBlock(i + 15, j + 19, k + 44, Blocks.viriBlock.blockID);
		world.setBlock(i + 15, j + 20, k + 9, Blocks.viriBlock.blockID);
		world.setBlock(i + 15, j + 20, k + 45, Blocks.viriBlock.blockID);
		world.setBlock(i + 15, j + 21, k + 9, Blocks.viriBlock.blockID);
		world.setBlock(i + 15, j + 21, k + 45, Blocks.viriBlock.blockID);
		world.setBlock(i + 15, j + 22, k + 8, Blocks.viriBlock.blockID);
		world.setBlock(i + 15, j + 22, k + 46, Blocks.viriBlock.blockID);
		world.setBlock(i + 15, j + 23, k + 8, Blocks.viriBlock.blockID);
		world.setBlock(i + 15, j + 23, k + 46, Blocks.viriBlock.blockID);
		world.setBlock(i + 15, j + 24, k + 8, Blocks.viriBlock.blockID);
		world.setBlock(i + 15, j + 24, k + 46, Blocks.viriBlock.blockID);
		world.setBlock(i + 15, j + 25, k + 8, Blocks.viriBlock.blockID);
		world.setBlock(i + 15, j + 25, k + 46, Blocks.viriBlock.blockID);
		world.setBlock(i + 15, j + 26, k + 7, Blocks.viriBlock.blockID);
		world.setBlock(i + 15, j + 26, k + 47, Blocks.viriBlock.blockID);
		world.setBlock(i + 15, j + 27, k + 7, Blocks.viriBlock.blockID);
		world.setBlock(i + 15, j + 27, k + 47, Blocks.viriBlock.blockID);
		world.setBlock(i + 15, j + 28, k + 7, Blocks.viriBlock.blockID);
		world.setBlock(i + 15, j + 28, k + 47, Blocks.viriBlock.blockID);
		world.setBlock(i + 15, j + 29, k + 7, Blocks.viriBlock.blockID);
		world.setBlock(i + 15, j + 29, k + 47, Blocks.viriBlock.blockID);
		world.setBlock(i + 15, j + 30, k + 7, Blocks.viriBlock.blockID);
		world.setBlock(i + 15, j + 30, k + 47, Blocks.viriBlock.blockID);
		world.setBlock(i + 15, j + 31, k + 7, Block.glass.blockID);
		world.setBlock(i + 15, j + 31, k + 8, Block.glass.blockID);
		world.setBlock(i + 15, j + 31, k + 9, Block.glass.blockID);
		world.setBlock(i + 15, j + 31, k + 10, Block.glass.blockID);
		world.setBlock(i + 15, j + 31, k + 11, Block.glass.blockID);
		world.setBlock(i + 15, j + 31, k + 12, Block.glass.blockID);
		world.setBlock(i + 15, j + 31, k + 13, Block.glass.blockID);
		world.setBlock(i + 15, j + 31, k + 14, Block.glass.blockID);
		world.setBlock(i + 15, j + 31, k + 15, Block.glass.blockID);
		world.setBlock(i + 15, j + 31, k + 16, Block.glass.blockID);
		world.setBlock(i + 15, j + 31, k + 17, Block.glass.blockID);
		world.setBlock(i + 15, j + 31, k + 18, Block.glass.blockID);
		world.setBlock(i + 15, j + 31, k + 19, Block.glass.blockID);
		world.setBlock(i + 15, j + 31, k + 20, Block.glass.blockID);
		world.setBlock(i + 15, j + 31, k + 21, Block.glass.blockID);
		world.setBlock(i + 15, j + 31, k + 22, Block.glass.blockID);
		world.setBlock(i + 15, j + 31, k + 23, Block.glass.blockID);
		world.setBlock(i + 15, j + 31, k + 24, Block.glass.blockID);
		world.setBlock(i + 15, j + 31, k + 25, Block.glass.blockID);
		world.setBlock(i + 15, j + 31, k + 26, Block.glass.blockID);
		world.setBlock(i + 15, j + 31, k + 27, Block.glass.blockID);
		world.setBlock(i + 15, j + 31, k + 28, Block.glass.blockID);
		world.setBlock(i + 15, j + 31, k + 29, Block.glass.blockID);
		world.setBlock(i + 15, j + 31, k + 30, Block.glass.blockID);
		world.setBlock(i + 15, j + 31, k + 31, Block.glass.blockID);
		world.setBlock(i + 15, j + 31, k + 32, Block.glass.blockID);
		world.setBlock(i + 15, j + 31, k + 33, Block.glass.blockID);
		world.setBlock(i + 15, j + 31, k + 34, Block.glass.blockID);
		world.setBlock(i + 15, j + 31, k + 35, Block.glass.blockID);
		world.setBlock(i + 15, j + 31, k + 36, Block.glass.blockID);
		world.setBlock(i + 15, j + 31, k + 37, Block.glass.blockID);
		world.setBlock(i + 15, j + 31, k + 38, Block.glass.blockID);
		world.setBlock(i + 15, j + 31, k + 39, Block.glass.blockID);
		world.setBlock(i + 15, j + 31, k + 40, Block.glass.blockID);
		world.setBlock(i + 15, j + 31, k + 41, Block.glass.blockID);
		world.setBlock(i + 15, j + 31, k + 42, Block.glass.blockID);
		world.setBlock(i + 15, j + 31, k + 43, Block.glass.blockID);
		world.setBlock(i + 15, j + 31, k + 44, Block.glass.blockID);
		world.setBlock(i + 15, j + 31, k + 45, Block.glass.blockID);
		world.setBlock(i + 15, j + 31, k + 46, Block.glass.blockID);
		world.setBlock(i + 15, j + 31, k + 47, Block.glass.blockID);
		world.setBlock(i + 15, j + 32, k + 7, Blocks.viriBlock.blockID);
		world.setBlock(i + 15, j + 32, k + 47, Blocks.viriBlock.blockID);
		world.setBlock(i + 16, j + 9, k + 23, Blocks.viriBlock.blockID);
		world.setBlock(i + 16, j + 9, k + 24, Blocks.viriBlock.blockID);
		world.setBlock(i + 16, j + 9, k + 25, Blocks.viriBlock.blockID);
		world.setBlock(i + 16, j + 9, k + 26, Blocks.viriBlock.blockID);
		world.setBlock(i + 16, j + 9, k + 27, Blocks.viriBlock.blockID);
		world.setBlock(i + 16, j + 9, k + 28, Blocks.viriBlock.blockID);
		world.setBlock(i + 16, j + 9, k + 29, Blocks.viriBlock.blockID);
		world.setBlock(i + 16, j + 9, k + 30, Blocks.viriBlock.blockID);
		world.setBlock(i + 16, j + 9, k + 31, Blocks.viriBlock.blockID);
		world.setBlock(i + 16, j + 10, k + 20, Blocks.viriBlock.blockID);
		world.setBlock(i + 16, j + 10, k + 21, Blocks.viriBlock.blockID);
		world.setBlock(i + 16, j + 10, k + 22, Blocks.viriBlock.blockID);
		world.setBlock(i + 16, j + 10, k + 32, Blocks.viriBlock.blockID);
		world.setBlock(i + 16, j + 10, k + 33, Blocks.viriBlock.blockID);
		world.setBlock(i + 16, j + 10, k + 34, Blocks.viriBlock.blockID);
		world.setBlock(i + 16, j + 11, k + 18, Blocks.viriBlock.blockID);
		world.setBlock(i + 16, j + 11, k + 19, Blocks.viriBlock.blockID);
		world.setBlock(i + 16, j + 11, k + 33, Block.fenceIron.blockID);
		world.setBlock(i + 16, j + 11, k + 34, Block.fenceIron.blockID);
		world.setBlock(i + 16, j + 11, k + 35, Blocks.viriBlock.blockID);
		world.setBlock(i + 16, j + 11, k + 36, Blocks.viriBlock.blockID);
		world.setBlock(i + 16, j + 12, k + 16, Blocks.viriBlock.blockID);
		world.setBlock(i + 16, j + 12, k + 17, Blocks.viriBlock.blockID);
		world.setBlock(i + 16, j + 12, k + 33, Block.fenceIron.blockID);
		world.setBlock(i + 16, j + 12, k + 34, Block.fenceIron.blockID);
		world.setBlock(i + 16, j + 12, k + 35, Block.fenceIron.blockID);
		world.setBlock(i + 16, j + 12, k + 37, Blocks.viriBlock.blockID);
		world.setBlock(i + 16, j + 12, k + 38, Blocks.viriBlock.blockID);
		world.setBlock(i + 16, j + 13, k + 15, Blocks.viriBlock.blockID);
		world.setBlock(i + 16, j + 13, k + 39, Blocks.viriBlock.blockID);
		world.setBlock(i + 16, j + 14, k + 14, Blocks.viriBlock.blockID);
		world.setBlock(i + 16, j + 14, k + 40, Blocks.viriBlock.blockID);
		world.setBlock(i + 16, j + 15, k + 13, Blocks.viriBlock.blockID);
		world.setBlock(i + 16, j + 15, k + 41, Blocks.viriBlock.blockID);
		world.setBlock(i + 16, j + 16, k + 12, Blocks.viriBlock.blockID);
		world.setBlock(i + 16, j + 16, k + 42, Blocks.viriBlock.blockID);
		world.setBlock(i + 16, j + 17, k + 11, Blocks.viriBlock.blockID);
		world.setBlock(i + 16, j + 17, k + 43, Blocks.viriBlock.blockID);
		world.setBlock(i + 16, j + 18, k + 10, Blocks.viriBlock.blockID);
		world.setBlock(i + 16, j + 18, k + 44, Blocks.viriBlock.blockID);
		world.setBlock(i + 16, j + 19, k + 10, Blocks.viriBlock.blockID);
		world.setBlock(i + 16, j + 19, k + 44, Blocks.viriBlock.blockID);
		world.setBlock(i + 16, j + 20, k + 9, Blocks.viriBlock.blockID);
		world.setBlock(i + 16, j + 20, k + 45, Blocks.viriBlock.blockID);
		world.setBlock(i + 16, j + 21, k + 9, Blocks.viriBlock.blockID);
		world.setBlock(i + 16, j + 21, k + 45, Blocks.viriBlock.blockID);
		world.setBlock(i + 16, j + 22, k + 8, Blocks.viriBlock.blockID);
		world.setBlock(i + 16, j + 22, k + 46, Blocks.viriBlock.blockID);
