package alienMod.structures;

import java.util.Random;

import net.minecraft.block.Block;
import net.minecraft.world.World;
import net.minecraft.world.gen.feature.WorldGenerator;
import alienMod.blocks.Blocks;
import alienMod.mobs.entities.EntityAlien;

public class WorldGenUFO extends WorldGenerator
{
	protected int[] GetValidSpawnBlocks() {
		return new int[] { 0 };
	}
	
	public boolean LocationIsValidSpawn(World world, int i, int j, int k) {
		int distanceToAir = 0;
		int checkID = world.getBlockId(i, j, k);
		
		while (checkID != 0) {
			distanceToAir++;
			checkID = world.getBlockId(i, j + distanceToAir, k);
		}
		
		if (distanceToAir > 3) {
			return false;
		}
		j += distanceToAir - 1;
		
		int blockID = world.getBlockId(i, j, k);
		int blockIDAbove = world.getBlockId(i, j + 1, k);
		int blockIDBelow = world.getBlockId(i, j - 1, k);
		return true;
	}
	
	public WorldGenUFO() {
	}
	
	@Override
	public boolean generate(World world, Random rand, int i, int j, int k) {
		// check that each corner is one of the valid spawn blocks
		if (!LocationIsValidSpawn(world, i, j, k))
		{
			return false;
		}
		
		world.setBlock(i + 0, j + 3, k + 16, Blocks.viriBlock.blockID);
		world.setBlock(i + 0, j + 3, k + 17, Blocks.viriBlock.blockID);
		world.setBlock(i + 0, j + 3, k + 18, Blocks.viriBlock.blockID);
		world.setBlock(i + 0, j + 3, k + 19, Blocks.viriBlock.blockID);
		world.setBlock(i + 0, j + 3, k + 20, Blocks.viriBlock.blockID);
		world.setBlock(i + 0, j + 3, k + 21, Blocks.viriBlock.blockID);
		world.setBlock(i + 0, j + 3, k + 22, Blocks.viriBlock.blockID);
		world.setBlock(i + 0, j + 3, k + 23, Blocks.viriBlock.blockID);
		world.setBlock(i + 0, j + 4, k + 16, Blocks.viriBlock.blockID);
		world.setBlock(i + 0, j + 4, k + 17, Blocks.viriBlock.blockID);
		world.setBlock(i + 0, j + 4, k + 18, Blocks.viriBlock.blockID);
		world.setBlock(i + 0, j + 4, k + 19, Blocks.viriBlock.blockID);
		world.setBlock(i + 0, j + 4, k + 20, Blocks.viriBlock.blockID);
		world.setBlock(i + 0, j + 4, k + 21, Blocks.viriBlock.blockID);
		world.setBlock(i + 0, j + 4, k + 22, Blocks.viriBlock.blockID);
		world.setBlock(i + 0, j + 4, k + 23, Blocks.viriBlock.blockID);
		world.setBlock(i + 1, j + 2, k + 19, Blocks.viriBlock.blockID);
		world.setBlock(i + 1, j + 2, k + 20, Blocks.viriBlock.blockID);
		world.setBlock(i + 1, j + 3, k + 13, Blocks.viriBlock.blockID);
		world.setBlock(i + 1, j + 3, k + 14, Blocks.viriBlock.blockID);
		world.setBlock(i + 1, j + 3, k + 15, Blocks.viriBlock.blockID);
		world.setBlock(i + 1, j + 3, k + 16, Blocks.viriBlock.blockID);
		world.setBlock(i + 1, j + 3, k + 17, Blocks.viriBlock.blockID);
		world.setBlock(i + 1, j + 3, k + 18, Blocks.viriBlock.blockID);
		world.setBlock(i + 1, j + 3, k + 19, Blocks.viriBlock.blockID);
		world.setBlock(i + 1, j + 3, k + 20, Blocks.viriBlock.blockID);
		world.setBlock(i + 1, j + 3, k + 21, Blocks.viriBlock.blockID);
		world.setBlock(i + 1, j + 3, k + 22, Blocks.viriBlock.blockID);
		world.setBlock(i + 1, j + 3, k + 23, Blocks.viriBlock.blockID);
		world.setBlock(i + 1, j + 3, k + 24, Blocks.viriBlock.blockID);
		world.setBlock(i + 1, j + 3, k + 25, Blocks.viriBlock.blockID);
		world.setBlock(i + 1, j + 3, k + 26, Blocks.viriBlock.blockID);
		world.setBlock(i + 1, j + 4, k + 13, Blocks.viriBlock.blockID);
		world.setBlock(i + 1, j + 4, k + 14, Blocks.viriBlock.blockID);
		world.setBlock(i + 1, j + 4, k + 15, Blocks.viriBlock.blockID);
		world.setBlock(i + 1, j + 4, k + 16, Blocks.viriBlock.blockID);
		world.setBlock(i + 1, j + 4, k + 17, Blocks.viriBlock.blockID);
		world.setBlock(i + 1, j + 4, k + 18, Blocks.viriBlock.blockID);
		world.setBlock(i + 1, j + 4, k + 19, Blocks.viriBlock.blockID);
		world.setBlock(i + 1, j + 4, k + 20, Blocks.viriBlock.blockID);
		world.setBlock(i + 1, j + 4, k + 21, Blocks.viriBlock.blockID);
		world.setBlock(i + 1, j + 4, k + 22, Blocks.viriBlock.blockID);
		world.setBlock(i + 1, j + 4, k + 23, Blocks.viriBlock.blockID);
		world.setBlock(i + 1, j + 4, k + 24, Blocks.viriBlock.blockID);
		world.setBlock(i + 1, j + 4, k + 25, Blocks.viriBlock.blockID);
		world.setBlock(i + 1, j + 4, k + 26, Blocks.viriBlock.blockID);
		world.setBlock(i + 1, j + 5, k + 19, Blocks.viriBlock.blockID);
		world.setBlock(i + 1, j + 5, k + 20, Blocks.viriBlock.blockID);
		world.setBlock(i + 2, j + 2, k + 14, Blocks.viriBlock.blockID);
		world.setBlock(i + 2, j + 2, k + 15, Blocks.viriBlock.blockID);
		world.setBlock(i + 2, j + 2, k + 16, Blocks.viriBlock.blockID);
		world.setBlock(i + 2, j + 2, k + 17, Blocks.viriBlock.blockID);
		world.setBlock(i + 2, j + 2, k + 18, Blocks.viriBlock.blockID);
		world.setBlock(i + 2, j + 2, k + 19, Blocks.viriBlock.blockID);
		world.setBlock(i + 2, j + 2, k + 20, Blocks.viriBlock.blockID);
		world.setBlock(i + 2, j + 2, k + 21, Blocks.viriBlock.blockID);
		world.setBlock(i + 2, j + 2, k + 22, Blocks.viriBlock.blockID);
		world.setBlock(i + 2, j + 2, k + 23, Blocks.viriBlock.blockID);
		world.setBlock(i + 2, j + 2, k + 24, Blocks.viriBlock.blockID);
		world.setBlock(i + 2, j + 2, k + 25, Blocks.viriBlock.blockID);
		world.setBlock(i + 2, j + 3, k + 11, Blocks.viriBlock.blockID);
		world.setBlock(i + 2, j + 3, k + 12, Blocks.viriBlock.blockID);
		world.setBlock(i + 2, j + 3, k + 13, Blocks.viriBlock.blockID);
		world.setBlock(i + 2, j + 3, k + 14, Blocks.viriBlock.blockID);
		world.setBlock(i + 2, j + 3, k + 15, Blocks.viriBlock.blockID);
		world.setBlock(i + 2, j + 3, k + 16, Blocks.viriBlock.blockID);
		world.setBlock(i + 2, j + 3, k + 17, Blocks.viriBlock.blockID);
		world.setBlock(i + 2, j + 3, k + 18, Blocks.viriBlock.blockID);
		world.setBlock(i + 2, j + 3, k + 19, Blocks.viriBlock.blockID);
		world.setBlock(i + 2, j + 3, k + 20, Blocks.viriBlock.blockID);
		world.setBlock(i + 2, j + 3, k + 21, Blocks.viriBlock.blockID);
		world.setBlock(i + 2, j + 3, k + 22, Blocks.viriBlock.blockID);
		world.setBlock(i + 2, j + 3, k + 23, Blocks.viriBlock.blockID);
		world.setBlock(i + 2, j + 3, k + 24, Blocks.viriBlock.blockID);
		world.setBlock(i + 2, j + 3, k + 25, Blocks.viriBlock.blockID);
		world.setBlock(i + 2, j + 3, k + 26, Blocks.viriBlock.blockID);
		world.setBlock(i + 2, j + 3, k + 27, Blocks.viriBlock.blockID);
		world.setBlock(i + 2, j + 3, k + 28, Blocks.viriBlock.blockID);
		world.setBlock(i + 2, j + 4, k + 11, Blocks.viriBlock.blockID);
		world.setBlock(i + 2, j + 4, k + 12, Blocks.viriBlock.blockID);
		world.setBlock(i + 2, j + 4, k + 13, Blocks.viriBlock.blockID);
		world.setBlock(i + 2, j + 4, k + 14, Blocks.viriBlock.blockID);
		world.setBlock(i + 2, j + 4, k + 15, Blocks.viriBlock.blockID);
		world.setBlock(i + 2, j + 4, k + 16, Blocks.viriBlock.blockID);
		world.setBlock(i + 2, j + 4, k + 17, Blocks.viriBlock.blockID);
		world.setBlock(i + 2, j + 4, k + 18, Blocks.viriBlock.blockID);
		world.setBlock(i + 2, j + 4, k + 19, Blocks.viriBlock.blockID);
		world.setBlock(i + 2, j + 4, k + 20, Blocks.viriBlock.blockID);
		world.setBlock(i + 2, j + 4, k + 21, Blocks.viriBlock.blockID);
		world.setBlock(i + 2, j + 4, k + 22, Blocks.viriBlock.blockID);
		world.setBlock(i + 2, j + 4, k + 23, Blocks.viriBlock.blockID);
		world.setBlock(i + 2, j + 4, k + 24, Blocks.viriBlock.blockID);
		world.setBlock(i + 2, j + 4, k + 25, Blocks.viriBlock.blockID);
		world.setBlock(i + 2, j + 4, k + 26, Blocks.viriBlock.blockID);
		world.setBlock(i + 2, j + 4, k + 27, Blocks.viriBlock.blockID);
		world.setBlock(i + 2, j + 4, k + 28, Blocks.viriBlock.blockID);
		world.setBlock(i + 2, j + 5, k + 14, Blocks.viriBlock.blockID);
		world.setBlock(i + 2, j + 5, k + 15, Blocks.viriBlock.blockID);
		world.setBlock(i + 2, j + 5, k + 16, Blocks.viriBlock.blockID);
		world.setBlock(i + 2, j + 5, k + 17, Blocks.viriBlock.blockID);
		world.setBlock(i + 2, j + 5, k + 18, Blocks.viriBlock.blockID);
		world.setBlock(i + 2, j + 5, k + 19, Blocks.viriBlock.blockID);
		world.setBlock(i + 2, j + 5, k + 20, Blocks.viriBlock.blockID);
		world.setBlock(i + 2, j + 5, k + 21, Blocks.viriBlock.blockID);
		world.setBlock(i + 2, j + 5, k + 22, Blocks.viriBlock.blockID);
		world.setBlock(i + 2, j + 5, k + 23, Blocks.viriBlock.blockID);
		world.setBlock(i + 2, j + 5, k + 24, Blocks.viriBlock.blockID);
		world.setBlock(i + 2, j + 5, k + 25, Blocks.viriBlock.blockID);
		world.setBlock(i + 3, j + 2, k + 12, Blocks.viriBlock.blockID);
		world.setBlock(i + 3, j + 2, k + 13, Blocks.viriBlock.blockID);
		world.setBlock(i + 3, j + 2, k + 14, Blocks.viriBlock.blockID);
		world.setBlock(i + 3, j + 2, k + 15, Blocks.viriBlock.blockID);
		world.setBlock(i + 3, j + 2, k + 16, Blocks.viriBlock.blockID);
		world.setBlock(i + 3, j + 2, k + 17, Blocks.viriBlock.blockID);
		world.setBlock(i + 3, j + 2, k + 18, Blocks.viriBlock.blockID);
		world.setBlock(i + 3, j + 2, k + 19, Blocks.viriBlock.blockID);
		world.setBlock(i + 3, j + 2, k + 20, Blocks.viriBlock.blockID);
		world.setBlock(i + 3, j + 2, k + 21, Blocks.viriBlock.blockID);
		world.setBlock(i + 3, j + 2, k + 22, Blocks.viriBlock.blockID);
		world.setBlock(i + 3, j + 2, k + 23, Blocks.viriBlock.blockID);
		world.setBlock(i + 3, j + 2, k + 24, Blocks.viriBlock.blockID);
		world.setBlock(i + 3, j + 2, k + 25, Blocks.viriBlock.blockID);
		world.setBlock(i + 3, j + 2, k + 26, Blocks.viriBlock.blockID);
		world.setBlock(i + 3, j + 2, k + 27, Blocks.viriBlock.blockID);
		world.setBlock(i + 3, j + 3, k + 9, Blocks.viriBlock.blockID);
		world.setBlock(i + 3, j + 3, k + 10, Blocks.viriBlock.blockID);
		world.setBlock(i + 3, j + 3, k + 11, Blocks.viriBlock.blockID);
		world.setBlock(i + 3, j + 3, k + 12, Blocks.viriBlock.blockID);
		world.setBlock(i + 3, j + 3, k + 13, Blocks.viriBlock.blockID);
		world.setBlock(i + 3, j + 3, k + 14, Blocks.viriBlock.blockID);
		world.setBlock(i + 3, j + 3, k + 15, Blocks.viriBlock.blockID);
		world.setBlock(i + 3, j + 3, k + 16, Blocks.viriBlock.blockID);
		world.setBlock(i + 3, j + 3, k + 17, Blocks.viriBlock.blockID);
		world.setBlock(i + 3, j + 3, k + 18, Blocks.viriBlock.blockID);
		world.setBlock(i + 3, j + 3, k + 19, Blocks.viriBlock.blockID);
		world.setBlock(i + 3, j + 3, k + 20, Blocks.viriBlock.blockID);
		world.setBlock(i + 3, j + 3, k + 21, Blocks.viriBlock.blockID);
		world.setBlock(i + 3, j + 3, k + 22, Blocks.viriBlock.blockID);
		world.setBlock(i + 3, j + 3, k + 23, Blocks.viriBlock.blockID);
		world.setBlock(i + 3, j + 3, k + 24, Blocks.viriBlock.blockID);
		world.setBlock(i + 3, j + 3, k + 25, Blocks.viriBlock.blockID);
		world.setBlock(i + 3, j + 3, k + 26, Blocks.viriBlock.blockID);
		world.setBlock(i + 3, j + 3, k + 27, Blocks.viriBlock.blockID);
		world.setBlock(i + 3, j + 3, k + 28, Blocks.viriBlock.blockID);
		world.setBlock(i + 3, j + 3, k + 29, Blocks.viriBlock.blockID);
		world.setBlock(i + 3, j + 3, k + 30, Blocks.viriBlock.blockID);
		world.setBlock(i + 3, j + 4, k + 9, Blocks.viriBlock.blockID);
		world.setBlock(i + 3, j + 4, k + 10, Blocks.viriBlock.blockID);
		world.setBlock(i + 3, j + 4, k + 11, Blocks.viriBlock.blockID);
		world.setBlock(i + 3, j + 4, k + 12, Blocks.viriBlock.blockID);
		world.setBlock(i + 3, j + 4, k + 13, Blocks.viriBlock.blockID);
		world.setBlock(i + 3, j + 4, k + 14, Blocks.viriBlock.blockID);
		world.setBlock(i + 3, j + 4, k + 15, Blocks.viriBlock.blockID);
		world.setBlock(i + 3, j + 4, k + 16, Blocks.viriBlock.blockID);
		world.setBlock(i + 3, j + 4, k + 17, Blocks.viriBlock.blockID);
		world.setBlock(i + 3, j + 4, k + 18, Blocks.viriBlock.blockID);
		world.setBlock(i + 3, j + 4, k + 19, Blocks.viriBlock.blockID);
		world.setBlock(i + 3, j + 4, k + 20, Blocks.viriBlock.blockID);
		world.setBlock(i + 3, j + 4, k + 21, Blocks.viriBlock.blockID);
		world.setBlock(i + 3, j + 4, k + 22, Blocks.viriBlock.blockID);
		world.setBlock(i + 3, j + 4, k + 23, Blocks.viriBlock.blockID);
		world.setBlock(i + 3, j + 4, k + 24, Blocks.viriBlock.blockID);
		world.setBlock(i + 3, j + 4, k + 25, Blocks.viriBlock.blockID);
		world.setBlock(i + 3, j + 4, k + 26, Blocks.viriBlock.blockID);
		world.setBlock(i + 3, j + 4, k + 27, Blocks.viriBlock.blockID);
		world.setBlock(i + 3, j + 4, k + 28, Blocks.viriBlock.blockID);
		world.setBlock(i + 3, j + 4, k + 29, Blocks.viriBlock.blockID);
		world.setBlock(i + 3, j + 4, k + 30, Blocks.viriBlock.blockID);
		world.setBlock(i + 3, j + 5, k + 12, Blocks.viriBlock.blockID);
		world.setBlock(i + 3, j + 5, k + 13, Blocks.viriBlock.blockID);
		world.setBlock(i + 3, j + 5, k + 14, Blocks.viriBlock.blockID);
		world.setBlock(i + 3, j + 5, k + 15, Blocks.viriBlock.blockID);
		world.setBlock(i + 3, j + 5, k + 16, Blocks.viriBlock.blockID);
		world.setBlock(i + 3, j + 5, k + 17, Blocks.viriBlock.blockID);
		world.setBlock(i + 3, j + 5, k + 18, Blocks.viriBlock.blockID);
		world.setBlock(i + 3, j + 5, k + 19, Blocks.viriBlock.blockID);
		world.setBlock(i + 3, j + 5, k + 20, Blocks.viriBlock.blockID);
		world.setBlock(i + 3, j + 5, k + 21, Blocks.viriBlock.blockID);
		world.setBlock(i + 3, j + 5, k + 22, Blocks.viriBlock.blockID);
		world.setBlock(i + 3, j + 5, k + 23, Blocks.viriBlock.blockID);
		world.setBlock(i + 3, j + 5, k + 24, Blocks.viriBlock.blockID);
		world.setBlock(i + 3, j + 5, k + 25, Blocks.viriBlock.blockID);
		world.setBlock(i + 3, j + 5, k + 26, Blocks.viriBlock.blockID);
		world.setBlock(i + 3, j + 5, k + 27, Blocks.viriBlock.blockID);
		world.setBlock(i + 4, j + 1, k + 18, Blocks.viriBlock.blockID);
		world.setBlock(i + 4, j + 1, k + 19, Blocks.viriBlock.blockID);
		world.setBlock(i + 4, j + 1, k + 20, Blocks.viriBlock.blockID);
		world.setBlock(i + 4, j + 1, k + 21, Blocks.viriBlock.blockID);
		world.setBlock(i + 4, j + 2, k + 10, Blocks.viriBlock.blockID);
		world.setBlock(i + 4, j + 2, k + 11, Blocks.viriBlock.blockID);
		world.setBlock(i + 4, j + 2, k + 12, Blocks.viriBlock.blockID);
		world.setBlock(i + 4, j + 2, k + 13, Blocks.viriBlock.blockID);
		world.setBlock(i + 4, j + 2, k + 14, Blocks.viriBlock.blockID);
		world.setBlock(i + 4, j + 2, k + 15, Blocks.viriBlock.blockID);
		world.setBlock(i + 4, j + 2, k + 16, Blocks.viriBlock.blockID);
		world.setBlock(i + 4, j + 2, k + 17, Blocks.viriBlock.blockID);
		world.setBlock(i + 4, j + 2, k + 18, Blocks.viriBlock.blockID);
		world.setBlock(i + 4, j + 2, k + 19, Blocks.viriBlock.blockID);
		world.setBlock(i + 4, j + 2, k + 20, Blocks.viriBlock.blockID);
		world.setBlock(i + 4, j + 2, k + 21, Blocks.viriBlock.blockID);
		world.setBlock(i + 4, j + 2, k + 22, Blocks.viriBlock.blockID);
		world.setBlock(i + 4, j + 2, k + 23, Blocks.viriBlock.blockID);
		world.setBlock(i + 4, j + 2, k + 24, Blocks.viriBlock.blockID);
		world.setBlock(i + 4, j + 2, k + 25, Blocks.viriBlock.blockID);
		world.setBlock(i + 4, j + 2, k + 26, Blocks.viriBlock.blockID);
		world.setBlock(i + 4, j + 2, k + 27, Blocks.viriBlock.blockID);
		world.setBlock(i + 4, j + 2, k + 28, Blocks.viriBlock.blockID);
		world.setBlock(i + 4, j + 2, k + 29, Blocks.viriBlock.blockID);
		world.setBlock(i + 4, j + 3, k + 8, Blocks.viriBlock.blockID);
		world.setBlock(i + 4, j + 3, k + 9, Blocks.viriBlock.blockID);
		world.setBlock(i + 4, j + 3, k + 10, Blocks.viriBlock.blockID);
		world.setBlock(i + 4, j + 3, k + 11, Blocks.viriBlock.blockID);
		world.setBlock(i + 4, j + 3, k + 12, Blocks.viriBlock.blockID);
		world.setBlock(i + 4, j + 3, k + 13, Blocks.viriBlock.blockID);
		world.setBlock(i + 4, j + 3, k + 14, Blocks.viriBlock.blockID);
		world.setBlock(i + 4, j + 3, k + 15, Blocks.viriBlock.blockID);
		world.setBlock(i + 4, j + 3, k + 16, Blocks.viriBlock.blockID);
		world.setBlock(i + 4, j + 3, k + 17, Blocks.viriBlock.blockID);
		world.setBlock(i + 4, j + 3, k + 18, Blocks.viriBlock.blockID);
		world.setBlock(i + 4, j + 3, k + 19, Blocks.viriBlock.blockID);
		world.setBlock(i + 4, j + 3, k + 20, Blocks.viriBlock.blockID);
		world.setBlock(i + 4, j + 3, k + 21, Blocks.viriBlock.blockID);
		world.setBlock(i + 4, j + 3, k + 22, Blocks.viriBlock.blockID);
		world.setBlock(i + 4, j + 3, k + 23, Blocks.viriBlock.blockID);
		world.setBlock(i + 4, j + 3, k + 24, Blocks.viriBlock.blockID);
		world.setBlock(i + 4, j + 3, k + 25, Blocks.viriBlock.blockID);
		world.setBlock(i + 4, j + 3, k + 26, Blocks.viriBlock.blockID);
		world.setBlock(i + 4, j + 3, k + 27, Blocks.viriBlock.blockID);
		world.setBlock(i + 4, j + 3, k + 28, Blocks.viriBlock.blockID);
		world.setBlock(i + 4, j + 3, k + 29, Blocks.viriBlock.blockID);
		world.setBlock(i + 4, j + 3, k + 30, Blocks.viriBlock.blockID);
		world.setBlock(i + 4, j + 3, k + 31, Blocks.viriBlock.blockID);
		world.setBlock(i + 4, j + 4, k + 8, Blocks.viriBlock.blockID);
		world.setBlock(i + 4, j + 4, k + 9, Blocks.viriBlock.blockID);
		world.setBlock(i + 4, j + 4, k + 10, Blocks.viriBlock.blockID);
		world.setBlock(i + 4, j + 4, k + 11, Blocks.viriBlock.blockID);
		world.setBlock(i + 4, j + 4, k + 12, Blocks.viriBlock.blockID);
		world.setBlock(i + 4, j + 4, k + 13, Blocks.viriBlock.blockID);
		world.setBlock(i + 4, j + 4, k + 14, Blocks.viriBlock.blockID);
		world.setBlock(i + 4, j + 4, k + 15, Blocks.viriBlock.blockID);
		world.setBlock(i + 4, j + 4, k + 16, Blocks.viriBlock.blockID);
		world.setBlock(i + 4, j + 4, k + 17, Blocks.viriBlock.blockID);
		world.setBlock(i + 4, j + 4, k + 18, Blocks.viriBlock.blockID);
		world.setBlock(i + 4, j + 4, k + 19, Blocks.viriBlock.blockID);
		world.setBlock(i + 4, j + 4, k + 20, Blocks.viriBlock.blockID);
		world.setBlock(i + 4, j + 4, k + 21, Blocks.viriBlock.blockID);
		world.setBlock(i + 4, j + 4, k + 22, Blocks.viriBlock.blockID);
		world.setBlock(i + 4, j + 4, k + 23, Blocks.viriBlock.blockID);
		world.setBlock(i + 4, j + 4, k + 24, Blocks.viriBlock.blockID);
		world.setBlock(i + 4, j + 4, k + 25, Blocks.viriBlock.blockID);
		world.setBlock(i + 4, j + 4, k + 26, Blocks.viriBlock.blockID);
		world.setBlock(i + 4, j + 4, k + 27, Blocks.viriBlock.blockID);
		world.setBlock(i + 4, j + 4, k + 28, Blocks.viriBlock.blockID);
		world.setBlock(i + 4, j + 4, k + 29, Blocks.viriBlock.blockID);
		world.setBlock(i + 4, j + 4, k + 30, Blocks.viriBlock.blockID);
		world.setBlock(i + 4, j + 4, k + 31, Blocks.viriBlock.blockID);
		world.setBlock(i + 4, j + 5, k + 10, Blocks.viriBlock.blockID);
		world.setBlock(i + 4, j + 5, k + 11, Blocks.viriBlock.blockID);
		world.setBlock(i + 4, j + 5, k + 12, Blocks.viriBlock.blockID);
		world.setBlock(i + 4, j + 5, k + 13, Blocks.viriBlock.blockID);
		world.setBlock(i + 4, j + 5, k + 14, Blocks.viriBlock.blockID);
		world.setBlock(i + 4, j + 5, k + 15, Blocks.viriBlock.blockID);
		world.setBlock(i + 4, j + 5, k + 16, Blocks.viriBlock.blockID);
		world.setBlock(i + 4, j + 5, k + 17, Blocks.viriBlock.blockID);
		world.setBlock(i + 4, j + 5, k + 18, Blocks.viriBlock.blockID);
		world.setBlock(i + 4, j + 5, k + 19, Blocks.viriBlock.blockID);
		world.setBlock(i + 4, j + 5, k + 20, Blocks.viriBlock.blockID);
		world.setBlock(i + 4, j + 5, k + 21, Blocks.viriBlock.blockID);
		world.setBlock(i + 4, j + 5, k + 22, Blocks.viriBlock.blockID);
		world.setBlock(i + 4, j + 5, k + 23, Blocks.viriBlock.blockID);
		world.setBlock(i + 4, j + 5, k + 24, Blocks.viriBlock.blockID);
		world.setBlock(i + 4, j + 5, k + 25, Blocks.viriBlock.blockID);
		world.setBlock(i + 4, j + 5, k + 26, Blocks.viriBlock.blockID);
		world.setBlock(i + 4, j + 5, k + 27, Blocks.viriBlock.blockID);
		world.setBlock(i + 4, j + 5, k + 28, Blocks.viriBlock.blockID);
		world.setBlock(i + 4, j + 5, k + 29, Blocks.viriBlock.blockID);
		world.setBlock(i + 4, j + 6, k + 18, Blocks.viriBlock.blockID);
		world.setBlock(i + 4, j + 6, k + 19, Blocks.viriBlock.blockID);
		world.setBlock(i + 4, j + 6, k + 20, Blocks.viriBlock.blockID);
		world.setBlock(i + 4, j + 6, k + 21, Blocks.viriBlock.blockID);
		world.setBlock(i + 5, j + 1, k + 14, Blocks.viriBlock.blockID);
		world.setBlock(i + 5, j + 1, k + 15, Blocks.viriBlock.blockID);
		world.setBlock(i + 5, j + 1, k + 16, Blocks.viriBlock.blockID);
		world.setBlock(i + 5, j + 1, k + 17, Blocks.viriBlock.blockID);
		world.setBlock(i + 5, j + 1, k + 18, Blocks.viriBlock.blockID);
		world.setBlock(i + 5, j + 1, k + 19, Blocks.viriBlock.blockID);
		world.setBlock(i + 5, j + 1, k + 20, Blocks.viriBlock.blockID);
		world.setBlock(i + 5, j + 1, k + 21, Blocks.viriBlock.blockID);
		world.setBlock(i + 5, j + 1, k + 22, Blocks.viriBlock.blockID);
		world.setBlock(i + 5, j + 1, k + 23, Blocks.viriBlock.blockID);
		world.setBlock(i + 5, j + 1, k + 24, Blocks.viriBlock.blockID);
		world.setBlock(i + 5, j + 1, k + 25, Blocks.viriBlock.blockID);
		world.setBlock(i + 5, j + 2, k + 8, Blocks.viriBlock.blockID);
		world.setBlock(i + 5, j + 2, k + 9, Blocks.viriBlock.blockID);
		world.setBlock(i + 5, j + 2, k + 10, Blocks.viriBlock.blockID);
		world.setBlock(i + 5, j + 2, k + 11, Blocks.viriBlock.blockID);
		world.setBlock(i + 5, j + 2, k + 12, Blocks.viriBlock.blockID);
		world.setBlock(i + 5, j + 2, k + 13, Blocks.viriBlock.blockID);
		world.setBlock(i + 5, j + 2, k + 14, Blocks.viriBlock.blockID);
		world.setBlock(i + 5, j + 2, k + 15, Blocks.viriBlock.blockID);
		world.setBlock(i + 5, j + 2, k + 16, Blocks.viriBlock.blockID);
		world.setBlock(i + 5, j + 2, k + 17, Blocks.viriBlock.blockID);
		world.setBlock(i + 5, j + 2, k + 18, Blocks.viriBlock.blockID);
		world.setBlock(i + 5, j + 2, k + 19, Blocks.viriBlock.blockID);
		world.setBlock(i + 5, j + 2, k + 20, Blocks.viriBlock.blockID);
		world.setBlock(i + 5, j + 2, k + 21, Blocks.viriBlock.blockID);
		world.setBlock(i + 5, j + 2, k + 22, Blocks.viriBlock.blockID);
		world.setBlock(i + 5, j + 2, k + 23, Blocks.viriBlock.blockID);
		world.setBlock(i + 5, j + 2, k + 24, Blocks.viriBlock.blockID);
		world.setBlock(i + 5, j + 2, k + 25, Blocks.viriBlock.blockID);
		world.setBlock(i + 5, j + 2, k + 26, Blocks.viriBlock.blockID);
		world.setBlock(i + 5, j + 2, k + 27, Blocks.viriBlock.blockID);
		world.setBlock(i + 5, j + 2, k + 28, Blocks.viriBlock.blockID);
		world.setBlock(i + 5, j + 2, k + 29, Blocks.viriBlock.blockID);
		world.setBlock(i + 5, j + 2, k + 30, Blocks.viriBlock.blockID);
		world.setBlock(i + 5, j + 2, k + 31, Blocks.viriBlock.blockID);
		world.setBlock(i + 5, j + 3, k + 6, Blocks.viriBlock.blockID);
		world.setBlock(i + 5, j + 3, k + 7, Blocks.viriBlock.blockID);
		world.setBlock(i + 5, j + 3, k + 8, Blocks.viriBlock.blockID);
		world.setBlock(i + 5, j + 3, k + 9, Blocks.viriBlock.blockID);
		world.setBlock(i + 5, j + 3, k + 10, Blocks.viriBlock.blockID);
		world.setBlock(i + 5, j + 3, k + 11, Blocks.viriBlock.blockID);
		world.setBlock(i + 5, j + 3, k + 12, Blocks.viriBlock.blockID);
		world.setBlock(i + 5, j + 3, k + 13, Blocks.viriBlock.blockID);
		world.setBlock(i + 5, j + 3, k + 14, Blocks.viriBlock.blockID);
		world.setBlock(i + 5, j + 3, k + 15, Blocks.viriBlock.blockID);
		world.setBlock(i + 5, j + 3, k + 16, Blocks.viriBlock.blockID);
		world.setBlock(i + 5, j + 3, k + 17, Blocks.viriBlock.blockID);
		world.setBlock(i + 5, j + 3, k + 18, Blocks.viriBlock.blockID);
		world.setBlock(i + 5, j + 3, k + 19, Blocks.viriBlock.blockID);
		world.setBlock(i + 5, j + 3, k + 20, Blocks.viriBlock.blockID);
		world.setBlock(i + 5, j + 3, k + 21, Blocks.viriBlock.blockID);
		world.setBlock(i + 5, j + 3, k + 22, Blocks.viriBlock.blockID);
		world.setBlock(i + 5, j + 3, k + 23, Blocks.viriBlock.blockID);
		world.setBlock(i + 5, j + 3, k + 24, Blocks.viriBlock.blockID);
		world.setBlock(i + 5, j + 3, k + 25, Blocks.viriBlock.blockID);
		world.setBlock(i + 5, j + 3, k + 26, Blocks.viriBlock.blockID);
		world.setBlock(i + 5, j + 3, k + 27, Blocks.viriBlock.blockID);
		world.setBlock(i + 5, j + 3, k + 28, Blocks.viriBlock.blockID);
		world.setBlock(i + 5, j + 3, k + 29, Blocks.viriBlock.blockID);
		world.setBlock(i + 5, j + 3, k + 30, Blocks.viriBlock.blockID);
		world.setBlock(i + 5, j + 3, k + 31, Blocks.viriBlock.blockID);
		world.setBlock(i + 5, j + 3, k + 32, Blocks.viriBlock.blockID);
		world.setBlock(i + 5, j + 3, k + 33, Blocks.viriBlock.blockID);
		world.setBlock(i + 5, j + 4, k + 6, Blocks.viriBlock.blockID);
		world.setBlock(i + 5, j + 4, k + 7, Blocks.viriBlock.blockID);
		world.setBlock(i + 5, j + 4, k + 8, Blocks.viriBlock.blockID);
		world.setBlock(i + 5, j + 4, k + 9, Blocks.viriBlock.blockID);
		world.setBlock(i + 5, j + 4, k + 10, Blocks.viriBlock.blockID);
		world.setBlock(i + 5, j + 4, k + 11, Blocks.viriBlock.blockID);
		world.setBlock(i + 5, j + 4, k + 12, Blocks.viriBlock.blockID);
		world.setBlock(i + 5, j + 4, k + 13, Blocks.viriBlock.blockID);
		world.setBlock(i + 5, j + 4, k + 14, Blocks.viriBlock.blockID);
		world.setBlock(i + 5, j + 4, k + 15, Blocks.viriBlock.blockID);
		world.setBlock(i + 5, j + 4, k + 16, Blocks.viriBlock.blockID);
		world.setBlock(i + 5, j + 4, k + 17, Blocks.viriBlock.blockID);
		world.setBlock(i + 5, j + 4, k + 18, Blocks.viriBlock.blockID);
		world.setBlock(i + 5, j + 4, k + 19, Blocks.viriBlock.blockID);
		world.setBlock(i + 5, j + 4, k + 20, Blocks.viriBlock.blockID);
		world.setBlock(i + 5, j + 4, k + 21, Blocks.viriBlock.blockID);
		world.setBlock(i + 5, j + 4, k + 22, Blocks.viriBlock.blockID);
		world.setBlock(i + 5, j + 4, k + 23, Blocks.viriBlock.blockID);
		world.setBlock(i + 5, j + 4, k + 24, Blocks.viriBlock.blockID);
		world.setBlock(i + 5, j + 4, k + 25, Blocks.viriBlock.blockID);
		world.setBlock(i + 5, j + 4, k + 26, Blocks.viriBlock.blockID);
		world.setBlock(i + 5, j + 4, k + 27, Blocks.viriBlock.blockID);
		world.setBlock(i + 5, j + 4, k + 28, Blocks.viriBlock.blockID);
		world.setBlock(i + 5, j + 4, k + 29, Blocks.viriBlock.blockID);
		world.setBlock(i + 5, j + 4, k + 30, Blocks.viriBlock.blockID);
		world.setBlock(i + 5, j + 4, k + 31, Blocks.viriBlock.blockID);
		world.setBlock(i + 5, j + 4, k + 32, Blocks.viriBlock.blockID);
		world.setBlock(i + 5, j + 4, k + 33, Blocks.viriBlock.blockID);
		world.setBlock(i + 5, j + 5, k + 8, Blocks.viriBlock.blockID);
		world.setBlock(i + 5, j + 5, k + 9, Blocks.viriBlock.blockID);
		world.setBlock(i + 5, j + 5, k + 10, Blocks.viriBlock.blockID);
		world.setBlock(i + 5, j + 5, k + 11, Blocks.viriBlock.blockID);
		world.setBlock(i + 5, j + 5, k + 12, Blocks.viriBlock.blockID);
		world.setBlock(i + 5, j + 5, k + 13, Blocks.viriBlock.blockID);
		world.setBlock(i + 5, j + 5, k + 14, Blocks.viriBlock.blockID);
		world.setBlock(i + 5, j + 5, k + 15, Blocks.viriBlock.blockID);
		world.setBlock(i + 5, j + 5, k + 16, Blocks.viriBlock.blockID);
		world.setBlock(i + 5, j + 5, k + 17, Blocks.viriBlock.blockID);
		world.setBlock(i + 5, j + 5, k + 18, Blocks.viriBlock.blockID);
		world.setBlock(i + 5, j + 5, k + 19, Blocks.viriBlock.blockID);
		world.setBlock(i + 5, j + 5, k + 20, Blocks.viriBlock.blockID);
		world.setBlock(i + 5, j + 5, k + 21, Blocks.viriBlock.blockID);
		world.setBlock(i + 5, j + 5, k + 22, Blocks.viriBlock.blockID);
		world.setBlock(i + 5, j + 5, k + 23, Blocks.viriBlock.blockID);
		world.setBlock(i + 5, j + 5, k + 24, Blocks.viriBlock.blockID);
		world.setBlock(i + 5, j + 5, k + 25, Blocks.viriBlock.blockID);
		world.setBlock(i + 5, j + 5, k + 26, Blocks.viriBlock.blockID);
		world.setBlock(i + 5, j + 5, k + 27, Blocks.viriBlock.blockID);
		world.setBlock(i + 5, j + 5, k + 28, Blocks.viriBlock.blockID);
		world.setBlock(i + 5, j + 5, k + 29, Blocks.viriBlock.blockID);
		world.setBlock(i + 5, j + 5, k + 30, Blocks.viriBlock.blockID);
		world.setBlock(i + 5, j + 5, k + 31, Blocks.viriBlock.blockID);
		world.setBlock(i + 5, j + 6, k + 14, Blocks.viriBlock.blockID);
		world.setBlock(i + 5, j + 6, k + 15, Blocks.viriBlock.blockID);
		world.setBlock(i + 5, j + 6, k + 16, Blocks.viriBlock.blockID);
		world.setBlock(i + 5, j + 6, k + 17, Blocks.viriBlock.blockID);
		world.setBlock(i + 5, j + 6, k + 18, Blocks.viriBlock.blockID);
		world.setBlock(i + 5, j + 6, k + 19, Blocks.viriBlock.blockID);
		world.setBlock(i + 5, j + 6, k + 20, Blocks.viriBlock.blockID);
		world.setBlock(i + 5, j + 6, k + 21, Blocks.viriBlock.blockID);
		world.setBlock(i + 5, j + 6, k + 22, Blocks.viriBlock.blockID);
		world.setBlock(i + 5, j + 6, k + 23, Blocks.viriBlock.blockID);
		world.setBlock(i + 5, j + 6, k + 24, Blocks.viriBlock.blockID);
		world.setBlock(i + 5, j + 6, k + 25, Blocks.viriBlock.blockID);
		world.setBlock(i + 6, j + 1, k + 12, Blocks.viriBlock.blockID);
		world.setBlock(i + 6, j + 1, k + 13, Blocks.viriBlock.blockID);
		world.setBlock(i + 6, j + 1, k + 14, Blocks.viriBlock.blockID);
		world.setBlock(i + 6, j + 1, k + 15, Blocks.viriBlock.blockID);
		world.setBlock(i + 6, j + 1, k + 16, Blocks.viriBlock.blockID);
		world.setBlock(i + 6, j + 1, k + 17, Blocks.viriBlock.blockID);
		world.setBlock(i + 6, j + 1, k + 18, Blocks.viriBlock.blockID);
		world.setBlock(i + 6, j + 1, k + 19, Blocks.viriBlock.blockID);
		world.setBlock(i + 6, j + 1, k + 20, Blocks.viriBlock.blockID);
		world.setBlock(i + 6, j + 1, k + 21, Blocks.viriBlock.blockID);
		world.setBlock(i + 6, j + 1, k + 22, Blocks.viriBlock.blockID);
		world.setBlock(i + 6, j + 1, k + 23, Blocks.viriBlock.blockID);
		world.setBlock(i + 6, j + 1, k + 24, Blocks.viriBlock.blockID);
		world.setBlock(i + 6, j + 1, k + 25, Blocks.viriBlock.blockID);
		world.setBlock(i + 6, j + 1, k + 26, Blocks.viriBlock.blockID);
		world.setBlock(i + 6, j + 1, k + 27, Blocks.viriBlock.blockID);
		world.setBlock(i + 6, j + 2, k + 7, Blocks.viriBlock.blockID);
		world.setBlock(i + 6, j + 2, k + 8, Blocks.viriBlock.blockID);
		world.setBlock(i + 6, j + 2, k + 9, Blocks.viriBlock.blockID);
		world.setBlock(i + 6, j + 2, k + 10, Blocks.viriBlock.blockID);
		world.setBlock(i + 6, j + 2, k + 11, Blocks.viriBlock.blockID);
		world.setBlock(i + 6, j + 2, k + 12, Blocks.viriBlock.blockID);
		world.setBlock(i + 6, j + 2, k + 13, Blocks.viriBlock.blockID);
		world.setBlock(i + 6, j + 2, k + 14, Blocks.viriBlock.blockID);
		world.setBlock(i + 6, j + 2, k + 15, Blocks.viriBlock.blockID);
		world.setBlock(i + 6, j + 2, k + 16, Blocks.viriBlock.blockID);
		world.setBlock(i + 6, j + 2, k + 17, Blocks.viriBlock.blockID);
		world.setBlock(i + 6, j + 2, k + 18, Blocks.viriBlock.blockID);
		world.setBlock(i + 6, j + 2, k + 19, Blocks.viriBlock.blockID);
		world.setBlock(i + 6, j + 2, k + 20, Blocks.viriBlock.blockID);
		world.setBlock(i + 6, j + 2, k + 21, Blocks.viriBlock.blockID);
		world.setBlock(i + 6, j + 2, k + 22, Blocks.viriBlock.blockID);
		world.setBlock(i + 6, j + 2, k + 23, Blocks.viriBlock.blockID);
		world.setBlock(i + 6, j + 2, k + 24, Blocks.viriBlock.blockID);
		world.setBlock(i + 6, j + 2, k + 25, Blocks.viriBlock.blockID);
		world.setBlock(i + 6, j + 2, k + 26, Blocks.viriBlock.blockID);
		world.setBlock(i + 6, j + 2, k + 27, Blocks.viriBlock.blockID);
		world.setBlock(i + 6, j + 2, k + 28, Blocks.viriBlock.blockID);
		world.setBlock(i + 6, j + 2, k + 29, Blocks.viriBlock.blockID);
		world.setBlock(i + 6, j + 2, k + 30, Blocks.viriBlock.blockID);
		world.setBlock(i + 6, j + 2, k + 31, Blocks.viriBlock.blockID);
		world.setBlock(i + 6, j + 2, k + 32, Blocks.viriBlock.blockID);
		world.setBlock(i + 6, j + 3, k + 5, Blocks.viriBlock.blockID);
		world.setBlock(i + 6, j + 3, k + 6, Blocks.viriBlock.blockID);
		world.setBlock(i + 6, j + 3, k + 7, Blocks.viriBlock.blockID);
		world.setBlock(i + 6, j + 3, k + 8, Blocks.viriBlock.blockID);
		world.setBlock(i + 6, j + 3, k + 9, Blocks.viriBlock.blockID);
		world.setBlock(i + 6, j + 3, k + 10, Blocks.viriBlock.blockID);
		world.setBlock(i + 6, j + 3, k + 11, Blocks.viriBlock.blockID);
		world.setBlock(i + 6, j + 3, k + 12, Blocks.viriBlock.blockID);
		world.setBlock(i + 6, j + 3, k + 13, Blocks.viriBlock.blockID);
		world.setBlock(i + 6, j + 3, k + 14, Blocks.viriBlock.blockID);
		world.setBlock(i + 6, j + 3, k + 15, Blocks.viriBlock.blockID);
		world.setBlock(i + 6, j + 3, k + 16, Blocks.viriBlock.blockID);
		world.setBlock(i + 6, j + 3, k + 17, Blocks.viriBlock.blockID);
		world.setBlock(i + 6, j + 3, k + 18, Blocks.viriBlock.blockID);
		world.setBlock(i + 6, j + 3, k + 19, Blocks.viriBlock.blockID);
		world.setBlock(i + 6, j + 3, k + 20, Blocks.viriBlock.blockID);
		world.setBlock(i + 6, j + 3, k + 21, Blocks.viriBlock.blockID);
		world.setBlock(i + 6, j + 3, k + 22, Blocks.viriBlock.blockID);
		world.setBlock(i + 6, j + 3, k + 23, Blocks.viriBlock.blockID);
		world.setBlock(i + 6, j + 3, k + 24, Blocks.viriBlock.blockID);
		world.setBlock(i + 6, j + 3, k + 25, Blocks.viriBlock.blockID);
		world.setBlock(i + 6, j + 3, k + 26, Blocks.viriBlock.blockID);
		world.setBlock(i + 6, j + 3, k + 27, Blocks.viriBlock.blockID);
		world.setBlock(i + 6, j + 3, k + 28, Blocks.viriBlock.blockID);
		world.setBlock(i + 6, j + 3, k + 29, Blocks.viriBlock.blockID);
		world.setBlock(i + 6, j + 3, k + 30, Blocks.viriBlock.blockID);
		world.setBlock(i + 6, j + 3, k + 31, Blocks.viriBlock.blockID);
		world.setBlock(i + 6, j + 3, k + 32, Blocks.viriBlock.blockID);
		world.setBlock(i + 6, j + 3, k + 33, Blocks.viriBlock.blockID);
		world.setBlock(i + 6, j + 3, k + 34, Blocks.viriBlock.blockID);
		world.setBlock(i + 6, j + 4, k + 5, Blocks.viriBlock.blockID);
		world.setBlock(i + 6, j + 4, k + 6, Blocks.viriBlock.blockID);
		world.setBlock(i + 6, j + 4, k + 7, Blocks.viriBlock.blockID);
		world.setBlock(i + 6, j + 4, k + 8, Blocks.viriBlock.blockID);
		world.setBlock(i + 6, j + 4, k + 9, Blocks.viriBlock.blockID);
		world.setBlock(i + 6, j + 4, k + 10, Blocks.viriBlock.blockID);
		world.setBlock(i + 6, j + 4, k + 11, Blocks.viriBlock.blockID);
		world.setBlock(i + 6, j + 4, k + 12, Blocks.viriBlock.blockID);
		world.setBlock(i + 6, j + 4, k + 13, Blocks.viriBlock.blockID);
		world.setBlock(i + 6, j + 4, k + 14, Blocks.viriBlock.blockID);
		world.setBlock(i + 6, j + 4, k + 15, Blocks.viriBlock.blockID);
		world.setBlock(i + 6, j + 4, k + 16, Blocks.viriBlock.blockID);
		world.setBlock(i + 6, j + 4, k + 17, Blocks.viriBlock.blockID);
		world.setBlock(i + 6, j + 4, k + 18, Blocks.viriBlock.blockID);
		world.setBlock(i + 6, j + 4, k + 19, Blocks.viriBlock.blockID);
		world.setBlock(i + 6, j + 4, k + 20, Blocks.viriBlock.blockID);
		world.setBlock(i + 6, j + 4, k + 21, Blocks.viriBlock.blockID);
		world.setBlock(i + 6, j + 4, k + 22, Blocks.viriBlock.blockID);
		world.setBlock(i + 6, j + 4, k + 23, Blocks.viriBlock.blockID);
		world.setBlock(i + 6, j + 4, k + 24, Blocks.viriBlock.blockID);
		world.setBlock(i + 6, j + 4, k + 25, Blocks.viriBlock.blockID);
		world.setBlock(i + 6, j + 4, k + 26, Blocks.viriBlock.blockID);
		world.setBlock(i + 6, j + 4, k + 27, Blocks.viriBlock.blockID);
		world.setBlock(i + 6, j + 4, k + 28, Blocks.viriBlock.blockID);
		world.setBlock(i + 6, j + 4, k + 29, Blocks.viriBlock.blockID);
		world.setBlock(i + 6, j + 4, k + 30, Blocks.viriBlock.blockID);
		world.setBlock(i + 6, j + 4, k + 31, Blocks.viriBlock.blockID);
		world.setBlock(i + 6, j + 4, k + 32, Blocks.viriBlock.blockID);
		world.setBlock(i + 6, j + 4, k + 33, Blocks.viriBlock.blockID);
		world.setBlock(i + 6, j + 4, k + 34, Blocks.viriBlock.blockID);
		world.setBlock(i + 6, j + 5, k + 7, Blocks.viriBlock.blockID);
		world.setBlock(i + 6, j + 5, k + 8, Blocks.viriBlock.blockID);
		world.setBlock(i + 6, j + 5, k + 9, Blocks.viriBlock.blockID);
		world.setBlock(i + 6, j + 5, k + 10, Blocks.viriBlock.blockID);
		world.setBlock(i + 6, j + 5, k + 11, Blocks.viriBlock.blockID);
		world.setBlock(i + 6, j + 5, k + 12, Blocks.viriBlock.blockID);
		world.setBlock(i + 6, j + 5, k + 13, Blocks.viriBlock.blockID);
		world.setBlock(i + 6, j + 5, k + 14, Blocks.viriBlock.blockID);
		world.setBlock(i + 6, j + 5, k + 15, Blocks.viriBlock.blockID);
		world.setBlock(i + 6, j + 5, k + 16, Blocks.viriBlock.blockID);
		world.setBlock(i + 6, j + 5, k + 17, Blocks.viriBlock.blockID);
		world.setBlock(i + 6, j + 5, k + 18, Blocks.viriBlock.blockID);
		world.setBlock(i + 6, j + 5, k + 19, Blocks.viriBlock.blockID);
		world.setBlock(i + 6, j + 5, k + 20, Blocks.viriBlock.blockID);
		world.setBlock(i + 6, j + 5, k + 21, Blocks.viriBlock.blockID);
		world.setBlock(i + 6, j + 5, k + 22, Blocks.viriBlock.blockID);
		world.setBlock(i + 6, j + 5, k + 23, Blocks.viriBlock.blockID);
		world.setBlock(i + 6, j + 5, k + 24, Blocks.viriBlock.blockID);
		world.setBlock(i + 6, j + 5, k + 25, Blocks.viriBlock.blockID);
		world.setBlock(i + 6, j + 5, k + 26, Blocks.viriBlock.blockID);
		world.setBlock(i + 6, j + 5, k + 27, Blocks.viriBlock.blockID);
		world.setBlock(i + 6, j + 5, k + 28, Blocks.viriBlock.blockID);
		world.setBlock(i + 6, j + 5, k + 29, Blocks.viriBlock.blockID);
		world.setBlock(i + 6, j + 5, k + 30, Blocks.viriBlock.blockID);
		world.setBlock(i + 6, j + 5, k + 31, Blocks.viriBlock.blockID);
		world.setBlock(i + 6, j + 5, k + 32, Blocks.viriBlock.blockID);
		world.setBlock(i + 6, j + 6, k + 12, Blocks.viriBlock.blockID);
		world.setBlock(i + 6, j + 6, k + 13, Blocks.viriBlock.blockID);
		world.setBlock(i + 6, j + 6, k + 14, Blocks.viriBlock.blockID);
		world.setBlock(i + 6, j + 6, k + 15, Blocks.viriBlock.blockID);
		world.setBlock(i + 6, j + 6, k + 16, Blocks.viriBlock.blockID);
		world.setBlock(i + 6, j + 6, k + 17, Blocks.viriBlock.blockID);
		world.setBlock(i + 6, j + 6, k + 18, Blocks.viriBlock.blockID);
		world.setBlock(i + 6, j + 6, k + 19, Blocks.viriBlock.blockID);
		world.setBlock(i + 6, j + 6, k + 20, Blocks.viriBlock.blockID);
		world.setBlock(i + 6, j + 6, k + 21, Blocks.viriBlock.blockID);
		world.setBlock(i + 6, j + 6, k + 22, Blocks.viriBlock.blockID);
		world.setBlock(i + 6, j + 6, k + 23, Blocks.viriBlock.blockID);
		world.setBlock(i + 6, j + 6, k + 24, Blocks.viriBlock.blockID);
		world.setBlock(i + 6, j + 6, k + 25, Blocks.viriBlock.blockID);
		world.setBlock(i + 6, j + 6, k + 26, Blocks.viriBlock.blockID);
		world.setBlock(i + 6, j + 6, k + 27, Blocks.viriBlock.blockID);
		world.setBlock(i + 7, j + 1, k + 11, Blocks.viriBlock.blockID);
		world.setBlock(i + 7, j + 1, k + 12, Blocks.viriBlock.blockID);
		world.setBlock(i + 7, j + 1, k + 13, Blocks.viriBlock.blockID);
		world.setBlock(i + 7, j + 1, k + 14, Blocks.viriBlock.blockID);
		world.setBlock(i + 7, j + 1, k + 15, Blocks.viriBlock.blockID);
		world.setBlock(i + 7, j + 1, k + 16, Blocks.viriBlock.blockID);
		world.setBlock(i + 7, j + 1, k + 17, Blocks.viriBlock.blockID);
		world.setBlock(i + 7, j + 1, k + 18, Blocks.viriBlock.blockID);
		world.setBlock(i + 7, j + 1, k + 19, Blocks.viriBlock.blockID);
		world.setBlock(i + 7, j + 1, k + 20, Blocks.viriBlock.blockID);
		world.setBlock(i + 7, j + 1, k + 21, Blocks.viriBlock.blockID);
		world.setBlock(i + 7, j + 1, k + 22, Blocks.viriBlock.blockID);
		world.setBlock(i + 7, j + 1, k + 23, Blocks.viriBlock.blockID);
		world.setBlock(i + 7, j + 1, k + 24, Blocks.viriBlock.blockID);
		world.setBlock(i + 7, j + 1, k + 25, Blocks.viriBlock.blockID);
		world.setBlock(i + 7, j + 1, k + 26, Blocks.viriBlock.blockID);
		world.setBlock(i + 7, j + 1, k + 27, Blocks.viriBlock.blockID);
		world.setBlock(i + 7, j + 1, k + 28, Blocks.viriBlock.blockID);
		world.setBlock(i + 7, j + 2, k + 6, Blocks.viriBlock.blockID);
		world.setBlock(i + 7, j + 2, k + 7, Blocks.viriBlock.blockID);
		world.setBlock(i + 7, j + 2, k + 8, Blocks.viriBlock.blockID);
		world.setBlock(i + 7, j + 2, k + 9, Blocks.viriBlock.blockID);
		world.setBlock(i + 7, j + 2, k + 10, Blocks.viriBlock.blockID);
		world.setBlock(i + 7, j + 2, k + 11, Blocks.viriBlock.blockID);
		world.setBlock(i + 7, j + 2, k + 12, Blocks.viriBlock.blockID);
		world.setBlock(i + 7, j + 2, k + 13, Blocks.viriBlock.blockID);
		world.setBlock(i + 7, j + 2, k + 14, Blocks.viriBlock.blockID);
		world.setBlock(i + 7, j + 2, k + 15, Blocks.viriBlock.blockID);
		world.setBlock(i + 7, j + 2, k + 16, Blocks.viriBlock.blockID);
		world.setBlock(i + 7, j + 2, k + 17, Blocks.viriBlock.blockID);
		world.setBlock(i + 7, j + 2, k + 18, Blocks.viriBlock.blockID);
		world.setBlock(i + 7, j + 2, k + 19, Blocks.viriBlock.blockID);
		world.setBlock(i + 7, j + 2, k + 20, Blocks.viriBlock.blockID);
		world.setBlock(i + 7, j + 2, k + 21, Blocks.viriBlock.blockID);
		world.setBlock(i + 7, j + 2, k + 22, Blocks.viriBlock.blockID);
		world.setBlock(i + 7, j + 2, k + 23, Blocks.viriBlock.blockID);
		world.setBlock(i + 7, j + 2, k + 24, Blocks.viriBlock.blockID);
		world.setBlock(i + 7, j + 2, k + 25, Blocks.viriBlock.blockID);
		world.setBlock(i + 7, j + 2, k + 26, Blocks.viriBlock.blockID);
		world.setBlock(i + 7, j + 2, k + 27, Blocks.viriBlock.blockID);
		world.setBlock(i + 7, j + 2, k + 28, Blocks.viriBlock.blockID);
		world.setBlock(i + 7, j + 2, k + 29, Blocks.viriBlock.blockID);
		world.setBlock(i + 7, j + 2, k + 30, Blocks.viriBlock.blockID);
		world.setBlock(i + 7, j + 2, k + 31, Blocks.viriBlock.blockID);
		world.setBlock(i + 7, j + 2, k + 32, Blocks.viriBlock.blockID);
		world.setBlock(i + 7, j + 2, k + 33, Blocks.viriBlock.blockID);
		world.setBlock(i + 7, j + 3, k + 5, Blocks.viriBlock.blockID);
		world.setBlock(i + 7, j + 3, k + 6, Blocks.viriBlock.blockID);
		world.setBlock(i + 7, j + 3, k + 7, Blocks.viriBlock.blockID);
		world.setBlock(i + 7, j + 3, k + 8, Blocks.viriBlock.blockID);
		world.setBlock(i + 7, j + 3, k + 9, Blocks.viriBlock.blockID);
		world.setBlock(i + 7, j + 3, k + 10, Blocks.viriBlock.blockID);
		world.setBlock(i + 7, j + 3, k + 11, Blocks.viriBlock.blockID);
		world.setBlock(i + 7, j + 3, k + 12, Blocks.viriBlock.blockID);
		world.setBlock(i + 7, j + 3, k + 13, Blocks.viriBlock.blockID);
		world.setBlock(i + 7, j + 3, k + 14, Blocks.viriBlock.blockID);
		world.setBlock(i + 7, j + 3, k + 15, Blocks.viriBlock.blockID);
		world.setBlock(i + 7, j + 3, k + 16, Blocks.viriBlock.blockID);
		world.setBlock(i + 7, j + 3, k + 17, Blocks.viriBlock.blockID);
		world.setBlock(i + 7, j + 3, k + 18, Blocks.viriBlock.blockID);
		world.setBlock(i + 7, j + 3, k + 19, Blocks.viriBlock.blockID);
		world.setBlock(i + 7, j + 3, k + 20, Blocks.viriBlock.blockID);
		world.setBlock(i + 7, j + 3, k + 21, Blocks.viriBlock.blockID);
		world.setBlock(i + 7, j + 3, k + 22, Blocks.viriBlock.blockID);
		world.setBlock(i + 7, j + 3, k + 23, Blocks.viriBlock.blockID);
		world.setBlock(i + 7, j + 3, k + 24, Blocks.viriBlock.blockID);
		world.setBlock(i + 7, j + 3, k + 25, Blocks.viriBlock.blockID);
		world.setBlock(i + 7, j + 3, k + 26, Blocks.viriBlock.blockID);
		world.setBlock(i + 7, j + 3, k + 27, Blocks.viriBlock.blockID);
		world.setBlock(i + 7, j + 3, k + 28, Blocks.viriBlock.blockID);
		world.setBlock(i + 7, j + 3, k + 29, Blocks.viriBlock.blockID);
		world.setBlock(i + 7, j + 3, k + 30, Blocks.viriBlock.blockID);
		world.setBlock(i + 7, j + 3, k + 31, Blocks.viriBlock.blockID);
		world.setBlock(i + 7, j + 3, k + 32, Blocks.viriBlock.blockID);
		world.setBlock(i + 7, j + 3, k + 33, Blocks.viriBlock.blockID);
		world.setBlock(i + 7, j + 3, k + 34, Blocks.viriBlock.blockID);
		world.setBlock(i + 7, j + 4, k + 5, Blocks.viriBlock.blockID);
		world.setBlock(i + 7, j + 4, k + 6, Blocks.viriBlock.blockID);
		world.setBlock(i + 7, j + 4, k + 7, Blocks.viriBlock.blockID);
		world.setBlock(i + 7, j + 4, k + 8, Blocks.viriBlock.blockID);
		world.setBlock(i + 7, j + 4, k + 9, Blocks.viriBlock.blockID);
		world.setBlock(i + 7, j + 4, k + 10, Blocks.viriBlock.blockID);
		world.setBlock(i + 7, j + 4, k + 11, Blocks.viriBlock.blockID);
		world.setBlock(i + 7, j + 4, k + 12, Blocks.viriBlock.blockID);
		world.setBlock(i + 7, j + 4, k + 13, Blocks.viriBlock.blockID);
		world.setBlock(i + 7, j + 4, k + 14, Blocks.viriBlock.blockID);
		world.setBlock(i + 7, j + 4, k + 15, Blocks.viriBlock.blockID);
		world.setBlock(i + 7, j + 4, k + 16, Blocks.viriBlock.blockID);
		world.setBlock(i + 7, j + 4, k + 17, Blocks.viriBlock.blockID);
		world.setBlock(i + 7, j + 4, k + 18, Blocks.viriBlock.blockID);
		world.setBlock(i + 7, j + 4, k + 19, Blocks.viriBlock.blockID);
		world.setBlock(i + 7, j + 4, k + 20, Blocks.viriBlock.blockID);
		world.setBlock(i + 7, j + 4, k + 21, Blocks.viriBlock.blockID);
		world.setBlock(i + 7, j + 4, k + 22, Blocks.viriBlock.blockID);
		world.setBlock(i + 7, j + 4, k + 23, Blocks.viriBlock.blockID);
		world.setBlock(i + 7, j + 4, k + 24, Blocks.viriBlock.blockID);
		world.setBlock(i + 7, j + 4, k + 25, Blocks.viriBlock.blockID);
		world.setBlock(i + 7, j + 4, k + 26, Blocks.viriBlock.blockID);
		world.setBlock(i + 7, j + 4, k + 27, Blocks.viriBlock.blockID);
		world.setBlock(i + 7, j + 4, k + 28, Blocks.viriBlock.blockID);
		world.setBlock(i + 7, j + 4, k + 29, Blocks.viriBlock.blockID);
		world.setBlock(i + 7, j + 4, k + 30, Blocks.viriBlock.blockID);
		world.setBlock(i + 7, j + 4, k + 31, Blocks.viriBlock.blockID);
		world.setBlock(i + 7, j + 4, k + 32, Blocks.viriBlock.blockID);
		world.setBlock(i + 7, j + 4, k + 33, Blocks.viriBlock.blockID);
		world.setBlock(i + 7, j + 4, k + 34, Blocks.viriBlock.blockID);
		world.setBlock(i + 7, j + 5, k + 6, Blocks.viriBlock.blockID);
		world.setBlock(i + 7, j + 5, k + 7, Blocks.viriBlock.blockID);
		world.setBlock(i + 7, j + 5, k + 8, Blocks.viriBlock.blockID);
		world.setBlock(i + 7, j + 5, k + 9, Blocks.viriBlock.blockID);
		world.setBlock(i + 7, j + 5, k + 10, Blocks.viriBlock.blockID);
		world.setBlock(i + 7, j + 5, k + 11, Blocks.viriBlock.blockID);
		world.setBlock(i + 7, j + 5, k + 12, Blocks.viriBlock.blockID);
		world.setBlock(i + 7, j + 5, k + 13, Blocks.viriBlock.blockID);
		world.setBlock(i + 7, j + 5, k + 14, Blocks.viriBlock.blockID);
		world.setBlock(i + 7, j + 5, k + 15, Blocks.viriBlock.blockID);
		world.setBlock(i + 7, j + 5, k + 16, Blocks.viriBlock.blockID);
		world.setBlock(i + 7, j + 5, k + 17, Blocks.viriBlock.blockID);
		world.setBlock(i + 7, j + 5, k + 18, Blocks.viriBlock.blockID);
		world.setBlock(i + 7, j + 5, k + 19, Blocks.viriBlock.blockID);
		world.setBlock(i + 7, j + 5, k + 20, Blocks.viriBlock.blockID);
		world.setBlock(i + 7, j + 5, k + 21, Blocks.viriBlock.blockID);
		world.setBlock(i + 7, j + 5, k + 22, Blocks.viriBlock.blockID);
		world.setBlock(i + 7, j + 5, k + 23, Blocks.viriBlock.blockID);
		world.setBlock(i + 7, j + 5, k + 24, Blocks.viriBlock.blockID);
		world.setBlock(i + 7, j + 5, k + 25, Blocks.viriBlock.blockID);
		world.setBlock(i + 7, j + 5, k + 26, Blocks.viriBlock.blockID);
		world.setBlock(i + 7, j + 5, k + 27, Blocks.viriBlock.blockID);
		world.setBlock(i + 7, j + 5, k + 28, Blocks.viriBlock.blockID);
		world.setBlock(i + 7, j + 5, k + 29, Blocks.viriBlock.blockID);
		world.setBlock(i + 7, j + 5, k + 30, Blocks.viriBlock.blockID);
		world.setBlock(i + 7, j + 5, k + 31, Blocks.viriBlock.blockID);
		world.setBlock(i + 7, j + 5, k + 32, Blocks.viriBlock.blockID);
		world.setBlock(i + 7, j + 5, k + 33, Blocks.viriBlock.blockID);
		world.setBlock(i + 7, j + 6, k + 11, Blocks.viriBlock.blockID);
		world.setBlock(i + 7, j + 6, k + 12, Blocks.viriBlock.blockID);
		world.setBlock(i + 7, j + 6, k + 13, Blocks.viriBlock.blockID);
		world.setBlock(i + 7, j + 6, k + 14, Blocks.viriBlock.blockID);
		world.setBlock(i + 7, j + 6, k + 15, Blocks.viriBlock.blockID);
		world.setBlock(i + 7, j + 6, k + 16, Blocks.viriBlock.blockID);
		world.setBlock(i + 7, j + 6, k + 17, Blocks.viriBlock.blockID);
		world.setBlock(i + 7, j + 6, k + 18, Blocks.viriBlock.blockID);
		world.setBlock(i + 7, j + 6, k + 19, Blocks.viriBlock.blockID);
		world.setBlock(i + 7, j + 6, k + 20, Blocks.viriBlock.blockID);
		world.setBlock(i + 7, j + 6, k + 21, Blocks.viriBlock.blockID);
		world.setBlock(i + 7, j + 6, k + 22, Blocks.viriBlock.blockID);
		world.setBlock(i + 7, j + 6, k + 23, Blocks.viriBlock.blockID);
		world.setBlock(i + 7, j + 6, k + 24, Blocks.viriBlock.blockID);
		world.setBlock(i + 7, j + 6, k + 25, Blocks.viriBlock.blockID);
		world.setBlock(i + 7, j + 6, k + 26, Blocks.viriBlock.blockID);
		world.setBlock(i + 7, j + 6, k + 27, Blocks.viriBlock.blockID);
		world.setBlock(i + 7, j + 6, k + 28, Blocks.viriBlock.blockID);
		world.setBlock(i + 8, j + 1, k + 9, Blocks.viriBlock.blockID);
		world.setBlock(i + 8, j + 1, k + 10, Blocks.viriBlock.blockID);
		world.setBlock(i + 8, j + 1, k + 11, Blocks.viriBlock.blockID);
		world.setBlock(i + 8, j + 1, k + 12, Blocks.viriBlock.blockID);
		world.setBlock(i + 8, j + 1, k + 13, Blocks.viriBlock.blockID);
		world.setBlock(i + 8, j + 1, k + 14, Blocks.viriBlock.blockID);
		world.setBlock(i + 8, j + 1, k + 15, Blocks.viriBlock.blockID);
		world.setBlock(i + 8, j + 1, k + 16, Blocks.viriBlock.blockID);
		world.setBlock(i + 8, j + 1, k + 17, Blocks.viriBlock.blockID);
		world.setBlock(i + 8, j + 1, k + 18, Blocks.viriBlock.blockID);
		world.setBlock(i + 8, j + 1, k + 19, Blocks.viriBlock.blockID);
		world.setBlock(i + 8, j + 1, k + 20, Blocks.viriBlock.blockID);
		world.setBlock(i + 8, j + 1, k + 21, Blocks.viriBlock.blockID);
		world.setBlock(i + 8, j + 1, k + 22, Blocks.viriBlock.blockID);
		world.setBlock(i + 8, j + 1, k + 23, Blocks.viriBlock.blockID);
		world.setBlock(i + 8, j + 1, k + 24, Blocks.viriBlock.blockID);
		world.setBlock(i + 8, j + 1, k + 25, Blocks.viriBlock.blockID);
		world.setBlock(i + 8, j + 1, k + 26, Blocks.viriBlock.blockID);
		world.setBlock(i + 8, j + 1, k + 27, Blocks.viriBlock.blockID);
		world.setBlock(i + 8, j + 1, k + 28, Blocks.viriBlock.blockID);
		world.setBlock(i + 8, j + 1, k + 29, Blocks.viriBlock.blockID);
		world.setBlock(i + 8, j + 1, k + 30, Blocks.viriBlock.blockID);
		world.setBlock(i + 8, j + 2, k + 5, Blocks.viriBlock.blockID);
		world.setBlock(i + 8, j + 2, k + 6, Blocks.viriBlock.blockID);
		world.setBlock(i + 8, j + 2, k + 7, Blocks.viriBlock.blockID);
		world.setBlock(i + 8, j + 2, k + 8, Blocks.viriBlock.blockID);
		world.setBlock(i + 8, j + 2, k + 9, Blocks.viriBlock.blockID);
		world.setBlock(i + 8, j + 2, k + 10, Blocks.viriBlock.blockID);
		world.setBlock(i + 8, j + 2, k + 11, Blocks.viriBlock.blockID);
		world.setBlock(i + 8, j + 2, k + 12, Blocks.viriBlock.blockID);
		world.setBlock(i + 8, j + 2, k + 13, Blocks.viriBlock.blockID);
		world.setBlock(i + 8, j + 2, k + 14, Blocks.viriBlock.blockID);
		world.setBlock(i + 8, j + 2, k + 15, Blocks.viriBlock.blockID);
		world.setBlock(i + 8, j + 2, k + 16, Blocks.viriBlock.blockID);
		world.setBlock(i + 8, j + 2, k + 17, Blocks.viriBlock.blockID);
		world.setBlock(i + 8, j + 2, k + 18, Blocks.viriBlock.blockID);
		world.setBlock(i + 8, j + 2, k + 19, Blocks.viriBlock.blockID);
		world.setBlock(i + 8, j + 2, k + 20, Blocks.viriBlock.blockID);
		world.setBlock(i + 8, j + 2, k + 21, Blocks.viriBlock.blockID);
		world.setBlock(i + 8, j + 2, k + 22, Blocks.viriBlock.blockID);
		world.setBlock(i + 8, j + 2, k + 23, Blocks.viriBlock.blockID);
		world.setBlock(i + 8, j + 2, k + 24, Blocks.viriBlock.blockID);
		world.setBlock(i + 8, j + 2, k + 25, Blocks.viriBlock.blockID);
		world.setBlock(i + 8, j + 2, k + 26, Blocks.viriBlock.blockID);
		world.setBlock(i + 8, j + 2, k + 27, Blocks.viriBlock.blockID);
		world.setBlock(i + 8, j + 2, k + 28, Blocks.viriBlock.blockID);
		world.setBlock(i + 8, j + 2, k + 29, Blocks.viriBlock.blockID);
		world.setBlock(i + 8, j + 2, k + 30, Blocks.viriBlock.blockID);
		world.setBlock(i + 8, j + 2, k + 31, Blocks.viriBlock.blockID);
		world.setBlock(i + 8, j + 2, k + 32, Blocks.viriBlock.blockID);
		world.setBlock(i + 8, j + 2, k + 33, Blocks.viriBlock.blockID);
		world.setBlock(i + 8, j + 2, k + 34, Blocks.viriBlock.blockID);
		world.setBlock(i + 8, j + 3, k + 4, Blocks.viriBlock.blockID);
		world.setBlock(i + 8, j + 3, k + 5, Blocks.viriBlock.blockID);
		world.setBlock(i + 8, j + 3, k + 6, Blocks.viriBlock.blockID);
		world.setBlock(i + 8, j + 3, k + 7, Blocks.viriBlock.blockID);
		world.setBlock(i + 8, j + 3, k + 8, Blocks.viriBlock.blockID);
		world.setBlock(i + 8, j + 3, k + 9, Blocks.viriBlock.blockID);
		world.setBlock(i + 8, j + 3, k + 10, Blocks.viriBlock.blockID);
		world.setBlock(i + 8, j + 3, k + 11, Blocks.viriBlock.blockID);
		world.setBlock(i + 8, j + 3, k + 12, Blocks.viriBlock.blockID);
		world.setBlock(i + 8, j + 3, k + 13, Blocks.viriBlock.blockID);
		world.setBlock(i + 8, j + 3, k + 14, Blocks.viriBlock.blockID);
		world.setBlock(i + 8, j + 3, k + 15, Blocks.viriBlock.blockID);
		world.setBlock(i + 8, j + 3, k + 16, Blocks.viriBlock.blockID);
		world.setBlock(i + 8, j + 3, k + 17, Blocks.viriBlock.blockID);
		world.setBlock(i + 8, j + 3, k + 18, Blocks.viriBlock.blockID);
		world.setBlock(i + 8, j + 3, k + 19, Blocks.viriBlock.blockID);
		world.setBlock(i + 8, j + 3, k + 20, Blocks.viriBlock.blockID);
		world.setBlock(i + 8, j + 3, k + 21, Blocks.viriBlock.blockID);
		world.setBlock(i + 8, j + 3, k + 22, Blocks.viriBlock.blockID);
		world.setBlock(i + 8, j + 3, k + 23, Blocks.viriBlock.blockID);
		world.setBlock(i + 8, j + 3, k + 24, Blocks.viriBlock.blockID);
		world.setBlock(i + 8, j + 3, k + 25, Blocks.viriBlock.blockID);
		world.setBlock(i + 8, j + 3, k + 26, Blocks.viriBlock.blockID);
		world.setBlock(i + 8, j + 3, k + 27, Blocks.viriBlock.blockID);
		world.setBlock(i + 8, j + 3, k + 28, Blocks.viriBlock.blockID);
		world.setBlock(i + 8, j + 3, k + 29, Blocks.viriBlock.blockID);
		world.setBlock(i + 8, j + 3, k + 30, Blocks.viriBlock.blockID);
		world.setBlock(i + 8, j + 3, k + 31, Blocks.viriBlock.blockID);
		world.setBlock(i + 8, j + 3, k + 32, Blocks.viriBlock.blockID);
		world.setBlock(i + 8, j + 3, k + 33, Blocks.viriBlock.blockID);
		world.setBlock(i + 8, j + 3, k + 34, Blocks.viriBlock.blockID);
		world.setBlock(i + 8, j + 3, k + 35, Blocks.viriBlock.blockID);
		world.setBlock(i + 8, j + 4, k + 4, Blocks.viriBlock.blockID);
		world.setBlock(i + 8, j + 4, k + 5, Blocks.viriBlock.blockID);
		world.setBlock(i + 8, j + 4, k + 6, Blocks.viriBlock.blockID);
		world.setBlock(i + 8, j + 4, k + 7, Blocks.viriBlock.blockID);
		world.setBlock(i + 8, j + 4, k + 8, Blocks.viriBlock.blockID);
		world.setBlock(i + 8, j + 4, k + 9, Blocks.viriBlock.blockID);
		world.setBlock(i + 8, j + 4, k + 10, Blocks.viriBlock.blockID);
		world.setBlock(i + 8, j + 4, k + 11, Blocks.viriBlock.blockID);
		world.setBlock(i + 8, j + 4, k + 12, Blocks.viriBlock.blockID);
		world.setBlock(i + 8, j + 4, k + 13, Blocks.viriBlock.blockID);
		world.setBlock(i + 8, j + 4, k + 14, Blocks.viriBlock.blockID);
		world.setBlock(i + 8, j + 4, k + 15, Blocks.viriBlock.blockID);
		world.setBlock(i + 8, j + 4, k + 16, Blocks.viriBlock.blockID);
		world.setBlock(i + 8, j + 4, k + 17, Blocks.viriBlock.blockID);
		world.setBlock(i + 8, j + 4, k + 18, Blocks.viriBlock.blockID);
		world.setBlock(i + 8, j + 4, k + 19, Blocks.viriBlock.blockID);
		world.setBlock(i + 8, j + 4, k + 20, Blocks.viriBlock.blockID);
		world.setBlock(i + 8, j + 4, k + 21, Blocks.viriBlock.blockID);
		world.setBlock(i + 8, j + 4, k + 22, Blocks.viriBlock.blockID);
		world.setBlock(i + 8, j + 4, k + 23, Blocks.viriBlock.blockID);
		world.setBlock(i + 8, j + 4, k + 24, Blocks.viriBlock.blockID);
		world.setBlock(i + 8, j + 4, k + 25, Blocks.viriBlock.blockID);
		world.setBlock(i + 8, j + 4, k + 26, Blocks.viriBlock.blockID);
		world.setBlock(i + 8, j + 4, k + 27, Blocks.viriBlock.blockID);
		world.setBlock(i + 8, j + 4, k + 28, Blocks.viriBlock.blockID);
		world.setBlock(i + 8, j + 4, k + 29, Blocks.viriBlock.blockID);
		world.setBlock(i + 8, j + 4, k + 30, Blocks.viriBlock.blockID);
		world.setBlock(i + 8, j + 4, k + 31, Blocks.viriBlock.blockID);
		world.setBlock(i + 8, j + 4, k + 32, Blocks.viriBlock.blockID);
		world.setBlock(i + 8, j + 4, k + 33, Blocks.viriBlock.blockID);
		world.setBlock(i + 8, j + 4, k + 34, Blocks.viriBlock.blockID);
		world.setBlock(i + 8, j + 4, k + 35, Blocks.viriBlock.blockID);
		world.setBlock(i + 8, j + 5, k + 5, Blocks.viriBlock.blockID);
		world.setBlock(i + 8, j + 5, k + 6, Blocks.viriBlock.blockID);
		world.setBlock(i + 8, j + 5, k + 7, Blocks.viriBlock.blockID);
		world.setBlock(i + 8, j + 5, k + 8, Blocks.viriBlock.blockID);
		world.setBlock(i + 8, j + 5, k + 9, Blocks.viriBlock.blockID);
		world.setBlock(i + 8, j + 5, k + 10, Blocks.viriBlock.blockID);
		world.setBlock(i + 8, j + 5, k + 11, Blocks.viriBlock.blockID);
		world.setBlock(i + 8, j + 5, k + 12, Blocks.viriBlock.blockID);
		world.setBlock(i + 8, j + 5, k + 13, Blocks.viriBlock.blockID);
		world.setBlock(i + 8, j + 5, k + 14, Blocks.viriBlock.blockID);
		world.setBlock(i + 8, j + 5, k + 15, Blocks.viriBlock.blockID);
		world.setBlock(i + 8, j + 5, k + 16, Blocks.viriBlock.blockID);
		world.setBlock(i + 8, j + 5, k + 17, Blocks.viriBlock.blockID);
		world.setBlock(i + 8, j + 5, k + 18, Blocks.viriBlock.blockID);
		world.setBlock(i + 8, j + 5, k + 19, Blocks.viriBlock.blockID);
		world.setBlock(i + 8, j + 5, k + 20, Blocks.viriBlock.blockID);
		world.setBlock(i + 8, j + 5, k + 21, Blocks.viriBlock.blockID);
		world.setBlock(i + 8, j + 5, k + 22, Blocks.viriBlock.blockID);
		world.setBlock(i + 8, j + 5, k + 23, Blocks.viriBlock.blockID);
		world.setBlock(i + 8, j + 5, k + 24, Blocks.viriBlock.blockID);
		world.setBlock(i + 8, j + 5, k + 25, Blocks.viriBlock.blockID);
		world.setBlock(i + 8, j + 5, k + 26, Blocks.viriBlock.blockID);
		world.setBlock(i + 8, j + 5, k + 27, Blocks.viriBlock.blockID);
		world.setBlock(i + 8, j + 5, k + 28, Blocks.viriBlock.blockID);
		world.setBlock(i + 8, j + 5, k + 29, Blocks.viriBlock.blockID);
		world.setBlock(i + 8, j + 5, k + 30, Blocks.viriBlock.blockID);
		world.setBlock(i + 8, j + 5, k + 31, Blocks.viriBlock.blockID);
		world.setBlock(i + 8, j + 5, k + 32, Blocks.viriBlock.blockID);
		world.setBlock(i + 8, j + 5, k + 33, Blocks.viriBlock.blockID);
		world.setBlock(i + 8, j + 5, k + 34, Blocks.viriBlock.blockID);
		world.setBlock(i + 8, j + 6, k + 9, Blocks.viriBlock.blockID);
		world.setBlock(i + 8, j + 6, k + 10, Blocks.viriBlock.blockID);
		world.setBlock(i + 8, j + 6, k + 11, Blocks.viriBlock.blockID);
		world.setBlock(i + 8, j + 6, k + 12, Blocks.viriBlock.blockID);
		world.setBlock(i + 8, j + 6, k + 13, Blocks.viriBlock.blockID);
		world.setBlock(i + 8, j + 6, k + 14, Blocks.viriBlock.blockID);
		world.setBlock(i + 8, j + 6, k + 15, Blocks.viriBlock.blockID);
		world.setBlock(i + 8, j + 6, k + 16, Blocks.viriBlock.blockID);
		world.setBlock(i + 8, j + 6, k + 17, Blocks.viriBlock.blockID);
		world.setBlock(i + 8, j + 6, k + 18, Blocks.viriBlock.blockID);
		world.setBlock(i + 8, j + 6, k + 19, Blocks.viriBlock.blockID);
		world.setBlock(i + 8, j + 6, k + 20, Blocks.viriBlock.blockID);
		world.setBlock(i + 8, j + 6, k + 21, Blocks.viriBlock.blockID);
		world.setBlock(i + 8, j + 6, k + 22, Blocks.viriBlock.blockID);
		world.setBlock(i + 8, j + 6, k + 23, Blocks.viriBlock.blockID);
		world.setBlock(i + 8, j + 6, k + 24, Blocks.viriBlock.blockID);
		world.setBlock(i + 8, j + 6, k + 25, Blocks.viriBlock.blockID);
		world.setBlock(i + 8, j + 6, k + 26, Blocks.viriBlock.blockID);
		world.setBlock(i + 8, j + 6, k + 27, Blocks.viriBlock.blockID);
		world.setBlock(i + 8, j + 6, k + 28, Blocks.viriBlock.blockID);
		world.setBlock(i + 8, j + 6, k + 29, Blocks.viriBlock.blockID);
		world.setBlock(i + 8, j + 6, k + 30, Blocks.viriBlock.blockID);
		world.setBlock(i + 9, j + 1, k + 8, Blocks.viriBlock.blockID);
		world.setBlock(i + 9, j + 1, k + 9, Blocks.viriBlock.blockID);
		world.setBlock(i + 9, j + 1, k + 10, Blocks.viriBlock.blockID);
		world.setBlock(i + 9, j + 1, k + 11, Blocks.viriBlock.blockID);
		world.setBlock(i + 9, j + 1, k + 12, Blocks.viriBlock.blockID);
		world.setBlock(i + 9, j + 1, k + 13, Blocks.viriBlock.blockID);
		world.setBlock(i + 9, j + 1, k + 14, Blocks.viriBlock.blockID);
		world.setBlock(i + 9, j + 1, k + 15, Blocks.viriBlock.blockID);
		world.setBlock(i + 9, j + 1, k + 16, Blocks.viriBlock.blockID);
		world.setBlock(i + 9, j + 1, k + 17, Blocks.viriBlock.blockID);
		world.setBlock(i + 9, j + 1, k + 18, Blocks.viriBlock.blockID);
		world.setBlock(i + 9, j + 1, k + 19, Blocks.viriBlock.blockID);
		world.setBlock(i + 9, j + 1, k + 20, Blocks.viriBlock.blockID);
		world.setBlock(i + 9, j + 1, k + 21, Blocks.viriBlock.blockID);
		world.setBlock(i + 9, j + 1, k + 22, Blocks.viriBlock.blockID);
		world.setBlock(i + 9, j + 1, k + 23, Blocks.viriBlock.blockID);
		world.setBlock(i + 9, j + 1, k + 24, Blocks.viriBlock.blockID);
		world.setBlock(i + 9, j + 1, k + 25, Blocks.viriBlock.blockID);
		world.setBlock(i + 9, j + 1, k + 26, Blocks.viriBlock.blockID);
		world.setBlock(i + 9, j + 1, k + 27, Blocks.viriBlock.blockID);
		world.setBlock(i + 9, j + 1, k + 28, Blocks.viriBlock.blockID);
		world.setBlock(i + 9, j + 1, k + 29, Blocks.viriBlock.blockID);
		world.setBlock(i + 9, j + 1, k + 30, Blocks.viriBlock.blockID);
		world.setBlock(i + 9, j + 1, k + 31, Blocks.viriBlock.blockID);
		world.setBlock(i + 9, j + 2, k + 5, Blocks.viriBlock.blockID);
		world.setBlock(i + 9, j + 2, k + 6, Blocks.viriBlock.blockID);
		world.setBlock(i + 9, j + 2, k + 7, Blocks.viriBlock.blockID);
		world.setBlock(i + 9, j + 2, k + 8, Blocks.viriBlock.blockID);
		world.setBlock(i + 9, j + 2, k + 9, Blocks.viriBlock.blockID);
		world.setBlock(i + 9, j + 2, k + 10, Blocks.viriBlock.blockID);
		world.setBlock(i + 9, j + 2, k + 11, Blocks.viriBlock.blockID);
		world.setBlock(i + 9, j + 2, k + 12, Blocks.viriBlock.blockID);
		world.setBlock(i + 9, j + 2, k + 13, Blocks.viriBlock.blockID);
		world.setBlock(i + 9, j + 2, k + 14, Blocks.viriBlock.blockID);
		world.setBlock(i + 9, j + 2, k + 15, Blocks.viriBlock.blockID);
		world.setBlock(i + 9, j + 2, k + 16, Blocks.viriBlock.blockID);
		world.setBlock(i + 9, j + 2, k + 17, Blocks.viriBlock.blockID);
		world.setBlock(i + 9, j + 2, k + 18, Blocks.viriBlock.blockID);
		world.setBlock(i + 9, j + 2, k + 19, Blocks.viriBlock.blockID);
		world.setBlock(i + 9, j + 2, k + 20, Blocks.viriBlock.blockID);
		world.setBlock(i + 9, j + 2, k + 21, Blocks.viriBlock.blockID);
		world.setBlock(i + 9, j + 2, k + 22, Blocks.viriBlock.blockID);
		world.setBlock(i + 9, j + 2, k + 23, Blocks.viriBlock.blockID);
		world.setBlock(i + 9, j + 2, k + 24, Blocks.viriBlock.blockID);
		world.setBlock(i + 9, j + 2, k + 25, Blocks.viriBlock.blockID);
		world.setBlock(i + 9, j + 2, k + 26, Blocks.viriBlock.blockID);
		world.setBlock(i + 9, j + 2, k + 27, Blocks.viriBlock.blockID);
		world.setBlock(i + 9, j + 2, k + 28, Blocks.viriBlock.blockID);
		world.setBlock(i + 9, j + 2, k + 29, Blocks.viriBlock.blockID);
		world.setBlock(i + 9, j + 2, k + 30, Blocks.viriBlock.blockID);
		world.setBlock(i + 9, j + 2, k + 31, Blocks.viriBlock.blockID);
		world.setBlock(i + 9, j + 2, k + 32, Blocks.viriBlock.blockID);
		world.setBlock(i + 9, j + 2, k + 33, Blocks.viriBlock.blockID);
		world.setBlock(i + 9, j + 2, k + 34, Blocks.viriBlock.blockID);
		world.setBlock(i + 9, j + 3, k + 3, Blocks.viriBlock.blockID);
		world.setBlock(i + 9, j + 3, k + 4, Blocks.viriBlock.blockID);
		world.setBlock(i + 9, j + 3, k + 5, Blocks.viriBlock.blockID);
		world.setBlock(i + 9, j + 3, k + 6, Blocks.viriBlock.blockID);
		world.setBlock(i + 9, j + 3, k + 7, Blocks.viriBlock.blockID);
		world.setBlock(i + 9, j + 3, k + 8, Blocks.viriBlock.blockID);
		world.setBlock(i + 9, j + 3, k + 9, Blocks.viriBlock.blockID);
		world.setBlock(i + 9, j + 3, k + 10, Blocks.viriBlock.blockID);
		world.setBlock(i + 9, j + 3, k + 11, Blocks.viriBlock.blockID);
		world.setBlock(i + 9, j + 3, k + 12, Blocks.viriBlock.blockID);
		world.setBlock(i + 9, j + 3, k + 13, Blocks.viriBlock.blockID);
		world.setBlock(i + 9, j + 3, k + 14, Blocks.viriBlock.blockID);
		world.setBlock(i + 9, j + 3, k + 15, Blocks.viriBlock.blockID);
		world.setBlock(i + 9, j + 3, k + 16, Blocks.viriBlock.blockID);
		world.setBlock(i + 9, j + 3, k + 17, Blocks.viriBlock.blockID);
		world.setBlock(i + 9, j + 3, k + 18, Blocks.viriBlock.blockID);
		world.setBlock(i + 9, j + 3, k + 19, Blocks.viriBlock.blockID);
		world.setBlock(i + 9, j + 3, k + 20, Blocks.viriBlock.blockID);
		world.setBlock(i + 9, j + 3, k + 21, Blocks.viriBlock.blockID);
		world.setBlock(i + 9, j + 3, k + 22, Blocks.viriBlock.blockID);
		world.setBlock(i + 9, j + 3, k + 23, Blocks.viriBlock.blockID);
		world.setBlock(i + 9, j + 3, k + 24, Blocks.viriBlock.blockID);
		world.setBlock(i + 9, j + 3, k + 25, Blocks.viriBlock.blockID);
		world.setBlock(i + 9, j + 3, k + 26, Blocks.viriBlock.blockID);
		world.setBlock(i + 9, j + 3, k + 27, Blocks.viriBlock.blockID);
		world.setBlock(i + 9, j + 3, k + 28, Blocks.viriBlock.blockID);
		world.setBlock(i + 9, j + 3, k + 29, Blocks.viriBlock.blockID);
		world.setBlock(i + 9, j + 3, k + 30, Blocks.viriBlock.blockID);
		world.setBlock(i + 9, j + 3, k + 31, Blocks.viriBlock.blockID);
		world.setBlock(i + 9, j + 3, k + 32, Blocks.viriBlock.blockID);
		world.setBlock(i + 9, j + 3, k + 33, Blocks.viriBlock.blockID);
		world.setBlock(i + 9, j + 3, k + 34, Blocks.viriBlock.blockID);
		world.setBlock(i + 9, j + 3, k + 35, Blocks.viriBlock.blockID);
		world.setBlock(i + 9, j + 3, k + 36, Blocks.viriBlock.blockID);
		world.setBlock(i + 9, j + 4, k + 3, Blocks.viriBlock.blockID);
		world.setBlock(i + 9, j + 4, k + 4, Blocks.viriBlock.blockID);
		world.setBlock(i + 9, j + 4, k + 5, Blocks.viriBlock.blockID);
		world.setBlock(i + 9, j + 4, k + 6, Blocks.viriBlock.blockID);
		world.setBlock(i + 9, j + 4, k + 7, Blocks.viriBlock.blockID);
		world.setBlock(i + 9, j + 4, k + 8, Blocks.viriBlock.blockID);
		world.setBlock(i + 9, j + 4, k + 9, Blocks.viriBlock.blockID);
		world.setBlock(i + 9, j + 4, k + 10, Blocks.viriBlock.blockID);
		world.setBlock(i + 9, j + 4, k + 11, Blocks.viriBlock.blockID);
		world.setBlock(i + 9, j + 4, k + 12, Blocks.viriBlock.blockID);
		world.setBlock(i + 9, j + 4, k + 13, Blocks.viriBlock.blockID);
		world.setBlock(i + 9, j + 4, k + 14, Blocks.viriBlock.blockID);
		world.setBlock(i + 9, j + 4, k + 15, Blocks.viriBlock.blockID);
		world.setBlock(i + 9, j + 4, k + 16, Blocks.viriBlock.blockID);
		world.setBlock(i + 9, j + 4, k + 17, Blocks.viriBlock.blockID);
		world.setBlock(i + 9, j + 4, k + 18, Blocks.viriBlock.blockID);
		world.setBlock(i + 9, j + 4, k + 19, Blocks.viriBlock.blockID);
		world.setBlock(i + 9, j + 4, k + 20, Blocks.viriBlock.blockID);
		world.setBlock(i + 9, j + 4, k + 21, Blocks.viriBlock.blockID);
		world.setBlock(i + 9, j + 4, k + 22, Blocks.viriBlock.blockID);
		world.setBlock(i + 9, j + 4, k + 23, Blocks.viriBlock.blockID);
		world.setBlock(i + 9, j + 4, k + 24, Blocks.viriBlock.blockID);
		world.setBlock(i + 9, j + 4, k + 25, Blocks.viriBlock.blockID);
		world.setBlock(i + 9, j + 4, k + 26, Blocks.viriBlock.blockID);
		world.setBlock(i + 9, j + 4, k + 27, Blocks.viriBlock.blockID);
		world.setBlock(i + 9, j + 4, k + 28, Blocks.viriBlock.blockID);
		world.setBlock(i + 9, j + 4, k + 29, Blocks.viriBlock.blockID);
		world.setBlock(i + 9, j + 4, k + 30, Blocks.viriBlock.blockID);
		world.setBlock(i + 9, j + 4, k + 31, Blocks.viriBlock.blockID);
		world.setBlock(i + 9, j + 4, k + 32, Blocks.viriBlock.blockID);
		world.setBlock(i + 9, j + 4, k + 33, Blocks.viriBlock.blockID);
		world.setBlock(i + 9, j + 4, k + 34, Blocks.viriBlock.blockID);
		world.setBlock(i + 9, j + 4, k + 35, Blocks.viriBlock.blockID);
		world.setBlock(i + 9, j + 4, k + 36, Blocks.viriBlock.blockID);
		world.setBlock(i + 9, j + 5, k + 5, Blocks.viriBlock.blockID);
		world.setBlock(i + 9, j + 5, k + 6, Blocks.viriBlock.blockID);
		world.setBlock(i + 9, j + 5, k + 7, Blocks.viriBlock.blockID);
		world.setBlock(i + 9, j + 5, k + 8, Blocks.viriBlock.blockID);
		world.setBlock(i + 9, j + 5, k + 9, Blocks.viriBlock.blockID);
		world.setBlock(i + 9, j + 5, k + 10, Blocks.viriBlock.blockID);
		world.setBlock(i + 9, j + 5, k + 11, Blocks.viriBlock.blockID);
		world.setBlock(i + 9, j + 5, k + 12, Blocks.viriBlock.blockID);
		world.setBlock(i + 9, j + 5, k + 13, Blocks.viriBlock.blockID);
		world.setBlock(i + 9, j + 5, k + 14, Blocks.viriBlock.blockID);
		world.setBlock(i + 9, j + 5, k + 15, Blocks.viriBlock.blockID);
		world.setBlock(i + 9, j + 5, k + 16, Blocks.viriBlock.blockID);
		world.setBlock(i + 9, j + 5, k + 17, Blocks.viriBlock.blockID);
		world.setBlock(i + 9, j + 5, k + 18, Blocks.viriBlock.blockID);
		world.setBlock(i + 9, j + 5, k + 19, Blocks.viriBlock.blockID);
		world.setBlock(i + 9, j + 5, k + 20, Blocks.viriBlock.blockID);
		world.setBlock(i + 9, j + 5, k + 21, Blocks.viriBlock.blockID);
		world.setBlock(i + 9, j + 5, k + 22, Blocks.viriBlock.blockID);
		world.setBlock(i + 9, j + 5, k + 23, Blocks.viriBlock.blockID);
		world.setBlock(i + 9, j + 5, k + 24, Blocks.viriBlock.blockID);
		world.setBlock(i + 9, j + 5, k + 25, Blocks.viriBlock.blockID);
		world.setBlock(i + 9, j + 5, k + 26, Blocks.viriBlock.blockID);
		world.setBlock(i + 9, j + 5, k + 27, Blocks.viriBlock.blockID);
		world.setBlock(i + 9, j + 5, k + 28, Blocks.viriBlock.blockID);
		world.setBlock(i + 9, j + 5, k + 29, Blocks.viriBlock.blockID);
		world.setBlock(i + 9, j + 5, k + 30, Blocks.viriBlock.blockID);
		world.setBlock(i + 9, j + 5, k + 31, Blocks.viriBlock.blockID);
		world.setBlock(i + 9, j + 5, k + 32, Blocks.viriBlock.blockID);
		world.setBlock(i + 9, j + 5, k + 33, Blocks.viriBlock.blockID);
		world.setBlock(i + 9, j + 5, k + 34, Blocks.viriBlock.blockID);
		world.setBlock(i + 9, j + 6, k + 8, Blocks.viriBlock.blockID);
		world.setBlock(i + 9, j + 6, k + 9, Blocks.viriBlock.blockID);
		world.setBlock(i + 9, j + 6, k + 10, Blocks.viriBlock.blockID);
		world.setBlock(i + 9, j + 6, k + 11, Blocks.viriBlock.blockID);
		world.setBlock(i + 9, j + 6, k + 12, Blocks.viriBlock.blockID);
		world.setBlock(i + 9, j + 6, k + 13, Blocks.viriBlock.blockID);
		world.setBlock(i + 9, j + 6, k + 14, Blocks.viriBlock.blockID);
		world.setBlock(i + 9, j + 6, k + 15, Blocks.viriBlock.blockID);
		world.setBlock(i + 9, j + 6, k + 16, Blocks.viriBlock.blockID);
		world.setBlock(i + 9, j + 6, k + 17, Blocks.viriBlock.blockID);
		world.setBlock(i + 9, j + 6, k + 18, Blocks.viriBlock.blockID);
		world.setBlock(i + 9, j + 6, k + 19, Blocks.viriBlock.blockID);
		world.setBlock(i + 9, j + 6, k + 20, Blocks.viriBlock.blockID);
		world.setBlock(i + 9, j + 6, k + 21, Blocks.viriBlock.blockID);
		world.setBlock(i + 9, j + 6, k + 22, Blocks.viriBlock.blockID);
		world.setBlock(i + 9, j + 6, k + 23, Blocks.viriBlock.blockID);
		world.setBlock(i + 9, j + 6, k + 24, Blocks.viriBlock.blockID);
		world.setBlock(i + 9, j + 6, k + 25, Blocks.viriBlock.blockID);
		world.setBlock(i + 9, j + 6, k + 26, Blocks.viriBlock.blockID);
		world.setBlock(i + 9, j + 6, k + 27, Blocks.viriBlock.blockID);
		world.setBlock(i + 9, j + 6, k + 28, Blocks.viriBlock.blockID);
		world.setBlock(i + 9, j + 6, k + 29, Blocks.viriBlock.blockID);
		world.setBlock(i + 9, j + 6, k + 30, Blocks.viriBlock.blockID);
		world.setBlock(i + 9, j + 6, k + 31, Blocks.viriBlock.blockID);
		world.setBlock(i + 10, j + 0, k + 18, Blocks.viriBlock.blockID);
		world.setBlock(i + 10, j + 0, k + 19, Blocks.viriBlock.blockID);
		world.setBlock(i + 10, j + 0, k + 20, Blocks.viriBlock.blockID);
		world.setBlock(i + 10, j + 0, k + 21, Blocks.viriBlock.blockID);
		world.setBlock(i + 10, j + 1, k + 8, Blocks.viriBlock.blockID);
		world.setBlock(i + 10, j + 1, k + 9, Blocks.viriBlock.blockID);
		world.setBlock(i + 10, j + 1, k + 10, Blocks.viriBlock.blockID);
		world.setBlock(i + 10, j + 1, k + 11, Blocks.viriBlock.blockID);
		world.setBlock(i + 10, j + 1, k + 12, Blocks.viriBlock.blockID);
		world.setBlock(i + 10, j + 1, k + 13, Blocks.viriBlock.blockID);
		world.setBlock(i + 10, j + 1, k + 14, Blocks.viriBlock.blockID);
		world.setBlock(i + 10, j + 1, k + 15, Blocks.viriBlock.blockID);
		world.setBlock(i + 10, j + 1, k + 16, Blocks.viriBlock.blockID);
		world.setBlock(i + 10, j + 1, k + 17, Blocks.viriBlock.blockID);
		world.setBlock(i + 10, j + 1, k + 18, Blocks.viriBlock.blockID);
		world.setBlock(i + 10, j + 1, k + 19, Blocks.viriBlock.blockID);
		world.setBlock(i + 10, j + 1, k + 20, Blocks.viriBlock.blockID);
		world.setBlock(i + 10, j + 1, k + 21, Blocks.viriBlock.blockID);
		world.setBlock(i + 10, j + 1, k + 22, Blocks.viriBlock.blockID);
		world.setBlock(i + 10, j + 1, k + 23, Blocks.viriBlock.blockID);
		world.setBlock(i + 10, j + 1, k + 24, Blocks.viriBlock.blockID);
		world.setBlock(i + 10, j + 1, k + 25, Blocks.viriBlock.blockID);
		world.setBlock(i + 10, j + 1, k + 26, Blocks.viriBlock.blockID);
		world.setBlock(i + 10, j + 1, k + 27, Blocks.viriBlock.blockID);
		world.setBlock(i + 10, j + 1, k + 28, Blocks.viriBlock.blockID);
		world.setBlock(i + 10, j + 1, k + 29, Blocks.viriBlock.blockID);
		world.setBlock(i + 10, j + 1, k + 30, Blocks.viriBlock.blockID);
		world.setBlock(i + 10, j + 1, k + 31, Blocks.viriBlock.blockID);
		world.setBlock(i + 10, j + 2, k + 4, Blocks.viriBlock.blockID);
		world.setBlock(i + 10, j + 2, k + 5, Blocks.viriBlock.blockID);
		world.setBlock(i + 10, j + 2, k + 6, Blocks.viriBlock.blockID);
		world.setBlock(i + 10, j + 2, k + 7, Blocks.viriBlock.blockID);
		world.setBlock(i + 10, j + 2, k + 8, Blocks.viriBlock.blockID);
		world.setBlock(i + 10, j + 2, k + 9, Blocks.viriBlock.blockID);
		world.setBlock(i + 10, j + 2, k + 10, Blocks.viriBlock.blockID);
		world.setBlock(i + 10, j + 2, k + 11, Blocks.viriBlock.blockID);
		world.setBlock(i + 10, j + 2, k + 12, Blocks.viriBlock.blockID);
		world.setBlock(i + 10, j + 2, k + 13, Blocks.viriBlock.blockID);
		world.setBlock(i + 10, j + 2, k + 14, Blocks.viriBlock.blockID);
		world.setBlock(i + 10, j + 2, k + 15, Blocks.viriBlock.blockID);
		world.setBlock(i + 10, j + 2, k + 16, Blocks.viriBlock.blockID);
		world.setBlock(i + 10, j + 2, k + 17, Blocks.viriBlock.blockID);
		world.setBlock(i + 10, j + 2, k + 18, Blocks.viriBlock.blockID);
		world.setBlock(i + 10, j + 2, k + 19, Blocks.viriBlock.blockID);
		world.setBlock(i + 10, j + 2, k + 20, Blocks.viriBlock.blockID);
		world.setBlock(i + 10, j + 2, k + 21, Blocks.viriBlock.blockID);
		world.setBlock(i + 10, j + 2, k + 22, Blocks.viriBlock.blockID);
		world.setBlock(i + 10, j + 2, k + 23, Blocks.viriBlock.blockID);
		world.setBlock(i + 10, j + 2, k + 24, Blocks.viriBlock.blockID);
		world.setBlock(i + 10, j + 2, k + 25, Blocks.viriBlock.blockID);
		world.setBlock(i + 10, j + 2, k + 26, Blocks.viriBlock.blockID);
		world.setBlock(i + 10, j + 2, k + 27, Blocks.viriBlock.blockID);
		world.setBlock(i + 10, j + 2, k + 28, Blocks.viriBlock.blockID);
		world.setBlock(i + 10, j + 2, k + 29, Blocks.viriBlock.blockID);
		world.setBlock(i + 10, j + 2, k + 30, Blocks.viriBlock.blockID);
		world.setBlock(i + 10, j + 2, k + 31, Blocks.viriBlock.blockID);
		world.setBlock(i + 10, j + 2, k + 32, Blocks.viriBlock.blockID);
		world.setBlock(i + 10, j + 2, k + 33, Blocks.viriBlock.blockID);
		world.setBlock(i + 10, j + 2, k + 34, Blocks.viriBlock.blockID);
		world.setBlock(i + 10, j + 2, k + 35, Blocks.viriBlock.blockID);
		world.setBlock(i + 10, j + 3, k + 3, Blocks.viriBlock.blockID);
		world.setBlock(i + 10, j + 3, k + 4, Blocks.viriBlock.blockID);
		world.setBlock(i + 10, j + 3, k + 5, Blocks.viriBlock.blockID);
		world.setBlock(i + 10, j + 3, k + 6, Blocks.viriBlock.blockID);
		world.setBlock(i + 10, j + 3, k + 7, Blocks.viriBlock.blockID);
		world.setBlock(i + 10, j + 3, k + 8, Blocks.viriBlock.blockID);
		world.setBlock(i + 10, j + 3, k + 9, Blocks.viriBlock.blockID);
		world.setBlock(i + 10, j + 3, k + 10, Blocks.viriBlock.blockID);
		world.setBlock(i + 10, j + 3, k + 11, Blocks.viriBlock.blockID);
		world.setBlock(i + 10, j + 3, k + 12, Blocks.viriBlock.blockID);
		world.setBlock(i + 10, j + 3, k + 13, Blocks.viriBlock.blockID);
		world.setBlock(i + 10, j + 3, k + 14, Blocks.viriBlock.blockID);
		world.setBlock(i + 10, j + 3, k + 15, Blocks.viriBlock.blockID);
		world.setBlock(i + 10, j + 3, k + 16, Blocks.viriBlock.blockID);
		world.setBlock(i + 10, j + 3, k + 17, Blocks.viriBlock.blockID);
		world.setBlock(i + 10, j + 3, k + 18, Blocks.viriBlock.blockID);
		world.setBlock(i + 10, j + 3, k + 19, Blocks.viriBlock.blockID);
		world.setBlock(i + 10, j + 3, k + 20, Blocks.viriBlock.blockID);
		world.setBlock(i + 10, j + 3, k + 21, Blocks.viriBlock.blockID);
		world.setBlock(i + 10, j + 3, k + 22, Blocks.viriBlock.blockID);
		world.setBlock(i + 10, j + 3, k + 23, Blocks.viriBlock.blockID);
		world.setBlock(i + 10, j + 3, k + 24, Blocks.viriBlock.blockID);
		world.setBlock(i + 10, j + 3, k + 25, Blocks.viriBlock.blockID);
		world.setBlock(i + 10, j + 3, k + 26, Blocks.viriBlock.blockID);
		world.setBlock(i + 10, j + 3, k + 27, Blocks.viriBlock.blockID);
		world.setBlock(i + 10, j + 3, k + 28, Blocks.viriBlock.blockID);
		world.setBlock(i + 10, j + 3, k + 29, Blocks.viriBlock.blockID);
		world.setBlock(i + 10, j + 3, k + 30, Blocks.viriBlock.blockID);
		world.setBlock(i + 10, j + 3, k + 31, Blocks.viriBlock.blockID);
		world.setBlock(i + 10, j + 3, k + 32, Blocks.viriBlock.blockID);
		world.setBlock(i + 10, j + 3, k + 33, Blocks.viriBlock.blockID);
		world.setBlock(i + 10, j + 3, k + 34, Blocks.viriBlock.blockID);
		world.setBlock(i + 10, j + 3, k + 35, Blocks.viriBlock.blockID);
		world.setBlock(i + 10, j + 3, k + 36, Blocks.viriBlock.blockID);
		world.setBlock(i + 10, j + 4, k + 3, Blocks.viriBlock.blockID);
		world.setBlock(i + 10, j + 4, k + 4, Blocks.viriBlock.blockID);
		world.setBlock(i + 10, j + 4, k + 5, Blocks.viriBlock.blockID);
		world.setBlock(i + 10, j + 4, k + 6, Blocks.viriBlock.blockID);
		world.setBlock(i + 10, j + 4, k + 7, Blocks.viriBlock.blockID);
		world.setBlock(i + 10, j + 4, k + 8, Blocks.viriBlock.blockID);
		world.setBlock(i + 10, j + 4, k + 9, Blocks.viriBlock.blockID);
		world.setBlock(i + 10, j + 4, k + 10, Blocks.viriBlock.blockID);
		world.setBlock(i + 10, j + 4, k + 11, Blocks.viriBlock.blockID);
		world.setBlock(i + 10, j + 4, k + 12, Blocks.viriBlock.blockID);
		world.setBlock(i + 10, j + 4, k + 13, Blocks.viriBlock.blockID);
		world.setBlock(i + 10, j + 4, k + 14, Blocks.viriBlock.blockID);
		world.setBlock(i + 10, j + 4, k + 15, Blocks.viriBlock.blockID);
		world.setBlock(i + 10, j + 4, k + 16, Blocks.viriBlock.blockID);
		world.setBlock(i + 10, j + 4, k + 17, Blocks.viriBlock.blockID);
		world.setBlock(i + 10, j + 4, k + 18, Blocks.viriBlock.blockID);
		world.setBlock(i + 10, j + 4, k + 19, Blocks.viriBlock.blockID);
		world.setBlock(i + 10, j + 4, k + 20, Blocks.viriBlock.blockID);
		world.setBlock(i + 10, j + 4, k + 21, Blocks.viriBlock.blockID);
		world.setBlock(i + 10, j + 4, k + 22, Blocks.viriBlock.blockID);
		world.setBlock(i + 10, j + 4, k + 23, Blocks.viriBlock.blockID);
		world.setBlock(i + 10, j + 4, k + 24, Blocks.viriBlock.blockID);
		world.setBlock(i + 10, j + 4, k + 25, Blocks.viriBlock.blockID);
		world.setBlock(i + 10, j + 4, k + 26, Blocks.viriBlock.blockID);
		world.setBlock(i + 10, j + 4, k + 27, Blocks.viriBlock.blockID);
		world.setBlock(i + 10, j + 4, k + 28, Blocks.viriBlock.blockID);
		world.setBlock(i + 10, j + 4, k + 29, Blocks.viriBlock.blockID);
		world.setBlock(i + 10, j + 4, k + 30, Blocks.viriBlock.blockID);
		world.setBlock(i + 10, j + 4, k + 31, Blocks.viriBlock.blockID);
		world.setBlock(i + 10, j + 4, k + 32, Blocks.viriBlock.blockID);
		world.setBlock(i + 10, j + 4, k + 33, Blocks.viriBlock.blockID);
		world.setBlock(i + 10, j + 4, k + 34, Blocks.viriBlock.blockID);
		world.setBlock(i + 10, j + 4, k + 35, Blocks.viriBlock.blockID);
		world.setBlock(i + 10, j + 4, k + 36, Blocks.viriBlock.blockID);
		world.setBlock(i + 10, j + 5, k + 4, Blocks.viriBlock.blockID);
		world.setBlock(i + 10, j + 5, k + 5, Blocks.viriBlock.blockID);
		world.setBlock(i + 10, j + 5, k + 6, Blocks.viriBlock.blockID);
		world.setBlock(i + 10, j + 5, k + 7, Blocks.viriBlock.blockID);
		world.setBlock(i + 10, j + 5, k + 8, Blocks.viriBlock.blockID);
		world.setBlock(i + 10, j + 5, k + 9, Blocks.viriBlock.blockID);
		world.setBlock(i + 10, j + 5, k + 10, Blocks.viriBlock.blockID);
		world.setBlock(i + 10, j + 5, k + 11, Blocks.viriBlock.blockID);
		world.setBlock(i + 10, j + 5, k + 12, Blocks.viriBlock.blockID);
		world.setBlock(i + 10, j + 5, k + 13, Blocks.viriBlock.blockID);
		world.setBlock(i + 10, j + 5, k + 14, Blocks.viriBlock.blockID);
		world.setBlock(i + 10, j + 5, k + 15, Blocks.viriBlock.blockID);
		world.setBlock(i + 10, j + 5, k + 16, Blocks.viriBlock.blockID);
		world.setBlock(i + 10, j + 5, k + 17, Blocks.viriBlock.blockID);
		world.setBlock(i + 10, j + 5, k + 18, Blocks.viriBlock.blockID);
		world.setBlock(i + 10, j + 5, k + 19, Blocks.viriBlock.blockID);
		world.setBlock(i + 10, j + 5, k + 20, Blocks.viriBlock.blockID);
		world.setBlock(i + 10, j + 5, k + 21, Blocks.viriBlock.blockID);
		world.setBlock(i + 10, j + 5, k + 22, Blocks.viriBlock.blockID);
		world.setBlock(i + 10, j + 5, k + 23, Blocks.viriBlock.blockID);
		world.setBlock(i + 10, j + 5, k + 24, Blocks.viriBlock.blockID);
		world.setBlock(i + 10, j + 5, k + 25, Blocks.viriBlock.blockID);
		world.setBlock(i + 10, j + 5, k + 26, Blocks.viriBlock.blockID);
		world.setBlock(i + 10, j + 5, k + 27, Blocks.viriBlock.blockID);
		world.setBlock(i + 10, j + 5, k + 28, Blocks.viriBlock.blockID);
		world.setBlock(i + 10, j + 5, k + 29, Blocks.viriBlock.blockID);
		world.setBlock(i + 10, j + 5, k + 30, Blocks.viriBlock.blockID);
		world.setBlock(i + 10, j + 5, k + 31, Blocks.viriBlock.blockID);
		world.setBlock(i + 10, j + 5, k + 32, Blocks.viriBlock.blockID);
		world.setBlock(i + 10, j + 5, k + 33, Blocks.viriBlock.blockID);
		world.setBlock(i + 10, j + 5, k + 34, Blocks.viriBlock.blockID);
		world.setBlock(i + 10, j + 5, k + 35, Blocks.viriBlock.blockID);
		world.setBlock(i + 10, j + 6, k + 8, Blocks.viriBlock.blockID);
		world.setBlock(i + 10, j + 6, k + 9, Blocks.viriBlock.blockID);
		world.setBlock(i + 10, j + 6, k + 10, Blocks.viriBlock.blockID);
		world.setBlock(i + 10, j + 6, k + 11, Blocks.viriBlock.blockID);
		world.setBlock(i + 10, j + 6, k + 12, Blocks.viriBlock.blockID);
		world.setBlock(i + 10, j + 6, k + 13, Blocks.viriBlock.blockID);
		world.setBlock(i + 10, j + 6, k + 14, Blocks.viriBlock.blockID);
		world.setBlock(i + 10, j + 6, k + 15, Blocks.viriBlock.blockID);
		world.setBlock(i + 10, j + 6, k + 16, Blocks.viriBlock.blockID);
		world.setBlock(i + 10, j + 6, k + 17, Blocks.viriBlock.blockID);
		world.setBlock(i + 10, j + 6, k + 18, Blocks.viriBlock.blockID);
		world.setBlock(i + 10, j + 6, k + 19, Blocks.viriBlock.blockID);
		world.setBlock(i + 10, j + 6, k + 20, Blocks.viriBlock.blockID);
		world.setBlock(i + 10, j + 6, k + 21, Blocks.viriBlock.blockID);
		world.setBlock(i + 10, j + 6, k + 22, Blocks.viriBlock.blockID);
		world.setBlock(i + 10, j + 6, k + 23, Blocks.viriBlock.blockID);
		world.setBlock(i + 10, j + 6, k + 24, Blocks.viriBlock.blockID);
		world.setBlock(i + 10, j + 6, k + 25, Blocks.viriBlock.blockID);
		world.setBlock(i + 10, j + 6, k + 26, Blocks.viriBlock.blockID);
		world.setBlock(i + 10, j + 6, k + 27, Blocks.viriBlock.blockID);
		world.setBlock(i + 10, j + 6, k + 28, Blocks.viriBlock.blockID);
		world.setBlock(i + 10, j + 6, k + 29, Blocks.viriBlock.blockID);
		world.setBlock(i + 10, j + 6, k + 30, Blocks.viriBlock.blockID);
		world.setBlock(i + 10, j + 6, k + 31, Blocks.viriBlock.blockID);
		world.setBlock(i + 10, j + 7, k + 18, Blocks.viriBlock.blockID);
		world.setBlock(i + 10, j + 7, k + 19, Blocks.viriBlock.blockID);
		world.setBlock(i + 10, j + 7, k + 20, Blocks.viriBlock.blockID);
		world.setBlock(i + 10, j + 7, k + 21, Blocks.viriBlock.blockID);
		world.setBlock(i + 11, j + 0, k + 15, Blocks.viriBlock.blockID);
		world.setBlock(i + 11, j + 0, k + 16, Blocks.viriBlock.blockID);
		world.setBlock(i + 11, j + 0, k + 17, Blocks.viriBlock.blockID);
		world.setBlock(i + 11, j + 0, k + 18, Blocks.viriBlock.blockID);
		world.setBlock(i + 11, j + 0, k + 19, Blocks.viriBlock.blockID);
		world.setBlock(i + 11, j + 0, k + 20, Blocks.viriBlock.blockID);
		world.setBlock(i + 11, j + 0, k + 21, Blocks.viriBlock.blockID);
		world.setBlock(i + 11, j + 0, k + 22, Blocks.viriBlock.blockID);
		world.setBlock(i + 11, j + 0, k + 23, Blocks.viriBlock.blockID);
		world.setBlock(i + 11, j + 0, k + 24, Blocks.viriBlock.blockID);
		world.setBlock(i + 11, j + 1, k + 7, Blocks.viriBlock.blockID);
		world.setBlock(i + 11, j + 1, k + 8, Blocks.viriBlock.blockID);
		world.setBlock(i + 11, j + 1, k + 9, Blocks.viriBlock.blockID);
		world.setBlock(i + 11, j + 1, k + 10, Blocks.viriBlock.blockID);
		world.setBlock(i + 11, j + 1, k + 11, Blocks.viriBlock.blockID);
		world.setBlock(i + 11, j + 1, k + 12, Blocks.viriBlock.blockID);
		world.setBlock(i + 11, j + 1, k + 13, Blocks.viriBlock.blockID);
		world.setBlock(i + 11, j + 1, k + 14, Blocks.viriBlock.blockID);
		world.setBlock(i + 11, j + 1, k + 15, Blocks.viriBlock.blockID);
		world.setBlock(i + 11, j + 1, k + 16, Blocks.viriBlock.blockID);
		world.setBlock(i + 11, j + 1, k + 17, Blocks.viriBlock.blockID);
		world.setBlock(i + 11, j + 1, k + 18, Blocks.viriBlock.blockID);
		world.setBlock(i + 11, j + 1, k + 19, Blocks.viriBlock.blockID);
		world.setBlock(i + 11, j + 1, k + 20, Blocks.viriBlock.blockID);
		world.setBlock(i + 11, j + 1, k + 21, Blocks.viriBlock.blockID);
		world.setBlock(i + 11, j + 1, k + 22, Blocks.viriBlock.blockID);
		world.setBlock(i + 11, j + 1, k + 23, Blocks.viriBlock.blockID);
		world.setBlock(i + 11, j + 1, k + 24, Blocks.viriBlock.blockID);
		world.setBlock(i + 11, j + 1, k + 25, Blocks.viriBlock.blockID);
		world.setBlock(i + 11, j + 1, k + 26, Blocks.viriBlock.blockID);
		world.setBlock(i + 11, j + 1, k + 27, Blocks.viriBlock.blockID);
		world.setBlock(i + 11, j + 1, k + 28, Blocks.viriBlock.blockID);
		world.setBlock(i + 11, j + 1, k + 29, Blocks.viriBlock.blockID);
		world.setBlock(i + 11, j + 1, k + 30, Blocks.viriBlock.blockID);
		world.setBlock(i + 11, j + 1, k + 31, Blocks.viriBlock.blockID);
		world.setBlock(i + 11, j + 1, k + 32, Blocks.viriBlock.blockID);
		world.setBlock(i + 11, j + 2, k + 4, Blocks.viriBlock.blockID);
		world.setBlock(i + 11, j + 2, k + 5, Blocks.viriBlock.blockID);
		world.setBlock(i + 11, j + 2, k + 6, Blocks.viriBlock.blockID);
		world.setBlock(i + 11, j + 2, k + 7, Blocks.viriBlock.blockID);
		world.setBlock(i + 11, j + 2, k + 8, Blocks.viriBlock.blockID);
		world.setBlock(i + 11, j + 2, k + 9, Blocks.viriBlock.blockID);
		world.setBlock(i + 11, j + 2, k + 10, Blocks.viriBlock.blockID);
		world.setBlock(i + 11, j + 2, k + 11, Blocks.viriBlock.blockID);
		world.setBlock(i + 11, j + 2, k + 12, Blocks.viriBlock.blockID);
		world.setBlock(i + 11, j + 2, k + 13, Blocks.viriBlock.blockID);
		world.setBlock(i + 11, j + 2, k + 14, Blocks.viriBlock.blockID);
		world.setBlock(i + 11, j + 2, k + 15, Blocks.viriBlock.blockID);
		world.setBlock(i + 11, j + 2, k + 16, Blocks.viriBlock.blockID);
		world.setBlock(i + 11, j + 2, k + 17, Blocks.viriBlock.blockID);
		world.setBlock(i + 11, j + 2, k + 18, Blocks.viriBlock.blockID);
		world.setBlock(i + 11, j + 2, k + 19, Blocks.viriBlock.blockID);
		world.setBlock(i + 11, j + 2, k + 20, Blocks.viriBlock.blockID);
		world.setBlock(i + 11, j + 2, k + 21, Blocks.viriBlock.blockID);
		world.setBlock(i + 11, j + 2, k + 22, Blocks.viriBlock.blockID);
		world.setBlock(i + 11, j + 2, k + 23, Blocks.viriBlock.blockID);
		world.setBlock(i + 11, j + 2, k + 24, Blocks.viriBlock.blockID);
		world.setBlock(i + 11, j + 2, k + 25, Blocks.viriBlock.blockID);
		world.setBlock(i + 11, j + 2, k + 26, Blocks.viriBlock.blockID);
		world.setBlock(i + 11, j + 2, k + 27, Blocks.viriBlock.blockID);
		world.setBlock(i + 11, j + 2, k + 28, Blocks.viriBlock.blockID);
		world.setBlock(i + 11, j + 2, k + 29, Blocks.viriBlock.blockID);
		world.setBlock(i + 11, j + 2, k + 30, Blocks.viriBlock.blockID);
		world.setBlock(i + 11, j + 2, k + 31, Blocks.viriBlock.blockID);
		world.setBlock(i + 11, j + 2, k + 32, Blocks.viriBlock.blockID);
		world.setBlock(i + 11, j + 2, k + 33, Blocks.viriBlock.blockID);
		world.setBlock(i + 11, j + 2, k + 34, Blocks.viriBlock.blockID);
		world.setBlock(i + 11, j + 2, k + 35, Blocks.viriBlock.blockID);
		world.setBlock(i + 11, j + 3, k + 2, Blocks.viriBlock.blockID);
		world.setBlock(i + 11, j + 3, k + 3, Blocks.viriBlock.blockID);
		world.setBlock(i + 11, j + 3, k + 4, Blocks.viriBlock.blockID);
		world.setBlock(i + 11, j + 3, k + 5, Blocks.viriBlock.blockID);
		world.setBlock(i + 11, j + 3, k + 6, Blocks.viriBlock.blockID);
		world.setBlock(i + 11, j + 3, k + 7, Blocks.viriBlock.blockID);
		world.setBlock(i + 11, j + 3, k + 8, Blocks.viriBlock.blockID);
		world.setBlock(i + 11, j + 3, k + 9, Blocks.viriBlock.blockID);
		world.setBlock(i + 11, j + 3, k + 10, Blocks.viriBlock.blockID);
		world.setBlock(i + 11, j + 3, k + 11, Blocks.viriBlock.blockID);
		world.setBlock(i + 11, j + 3, k + 12, Blocks.viriBlock.blockID);
		world.setBlock(i + 11, j + 3, k + 13, Blocks.viriBlock.blockID);
		world.setBlock(i + 11, j + 3, k + 14, Blocks.viriBlock.blockID);
		world.setBlock(i + 11, j + 3, k + 15, Blocks.viriBlock.blockID);
		world.setBlock(i + 11, j + 3, k + 16, Blocks.viriBlock.blockID);
		world.setBlock(i + 11, j + 3, k + 17, Blocks.viriBlock.blockID);
		world.setBlock(i + 11, j + 3, k + 18, Blocks.viriBlock.blockID);
		world.setBlock(i + 11, j + 3, k + 19, Blocks.viriBlock.blockID);
		world.setBlock(i + 11, j + 3, k + 20, Blocks.viriBlock.blockID);
		world.setBlock(i + 11, j + 3, k + 21, Blocks.viriBlock.blockID);
		world.setBlock(i + 11, j + 3, k + 22, Blocks.viriBlock.blockID);
		world.setBlock(i + 11, j + 3, k + 23, Blocks.viriBlock.blockID);
		world.setBlock(i + 11, j + 3, k + 24, Blocks.viriBlock.blockID);
		world.setBlock(i + 11, j + 3, k + 25, Blocks.viriBlock.blockID);
		world.setBlock(i + 11, j + 3, k + 26, Blocks.viriBlock.blockID);
		world.setBlock(i + 11, j + 3, k + 27, Blocks.viriBlock.blockID);
		world.setBlock(i + 11, j + 3, k + 28, Blocks.viriBlock.blockID);
		world.setBlock(i + 11, j + 3, k + 29, Blocks.viriBlock.blockID);
		world.setBlock(i + 11, j + 3, k + 30, Blocks.viriBlock.blockID);
		world.setBlock(i + 11, j + 3, k + 31, Blocks.viriBlock.blockID);
		world.setBlock(i + 11, j + 3, k + 32, Blocks.viriBlock.blockID);
		world.setBlock(i + 11, j + 3, k + 33, Blocks.viriBlock.blockID);
		world.setBlock(i + 11, j + 3, k + 34, Blocks.viriBlock.blockID);
		world.setBlock(i + 11, j + 3, k + 35, Blocks.viriBlock.blockID);
		world.setBlock(i + 11, j + 3, k + 36, Blocks.viriBlock.blockID);
		world.setBlock(i + 11, j + 3, k + 37, Blocks.viriBlock.blockID);
		world.setBlock(i + 11, j + 4, k + 2, Blocks.viriBlock.blockID);
		world.setBlock(i + 11, j + 4, k + 3, Blocks.viriBlock.blockID);
		world.setBlock(i + 11, j + 4, k + 4, Blocks.viriBlock.blockID);
		world.setBlock(i + 11, j + 4, k + 5, Blocks.viriBlock.blockID);
		world.setBlock(i + 11, j + 4, k + 6, Blocks.viriBlock.blockID);
		world.setBlock(i + 11, j + 4, k + 7, Blocks.viriBlock.blockID);
		world.setBlock(i + 11, j + 4, k + 8, Blocks.viriBlock.blockID);
		world.setBlock(i + 11, j + 4, k + 9, Blocks.viriBlock.blockID);
		world.setBlock(i + 11, j + 4, k + 10, Blocks.viriBlock.blockID);
		world.setBlock(i + 11, j + 4, k + 11, Blocks.viriBlock.blockID);
		world.setBlock(i + 11, j + 4, k + 12, Blocks.viriBlock.blockID);
		world.setBlock(i + 11, j + 4, k + 13, Blocks.viriBlock.blockID);
		world.setBlock(i + 11, j + 4, k + 14, Blocks.viriBlock.blockID);
		world.setBlock(i + 11, j + 4, k + 15, Blocks.viriBlock.blockID);
		world.setBlock(i + 11, j + 4, k + 16, Blocks.viriBlock.blockID);
		world.setBlock(i + 11, j + 4, k + 17, Blocks.viriBlock.blockID);
		world.setBlock(i + 11, j + 4, k + 18, Blocks.viriBlock.blockID);
		world.setBlock(i + 11, j + 4, k + 19, Blocks.viriBlock.blockID);
		world.setBlock(i + 11, j + 4, k + 20, Blocks.viriBlock.blockID);
		world.setBlock(i + 11, j + 4, k + 21, Blocks.viriBlock.blockID);
		world.setBlock(i + 11, j + 4, k + 22, Blocks.viriBlock.blockID);
		world.setBlock(i + 11, j + 4, k + 23, Blocks.viriBlock.blockID);
		world.setBlock(i + 11, j + 4, k + 24, Blocks.viriBlock.blockID);
		world.setBlock(i + 11, j + 4, k + 25, Blocks.viriBlock.blockID);
		world.setBlock(i + 11, j + 4, k + 26, Blocks.viriBlock.blockID);
		world.setBlock(i + 11, j + 4, k + 27, Blocks.viriBlock.blockID);
		world.setBlock(i + 11, j + 4, k + 28, Blocks.viriBlock.blockID);
		world.setBlock(i + 11, j + 4, k + 29, Blocks.viriBlock.blockID);
		world.setBlock(i + 11, j + 4, k + 30, Blocks.viriBlock.blockID);
		world.setBlock(i + 11, j + 4, k + 31, Blocks.viriBlock.blockID);
		world.setBlock(i + 11, j + 4, k + 32, Blocks.viriBlock.blockID);
		world.setBlock(i + 11, j + 4, k + 33, Blocks.viriBlock.blockID);
		world.setBlock(i + 11, j + 4, k + 34, Blocks.viriBlock.blockID);
		world.setBlock(i + 11, j + 4, k + 35, Blocks.viriBlock.blockID);
		world.setBlock(i + 11, j + 4, k + 36, Blocks.viriBlock.blockID);
		world.setBlock(i + 11, j + 4, k + 37, Blocks.viriBlock.blockID);
		world.setBlock(i + 11, j + 5, k + 4, Blocks.viriBlock.blockID);
		world.setBlock(i + 11, j + 5, k + 5, Blocks.viriBlock.blockID);
		world.setBlock(i + 11, j + 5, k + 6, Blocks.viriBlock.blockID);
		world.setBlock(i + 11, j + 5, k + 7, Blocks.viriBlock.blockID);
		world.setBlock(i + 11, j + 5, k + 8, Blocks.viriBlock.blockID);
		world.setBlock(i + 11, j + 5, k + 9, Blocks.viriBlock.blockID);
		world.setBlock(i + 11, j + 5, k + 10, Blocks.viriBlock.blockID);
		world.setBlock(i + 11, j + 5, k + 11, Blocks.viriBlock.blockID);
		world.setBlock(i + 11, j + 5, k + 12, Blocks.viriBlock.blockID);
		world.setBlock(i + 11, j + 5, k + 13, Blocks.viriBlock.blockID);
		world.setBlock(i + 11, j + 5, k + 14, Blocks.viriBlock.blockID);
		world.setBlock(i + 11, j + 5, k + 15, Blocks.viriBlock.blockID);
		world.setBlock(i + 11, j + 5, k + 16, Blocks.viriBlock.blockID);
		world.setBlock(i + 11, j + 5, k + 17, Blocks.viriBlock.blockID);
		world.setBlock(i + 11, j + 5, k + 18, Blocks.viriBlock.blockID);
		world.setBlock(i + 11, j + 5, k + 19, Blocks.viriBlock.blockID);
		world.setBlock(i + 11, j + 5, k + 20, Blocks.viriBlock.blockID);
		world.setBlock(i + 11, j + 5, k + 21, Blocks.viriBlock.blockID);
		world.setBlock(i + 11, j + 5, k + 22, Blocks.viriBlock.blockID);
		world.setBlock(i + 11, j + 5, k + 23, Blocks.viriBlock.blockID);
		world.setBlock(i + 11, j + 5, k + 24, Blocks.viriBlock.blockID);
		world.setBlock(i + 11, j + 5, k + 25, Blocks.viriBlock.blockID);
		world.setBlock(i + 11, j + 5, k + 26, Blocks.viriBlock.blockID);
		world.setBlock(i + 11, j + 5, k + 27, Blocks.viriBlock.blockID);
		world.setBlock(i + 11, j + 5, k + 28, Blocks.viriBlock.blockID);
		world.setBlock(i + 11, j + 5, k + 29, Blocks.viriBlock.blockID);
		world.setBlock(i + 11, j + 5, k + 30, Blocks.viriBlock.blockID);
		world.setBlock(i + 11, j + 5, k + 31, Blocks.viriBlock.blockID);
		world.setBlock(i + 11, j + 5, k + 32, Blocks.viriBlock.blockID);
		world.setBlock(i + 11, j + 5, k + 33, Blocks.viriBlock.blockID);
		world.setBlock(i + 11, j + 5, k + 34, Blocks.viriBlock.blockID);
		world.setBlock(i + 11, j + 5, k + 35, Blocks.viriBlock.blockID);
		world.setBlock(i + 11, j + 6, k + 7, Blocks.viriBlock.blockID);
		world.setBlock(i + 11, j + 6, k + 8, Blocks.viriBlock.blockID);
		world.setBlock(i + 11, j + 6, k + 9, Blocks.viriBlock.blockID);
		world.setBlock(i + 11, j + 6, k + 10, Blocks.viriBlock.blockID);
		world.setBlock(i + 11, j + 6, k + 11, Blocks.viriBlock.blockID);
		world.setBlock(i + 11, j + 6, k + 12, Blocks.viriBlock.blockID);
		world.setBlock(i + 11, j + 6, k + 13, Blocks.viriBlock.blockID);
		world.setBlock(i + 11, j + 6, k + 14, Blocks.viriBlock.blockID);
		world.setBlock(i + 11, j + 6, k + 15, Blocks.viriBlock.blockID);
		world.setBlock(i + 11, j + 6, k + 16, Blocks.viriBlock.blockID);
		world.setBlock(i + 11, j + 6, k + 17, Blocks.viriBlock.blockID);
		world.setBlock(i + 11, j + 6, k + 18, Blocks.viriBlock.blockID);
		world.setBlock(i + 11, j + 6, k + 19, Blocks.viriBlock.blockID);
		world.setBlock(i + 11, j + 6, k + 20, Blocks.viriBlock.blockID);
		world.setBlock(i + 11, j + 6, k + 21, Blocks.viriBlock.blockID);
		world.setBlock(i + 11, j + 6, k + 22, Blocks.viriBlock.blockID);
		world.setBlock(i + 11, j + 6, k + 23, Blocks.viriBlock.blockID);
		world.setBlock(i + 11, j + 6, k + 24, Blocks.viriBlock.blockID);
		world.setBlock(i + 11, j + 6, k + 25, Blocks.viriBlock.blockID);
		world.setBlock(i + 11, j + 6, k + 26, Blocks.viriBlock.blockID);
		world.setBlock(i + 11, j + 6, k + 27, Blocks.viriBlock.blockID);
		world.setBlock(i + 11, j + 6, k + 28, Blocks.viriBlock.blockID);
		world.setBlock(i + 11, j + 6, k + 29, Blocks.viriBlock.blockID);
		world.setBlock(i + 11, j + 6, k + 30, Blocks.viriBlock.blockID);
		world.setBlock(i + 11, j + 6, k + 31, Blocks.viriBlock.blockID);
		world.setBlock(i + 11, j + 6, k + 32, Blocks.viriBlock.blockID);
		world.setBlock(i + 11, j + 7, k + 15, Blocks.viriBlock.blockID);
		world.setBlock(i + 11, j + 7, k + 16, Blocks.viriBlock.blockID);
		world.setBlock(i + 11, j + 7, k + 17, Blocks.viriBlock.blockID);
		world.setBlock(i + 11, j + 7, k + 18, Blocks.viriBlock.blockID);
		world.setBlock(i + 11, j + 7, k + 19, Blocks.viriBlock.blockID);
		world.setBlock(i + 11, j + 7, k + 20, Blocks.viriBlock.blockID);
		world.setBlock(i + 11, j + 7, k + 21, Blocks.viriBlock.blockID);
		world.setBlock(i + 11, j + 7, k + 22, Blocks.viriBlock.blockID);
		world.setBlock(i + 11, j + 7, k + 23, Blocks.viriBlock.blockID);
		world.setBlock(i + 11, j + 7, k + 24, Blocks.viriBlock.blockID);
		world.setBlock(i + 12, j + 0, k + 14, Blocks.viriBlock.blockID);
		world.setBlock(i + 12, j + 0, k + 15, Blocks.viriBlock.blockID);
		world.setBlock(i + 12, j + 0, k + 16, Blocks.viriBlock.blockID);
		world.setBlock(i + 12, j + 0, k + 17, Blocks.viriBlock.blockID);
		world.setBlock(i + 12, j + 0, k + 18, Blocks.viriBlock.blockID);
		world.setBlock(i + 12, j + 0, k + 19, Blocks.viriBlock.blockID);
		world.setBlock(i + 12, j + 0, k + 20, Blocks.viriBlock.blockID);
		world.setBlock(i + 12, j + 0, k + 21, Blocks.viriBlock.blockID);
		world.setBlock(i + 12, j + 0, k + 22, Blocks.viriBlock.blockID);
		world.setBlock(i + 12, j + 0, k + 23, Blocks.viriBlock.blockID);
		world.setBlock(i + 12, j + 0, k + 24, Blocks.viriBlock.blockID);
		world.setBlock(i + 12, j + 0, k + 25, Blocks.viriBlock.blockID);
		world.setBlock(i + 12, j + 1, k + 6, Blocks.viriBlock.blockID);
		world.setBlock(i + 12, j + 1, k + 7, Blocks.viriBlock.blockID);
		world.setBlock(i + 12, j + 1, k + 8, Blocks.viriBlock.blockID);
		world.setBlock(i + 12, j + 1, k + 9, Blocks.viriBlock.blockID);
		world.setBlock(i + 12, j + 1, k + 10, Blocks.viriBlock.blockID);
		world.setBlock(i + 12, j + 1, k + 11, Blocks.viriBlock.blockID);
		world.setBlock(i + 12, j + 1, k + 12, Blocks.viriBlock.blockID);
		world.setBlock(i + 12, j + 1, k + 13, Blocks.viriBlock.blockID);
		world.setBlock(i + 12, j + 1, k + 14, Blocks.viriBlock.blockID);
		world.setBlock(i + 12, j + 1, k + 15, Blocks.viriBlock.blockID);
		world.setBlock(i + 12, j + 1, k + 16, Blocks.viriBlock.blockID);
		world.setBlock(i + 12, j + 1, k + 17, Blocks.viriBlock.blockID);
		world.setBlock(i + 12, j + 1, k + 18, Blocks.viriBlock.blockID);
		world.setBlock(i + 12, j + 1, k + 19, Blocks.viriBlock.blockID);
		world.setBlock(i + 12, j + 1, k + 20, Blocks.viriBlock.blockID);
		world.setBlock(i + 12, j + 1, k + 21, Blocks.viriBlock.blockID);
		world.setBlock(i + 12, j + 1, k + 22, Blocks.viriBlock.blockID);
		world.setBlock(i + 12, j + 1, k + 23, Blocks.viriBlock.blockID);
		world.setBlock(i + 12, j + 1, k + 24, Blocks.viriBlock.blockID);
		world.setBlock(i + 12, j + 1, k + 25, Blocks.viriBlock.blockID);
		world.setBlock(i + 12, j + 1, k + 26, Blocks.viriBlock.blockID);
		world.setBlock(i + 12, j + 1, k + 27, Blocks.viriBlock.blockID);
		world.setBlock(i + 12, j + 1, k + 28, Blocks.viriBlock.blockID);
		world.setBlock(i + 12, j + 1, k + 29, Blocks.viriBlock.blockID);
		world.setBlock(i + 12, j + 1, k + 30, Blocks.viriBlock.blockID);
		world.setBlock(i + 12, j + 1, k + 31, Blocks.viriBlock.blockID);
		world.setBlock(i + 12, j + 1, k + 32, Blocks.viriBlock.blockID);
		world.setBlock(i + 12, j + 1, k + 33, Blocks.viriBlock.blockID);
		world.setBlock(i + 12, j + 2, k + 3, Blocks.viriBlock.blockID);
		world.setBlock(i + 12, j + 2, k + 4, Blocks.viriBlock.blockID);
		world.setBlock(i + 12, j + 2, k + 5, Blocks.viriBlock.blockID);
		world.setBlock(i + 12, j + 2, k + 6, Blocks.viriBlock.blockID);
		world.setBlock(i + 12, j + 2, k + 7, Blocks.viriBlock.blockID);
		world.setBlock(i + 12, j + 2, k + 8, Blocks.viriBlock.blockID);
		world.setBlock(i + 12, j + 2, k + 9, Blocks.viriBlock.blockID);
		world.setBlock(i + 12, j + 2, k + 10, Blocks.viriBlock.blockID);
		world.setBlock(i + 12, j + 2, k + 11, Blocks.viriBlock.blockID);
		world.setBlock(i + 12, j + 2, k + 12, Blocks.viriBlock.blockID);
